Workbook

Sheet How to use
B1: Debt & EMI Payoff Tracker — Snowball / Avalanche
B2: Rajput Lalit & Associates · www.rajputlalitassociates.in · WhatsApp +91 93549 53603
B4: Steps
A5: 1 | B5: In 'My Loans' list every loan and card: amount outstanding today, yearly interest rate and the EMI / minimum payment.
A6: 2 | B6: Choose a method: Snowball pays off the smallest balance first (quick wins); Avalanche pays the highest interest first (saves the most money).
A7: 3 | B7: Enter the extra amount you can pay every month on top of all EMIs — even ₹1,000 makes a difference.
A8: 4 | B8: 'Dashboard' shows your debt-free date, total interest, and the month each loan closes. 'Schedule' shows every month and the chart shows your total debt going down.
A9: 5 | B9: When a loan closes, its EMI automatically moves to the next loan in the order — that is what makes the method powerful.
B11: Good to know
B12: • Before prepaying a home or other loan, check prepayment charges with your bank.
B13: • Interest is worked out monthly on the reducing balance — the usual method for EMIs and cards.
B14: • If the minimum payment is less than the monthly interest, that loan never closes — the sheet warns you.
B16: Cells shaded light yellow are for your entries. White cells contain formulas — please don't type over them.
B18: Licensed for use in your own business. Please do not resell or share publicly. This template is a working aid, not professional advice.

Sheet Dashboard
A1: Dashboard
A2: Updates as you change 'My Loans'
A4: Total debt today | B4: =SUM('My Loans'!C6:C15)
A5: Paying every month (EMIs + extra) | B5: =(SUM('My Loans'!$E$6:$E$15)+'My Loans'!$D$3)
A6: Months to become debt-free | B6: =IF(Schedule!BB364>0.5,"More than 30 years — increase payments",COUNTIF(Schedule!BB5:BB364,">0.5")+1)
A7: Debt-free by | B7: =IF(ISNUMBER(B6),EOMONTH(TODAY(),B6-1),"—")
A8: Total interest you will pay | B8: =SUM(Schedule!N5:W364)-SUM(Schedule!D5:M364)
A10: Loan | B10: Order | C10: Closes in month # | D10: Closes by
A11: =IF(N('My Loans'!C6)<=0,"",'My Loans'!B6) | B11: =IF(A11="","",Schedule!D3) | C11: =IF(A11="","",IF(Schedule!AR364>0.5,"Never — EMI too low",COUNTIF(Schedule!AR5:AR364,">0.5")+1)) | D11: =IF(ISNUMBER(C11),EOMONTH(TODAY(),C11-1),"")
A12: =IF(N('My Loans'!C7)<=0,"",'My Loans'!B7) | B12: =IF(A12="","",Schedule!E3) | C12: =IF(A12="","",IF(Schedule!AS364>0.5,"Never — EMI too low",COUNTIF(Schedule!AS5:AS364,">0.5")+1)) | D12: =IF(ISNUMBER(C12),EOMONTH(TODAY(),C12-1),"")
A13: =IF(N('My Loans'!C8)<=0,"",'My Loans'!B8) | B13: =IF(A13="","",Schedule!F3) | C13: =IF(A13="","",IF(Schedule!AT364>0.5,"Never — EMI too low",COUNTIF(Schedule!AT5:AT364,">0.5")+1)) | D13: =IF(ISNUMBER(C13),EOMONTH(TODAY(),C13-1),"")
A14: =IF(N('My Loans'!C9)<=0,"",'My Loans'!B9) | B14: =IF(A14="","",Schedule!G3) | C14: =IF(A14="","",IF(Schedule!AU364>0.5,"Never — EMI too low",COUNTIF(Schedule!AU5:AU364,">0.5")+1)) | D14: =IF(ISNUMBER(C14),EOMONTH(TODAY(),C14-1),"")
A15: =IF(N('My Loans'!C10)<=0,"",'My Loans'!B10) | B15: =IF(A15="","",Schedule!H3) | C15: =IF(A15="","",IF(Schedule!AV364>0.5,"Never — EMI too low",COUNTIF(Schedule!AV5:AV364,">0.5")+1)) | D15: =IF(ISNUMBER(C15),EOMONTH(TODAY(),C15-1),"")
A16: =IF(N('My Loans'!C11)<=0,"",'My Loans'!B11) | B16: =IF(A16="","",Schedule!I3) | C16: =IF(A16="","",IF(Schedule!AW364>0.5,"Never — EMI too low",COUNTIF(Schedule!AW5:AW364,">0.5")+1)) | D16: =IF(ISNUMBER(C16),EOMONTH(TODAY(),C16-1),"")
A17: =IF(N('My Loans'!C12)<=0,"",'My Loans'!B12) | B17: =IF(A17="","",Schedule!J3) | C17: =IF(A17="","",IF(Schedule!AX364>0.5,"Never — EMI too low",COUNTIF(Schedule!AX5:AX364,">0.5")+1)) | D17: =IF(ISNUMBER(C17),EOMONTH(TODAY(),C17-1),"")
A18: =IF(N('My Loans'!C13)<=0,"",'My Loans'!B13) | B18: =IF(A18="","",Schedule!K3) | C18: =IF(A18="","",IF(Schedule!AY364>0.5,"Never — EMI too low",COUNTIF(Schedule!AY5:AY364,">0.5")+1)) | D18: =IF(ISNUMBER(C18),EOMONTH(TODAY(),C18-1),"")
A19: =IF(N('My Loans'!C14)<=0,"",'My Loans'!B14) | B19: =IF(A19="","",Schedule!L3) | C19: =IF(A19="","",IF(Schedule!AZ364>0.5,"Never — EMI too low",COUNTIF(Schedule!AZ5:AZ364,">0.5")+1)) | D19: =IF(ISNUMBER(C19),EOMONTH(TODAY(),C19-1),"")
A20: =IF(N('My Loans'!C15)<=0,"",'My Loans'!B15) | B20: =IF(A20="","",Schedule!M3) | C20: =IF(A20="","",IF(Schedule!BA364>0.5,"Never — EMI too low",COUNTIF(Schedule!BA5:BA364,">0.5")+1)) | D20: =IF(ISNUMBER(C20),EOMONTH(TODAY(),C20-1),"")
A23: Tax, GST or accounts question? Rajput Lalit & Associates — WhatsApp +91 93549 53603 · www.rajputlalitassociates.in

Sheet My Loans
A1: My Loans & Cards
A2: Up to 10. Yellow cells are yours to fill.
A3: Method | B3: Avalanche | C3: Extra per month (₹) | D3: 2000
A5: # | B5: Loan / card | C5: Outstanding today (₹) | D5: Interest % per year | E5: EMI / minimum (₹) | F5: Monthly interest now | G5: Sort key
A6: 1 | B6: Credit card | C6: 60000 | D6: 36 | E6: 3000 | F6: =IF(C6="","",C6*D6/1200) | G6: =IF(N(C6)<=0,1E+15,IF($B$3="Snowball",C6,-D6))+ROW()/1E+6
A7: 2 | B7: Personal loan | C7: 200000 | D7: 14 | E7: 7000 | F7: =IF(C7="","",C7*D7/1200) | G7: =IF(N(C7)<=0,1E+15,IF($B$3="Snowball",C7,-D7))+ROW()/1E+6
A8: 3 | B8: Car loan | C8: 350000 | D8: 9.5 | E8: 9000 | F8: =IF(C8="","",C8*D8/1200) | G8: =IF(N(C8)<=0,1E+15,IF($B$3="Snowball",C8,-D8))+ROW()/1E+6
A9: 4 | F9: =IF(C9="","",C9*D9/1200) | G9: =IF(N(C9)<=0,1E+15,IF($B$3="Snowball",C9,-D9))+ROW()/1E+6
A10: 5 | F10: =IF(C10="","",C10*D10/1200) | G10: =IF(N(C10)<=0,1E+15,IF($B$3="Snowball",C10,-D10))+ROW()/1E+6
A11: 6 | F11: =IF(C11="","",C11*D11/1200) | G11: =IF(N(C11)<=0,1E+15,IF($B$3="Snowball",C11,-D11))+ROW()/1E+6
A12: 7 | F12: =IF(C12="","",C12*D12/1200) | G12: =IF(N(C12)<=0,1E+15,IF($B$3="Snowball",C12,-D12))+ROW()/1E+6
A13: 8 | F13: =IF(C13="","",C13*D13/1200) | G13: =IF(N(C13)<=0,1E+15,IF($B$3="Snowball",C13,-D13))+ROW()/1E+6
A14: 9 | F14: =IF(C14="","",C14*D14/1200) | G14: =IF(N(C14)<=0,1E+15,IF($B$3="Snowball",C14,-D14))+ROW()/1E+6
A15: 10 | F15: =IF(C15="","",C15*D15/1200) | G15: =IF(N(C15)<=0,1E+15,IF($B$3="Snowball",C15,-D15))+ROW()/1E+6
B17: Red EMI = it doesn't even cover the monthly interest, so that loan will never close. Increase it.
B18: The sample rows are only an example — overwrite or clear them.

Sheet Schedule
A1: Month-by-month schedule
A2: Calculated — no entries needed here
A3: Order → | D3: =COUNTIF('My Loans'!$G$6:$G$15,"<"&'My Loans'!G6)+1 | E3: =COUNTIF('My Loans'!$G$6:$G$15,"<"&'My Loans'!G7)+1 | F3: =COUNTIF('My Loans'!$G$6:$G$15,"<"&'My Loans'!G8)+1 | G3: =COUNTIF('My Loans'!$G$6:$G$15,"<"&'My Loans'!G9)+1 | H3: =COUNTIF('My Loans'!$G$6:$G$15,"<"&'My Loans'!G10)+1 | I3: =COUNTIF('My Loans'!$G$6:$G$15,"<"&'My Loans'!G11)+1 | J3: =COUNTIF('My Loans'!$G$6:$G$15,"<"&'My Loans'!G12)+1 | K3: =COUNTIF('My Loans'!$G$6:$G$15,"<"&'My Loans'!G13)+1 | L3: =COUNTIF('My Loans'!$G$6:$G$15,"<"&'My Loans'!G14)+1 | M3: =COUNTIF('My Loans'!$G$6:$G$15,"<"&'My Loans'!G15)+1 | N3: =COUNTIF('My Loans'!$G$6:$G$15,"<"&'My Loans'!G6)+1 | O3: =COUNTIF('My Loans'!$G$6:$G$15,"<"&'My Loans'!G7)+1 | P3: =COUNTIF('My Loans'!$G$6:$G$15,"<"&'My Loans'!G8)+1 | Q3: =COUNTIF('My Loans'!$G$6:$G$15,"<"&'My Loans'!G9)+1 | R3: =COUNTIF('My Loans'!$G$6:$G$15,"<"&'My Loans'!G10)+1 | S3: =COUNTIF('My Loans'!$G$6:$G$15,"<"&'My Loans'!G11)+1 | T3: =COUNTIF('My Loans'!$G$6:$G$15,"<"&'My Loans'!G12)+1 | U3: =COUNTIF('My Loans'!$G$6:$G$15,"<"&'My Loans'!G13)+1 | V3: =COUNTIF('My Loans'!$G$6:$G$15,"<"&'My Loans'!G14)+1 | W3: =COUNTIF('My Loans'!$G$6:$G$15,"<"&'My Loans'!G15)+1 | X3: =COUNTIF('My Loans'!$G$6:$G$15,"<"&'My Loans'!G6)+1 | Y3: =COUNTIF('My Loans'!$G$6:$G$15,"<"&'My Loans'!G7)+1 | Z3: =COUNTIF('My Loans'!$G$6:$G$15,"<"&'My Loans'!G8)+1 | AA3: =COUNTIF('My Loans'!$G$6:$G$15,"<"&'My Loans'!G9)+1 | AB3: =COUNTIF('My Loans'!$G$6:$G$15,"<"&'My Loans'!G10)+1 | AC3: =COUNTIF('My Loans'!$G$6:$G$15,"<"&'My Loans'!G11)+1 | AD3: =COUNTIF('My Loans'!$G$6:$G$15,"<"&'My Loans'!G12)+1 | AE3: =COUNTIF('My Loans'!$G$6:$G$15,"<"&'My Loans'!G13)+1 | AF3: =COUNTIF('My Loans'!$G$6:$G$15,"<"&'My Loans'!G14)+1 | AG3: =COUNTIF('My Loans'!$G$6:$G$15,"<"&'My Loans'!G15)+1 | AH3: =COUNTIF('My Loans'!$G$6:$G$15,"<"&'My Loans'!G6)+1 | AI3: =COUNTIF('My Loans'!$G$6:$G$15,"<"&'My Loans'!G7)+1 | AJ3: =COUNTIF('My Loans'!$G$6:$G$15,"<"&'My Loans'!G8)+1 | AK3: =COUNTIF('My Loans'!$G$6:$G$15,"<"&'My Loans'!G9)+1 | AL3: =COUNTIF('My Loans'!$G$6:$G$15,"<"&'My Loans'!G10)+1 | AM3: =COUNTIF('My Loans'!$G$6:$G$15,"<"&'My Loans'!G11)+1 | AN3: =COUNTIF('My Loans'!$G$6:$G$15,"<"&'My Loans'!G12)+1 | AO3: =COUNTIF('My Loans'!$G$6:$G$15,"<"&'My Loans'!G13)+1 | AP3: =COUNTIF('My Loans'!$G$6:$G$15,"<"&'My Loans'!G14)+1 | AQ3: =COUNTIF('My Loans'!$G$6:$G$15,"<"&'My Loans'!G15)+1 | AR3: =COUNTIF('My Loans'!$G$6:$G$15,"<"&'My Loans'!G6)+1 | AS3: =COUNTIF('My Loans'!$G$6:$G$15,"<"&'My Loans'!G7)+1 | AT3: =COUNTIF('My Loans'!$G$6:$G$15,"<"&'My Loans'!G8)+1 | AU3: =COUNTIF('My Loans'!$G$6:$G$15,"<"&'My Loans'!G9)+1 | AV3: =COUNTIF('My Loans'!$G$6:$G$15,"<"&'My Loans'!G10)+1 | AW3: =COUNTIF('My Loans'!$G$6:$G$15,"<"&'My Loans'!G11)+1 | AX3: =COUNTIF('My Loans'!$G$6:$G$15,"<"&'My Loans'!G12)+1 | AY3: =COUNTIF('My Loans'!$G$6:$G$15,"<"&'My Loans'!G13)+1 | AZ3: =COUNTIF('My Loans'!$G$6:$G$15,"<"&'My Loans'!G14)+1 | BA3: =COUNTIF('My Loans'!$G$6:$G$15,"<"&'My Loans'!G15)+1
A4: Month | B4: Date | C4: Money for extra | D4: ='My Loans'!B6&" — Opening" | E4: ='My Loans'!B7&" — Opening" | F4: ='My Loans'!B8&" — Opening" | G4: ='My Loans'!B9&" — Opening" | H4: ='My Loans'!B10&" — Opening" | I4: ='My Loans'!B11&" — Opening" | J4: ='My Loans'!B12&" — Opening" | K4: ='My Loans'!B13&" — Opening" | L4: ='My Loans'!B14&" — Opening" | M4: ='My Loans'!B15&" — Opening" | N4: ='My Loans'!B6&" — With interest" | O4: ='My Loans'!B7&" — With interest" | P4: ='My Loans'!B8&" — With interest" | Q4: ='My Loans'!B9&" — With interest" | R4: ='My Loans'!B10&" — With interest" | S4: ='My Loans'!B11&" — With interest" | T4: ='My Loans'!B12&" — With interest" | U4: ='My Loans'!B13&" — With interest" | V4: ='My Loans'!B14&" — With interest" | W4: ='My Loans'!B15&" — With interest" | X4: ='My Loans'!B6&" — EMI paid" | Y4: ='My Loans'!B7&" — EMI paid" | Z4: ='My Loans'!B8&" — EMI paid" | AA4: ='My Loans'!B9&" — EMI paid" | AB4: ='My Loans'!B10&" — EMI paid" | AC4: ='My Loans'!B11&" — EMI paid" | AD4: ='My Loans'!B12&" — EMI paid" | AE4: ='My Loans'!B13&" — EMI paid" | AF4: ='My Loans'!B14&" — EMI paid" | AG4: ='My Loans'!B15&" — EMI paid" | AH4: ='My Loans'!B6&" — Extra paid" | AI4: ='My Loans'!B7&" — Extra paid" | AJ4: ='My Loans'!B8&" — Extra paid" | AK4: ='My Loans'!B9&" — Extra paid" | AL4: ='My Loans'!B10&" — Extra paid" | AM4: ='My Loans'!B11&" — Extra paid" | AN4: ='My Loans'!B12&" — Extra paid" | AO4: ='My Loans'!B13&" — Extra paid" | AP4: ='My Loans'!B14&" — Extra paid" | AQ4: ='My Loans'!B15&" — Extra paid" | AR4: ='My Loans'!B6&" — Closing" | AS4: ='My Loans'!B7&" — Closing" | AT4: ='My Loans'!B8&" — Closing" | AU4: ='My Loans'!B9&" — Closing" | AV4: ='My Loans'!B10&" — Closing" | AW4: ='My Loans'!B11&" — Closing" | AX4: ='My Loans'!B12&" — Closing" | AY4: ='My Loans'!B13&" — Closing" | AZ4: ='My Loans'!B14&" — Closing" | BA4: ='My Loans'!B15&" — Closing" | BB4: TOTAL DEBT
A5: 1 | B5: =EOMONTH(TODAY(),0) | C5: =MAX(0,(SUM('My Loans'!$E$6:$E$15)+'My Loans'!$D$3)-SUM($X5:$AG5)) | D5: =MAX(0,N('My Loans'!C6)) | E5: =MAX(0,N('My Loans'!C7)) | F5: =MAX(0,N('My Loans'!C8)) | G5: =MAX(0,N('My Loans'!C9)) | H5: =MAX(0,N('My Loans'!C10)) | I5: =MAX(0,N('My Loans'!C11)) | J5: =MAX(0,N('My Loans'!C12)) | K5: =MAX(0,N('My Loans'!C13)) | L5: =MAX(0,N('My Loans'!C14)) | M5: =MAX(0,N('My Loans'!C15)) | N5: =IF(D5<0.5,0,D5*(1+N('My Loans'!D6)/1200)) | O5: =IF(E5<0.5,0,E5*(1+N('My Loans'!D7)/1200)) | P5: =IF(F5<0.5,0,F5*(1+N('My Loans'!D8)/1200)) | Q5: =IF(G5<0.5,0,G5*(1+N('My Loans'!D9)/1200)) | R5: =IF(H5<0.5,0,H5*(1+N('My Loans'!D10)/1200)) | S5: =IF(I5<0.5,0,I5*(1+N('My Loans'!D11)/1200)) | T5: =IF(J5<0.5,0,J5*(1+N('My Loans'!D12)/1200)) | U5: =IF(K5<0.5,0,K5*(1+N('My Loans'!D13)/1200)) | V5: =IF(L5<0.5,0,L5*(1+N('My Loans'!D14)/1200)) | W5: =IF(M5<0.5,0,M5*(1+N('My Loans'!D15)/1200)) | X5: =MIN(N5,N('My Loans'!E6)) | Y5: =MIN(O5,N('My Loans'!E7)) | Z5: =MIN(P5,N('My Loans'!E8)) | AA5: =MIN(Q5,N('My Loans'!E9)) | AB5: =MIN(R5,N('My Loans'!E10)) | AC5: =MIN(S5,N('My Loans'!E11)) | AD5: =MIN(T5,N('My Loans'!E12)) | AE5: =MIN(U5,N('My Loans'!E13)) | AF5: =MIN(V5,N('My Loans'!E14)) | AG5: =MIN(W5,N('My Loans'!E15)) | AH5: =MIN(N5-X5,MAX(0,$C5-SUMPRODUCT(($D$3:$M$3<D$3)*($N5:$W5-$X5:$AG5)))) | AI5: =MIN(O5-Y5,MAX(0,$C5-SUMPRODUCT(($D$3:$M$3<E$3)*($N5:$W5-$X5:$AG5)))) | AJ5: =MIN(P5-Z5,MAX(0,$C5-SUMPRODUCT(($D$3:$M$3<F$3)*($N5:$W5-$X5:$AG5)))) | AK5: =MIN(Q5-AA5,MAX(0,$C5-SUMPRODUCT(($D$3:$M$3<G$3)*($N5:$W5-$X5:$AG5)))) | AL5: =MIN(R5-AB5,MAX(0,$C5-SUMPRODUCT(($D$3:$M$3<H$3)*($N5:$W5-$X5:$AG5)))) | AM5: =MIN(S5-AC5,MAX(0,$C5-SUMPRODUCT(($D$3:$M$3<I$3)*($N5:$W5-$X5:$AG5)))) | AN5: =MIN(T5-AD5,MAX(0,$C5-SUMPRODUCT(($D$3:$M$3<J$3)*($N5:$W5-$X5:$AG5)))) | AO5: =MIN(U5-AE5,MAX(0,$C5-SUMPRODUCT(($D$3:$M$3<K$3)*($N5:$W5-$X5:$AG5)))) | ... AQ5: =MIN(W5-AG5,MAX(0,$C5-SUMPRODUCT(($D$3:$M$3<M$3)*($N5:$W5-$X5:$AG5)))) | AR5: =ROUND(N5-X5-AH5,2) | AS5: =ROUND(O5-Y5-AI5,2) | AT5: =ROUND(P5-Z5-AJ5,2) | AU5: =ROUND(Q5-AA5-AK5,2) | AV5: =ROUND(R5-AB5-AL5,2) | AW5: =ROUND(S5-AC5-AM5,2) | AX5: =ROUND(T5-AD5-AN5,2) | AY5: =ROUND(U5-AE5-AO5,2) | ... BA5: =ROUND(W5-AG5-AQ5,2) | BB5: =SUM(AR5:BA5)
A6: 2 | B6: =EOMONTH(TODAY(),1) | C6: =MAX(0,(SUM('My Loans'!$E$6:$E$15)+'My Loans'!$D$3)-SUM($X6:$AG6)) | D6: =MAX(0,AR5) | E6: =MAX(0,AS5) | F6: =MAX(0,AT5) | G6: =MAX(0,AU5) | H6: =MAX(0,AV5) | I6: =MAX(0,AW5) | J6: =MAX(0,AX5) | K6: =MAX(0,AY5) | ... M6: =MAX(0,BA5) | N6: =IF(D6<0.5,0,D6*(1+N('My Loans'!D6)/1200)) | O6: =IF(E6<0.5,0,E6*(1+N('My Loans'!D7)/1200)) | P6: =IF(F6<0.5,0,F6*(1+N('My Loans'!D8)/1200)) | Q6: =IF(G6<0.5,0,G6*(1+N('My Loans'!D9)/1200)) | R6: =IF(H6<0.5,0,H6*(1+N('My Loans'!D10)/1200)) | S6: =IF(I6<0.5,0,I6*(1+N('My Loans'!D11)/1200)) | T6: =IF(J6<0.5,0,J6*(1+N('My Loans'!D12)/1200)) | U6: =IF(K6<0.5,0,K6*(1+N('My Loans'!D13)/1200)) | V6: =IF(L6<0.5,0,L6*(1+N('My Loans'!D14)/1200)) | W6: =IF(M6<0.5,0,M6*(1+N('My Loans'!D15)/1200)) | X6: =MIN(N6,N('My Loans'!E6)) | Y6: =MIN(O6,N('My Loans'!E7)) | Z6: =MIN(P6,N('My Loans'!E8)) | AA6: =MIN(Q6,N('My Loans'!E9)) | AB6: =MIN(R6,N('My Loans'!E10)) | AC6: =MIN(S6,N('My Loans'!E11)) | AD6: =MIN(T6,N('My Loans'!E12)) | AE6: =MIN(U6,N('My Loans'!E13)) | AF6: =MIN(V6,N('My Loans'!E14)) | AG6: =MIN(W6,N('My Loans'!E15)) | AH6: =MIN(N6-X6,MAX(0,$C6-SUMPRODUCT(($D$3:$M$3<D$3)*($N6:$W6-$X6:$AG6)))) | AI6: =MIN(O6-Y6,MAX(0,$C6-SUMPRODUCT(($D$3:$M$3<E$3)*($N6:$W6-$X6:$AG6)))) | AJ6: =MIN(P6-Z6,MAX(0,$C6-SUMPRODUCT(($D$3:$M$3<F$3)*($N6:$W6-$X6:$AG6)))) | AK6: =MIN(Q6-AA6,MAX(0,$C6-SUMPRODUCT(($D$3:$M$3<G$3)*($N6:$W6-$X6:$AG6)))) | AL6: =MIN(R6-AB6,MAX(0,$C6-SUMPRODUCT(($D$3:$M$3<H$3)*($N6:$W6-$X6:$AG6)))) | AM6: =MIN(S6-AC6,MAX(0,$C6-SUMPRODUCT(($D$3:$M$3<I$3)*($N6:$W6-$X6:$AG6)))) | AN6: =MIN(T6-AD6,MAX(0,$C6-SUMPRODUCT(($D$3:$M$3<J$3)*($N6:$W6-$X6:$AG6)))) | AO6: =MIN(U6-AE6,MAX(0,$C6-SUMPRODUCT(($D$3:$M$3<K$3)*($N6:$W6-$X6:$AG6)))) | ... AQ6: =MIN(W6-AG6,MAX(0,$C6-SUMPRODUCT(($D$3:$M$3<M$3)*($N6:$W6-$X6:$AG6)))) | AR6: =ROUND(N6-X6-AH6,2) | AS6: =ROUND(O6-Y6-AI6,2) | AT6: =ROUND(P6-Z6-AJ6,2) | AU6: =ROUND(Q6-AA6-AK6,2) | AV6: =ROUND(R6-AB6-AL6,2) | AW6: =ROUND(S6-AC6-AM6,2) | AX6: =ROUND(T6-AD6-AN6,2) | AY6: =ROUND(U6-AE6-AO6,2) | ... BA6: =ROUND(W6-AG6-AQ6,2) | BB6: =SUM(AR6:BA6)
A7: 3 | B7: =EOMONTH(TODAY(),2) | C7: =MAX(0,(SUM('My Loans'!$E$6:$E$15)+'My Loans'!$D$3)-SUM($X7:$AG7)) | D7: =MAX(0,AR6) | E7: =MAX(0,AS6) | F7: =MAX(0,AT6) | G7: =MAX(0,AU6) | H7: =MAX(0,AV6) | I7: =MAX(0,AW6) | J7: =MAX(0,AX6) | K7: =MAX(0,AY6) | ... M7: =MAX(0,BA6) | N7: =IF(D7<0.5,0,D7*(1+N('My Loans'!D6)/1200)) | O7: =IF(E7<0.5,0,E7*(1+N('My Loans'!D7)/1200)) | P7: =IF(F7<0.5,0,F7*(1+N('My Loans'!D8)/1200)) | Q7: =IF(G7<0.5,0,G7*(1+N('My Loans'!D9)/1200)) | R7: =IF(H7<0.5,0,H7*(1+N('My Loans'!D10)/1200)) | S7: =IF(I7<0.5,0,I7*(1+N('My Loans'!D11)/1200)) | T7: =IF(J7<0.5,0,J7*(1+N('My Loans'!D12)/1200)) | U7: =IF(K7<0.5,0,K7*(1+N('My Loans'!D13)/1200)) | V7: =IF(L7<0.5,0,L7*(1+N('My Loans'!D14)/1200)) | W7: =IF(M7<0.5,0,M7*(1+N('My Loans'!D15)/1200)) | X7: =MIN(N7,N('My Loans'!E6)) | Y7: =MIN(O7,N('My Loans'!E7)) | Z7: =MIN(P7,N('My Loans'!E8)) | AA7: =MIN(Q7,N('My Loans'!E9)) | AB7: =MIN(R7,N('My Loans'!E10)) | AC7: =MIN(S7,N('My Loans'!E11)) | AD7: =MIN(T7,N('My Loans'!E12)) | AE7: =MIN(U7,N('My Loans'!E13)) | AF7: =MIN(V7,N('My Loans'!E14)) | AG7: =MIN(W7,N('My Loans'!E15)) | AH7: =MIN(N7-X7,MAX(0,$C7-SUMPRODUCT(($D$3:$M$3<D$3)*($N7:$W7-$X7:$AG7)))) | AI7: =MIN(O7-Y7,MAX(0,$C7-SUMPRODUCT(($D$3:$M$3<E$3)*($N7:$W7-$X7:$AG7)))) | AJ7: =MIN(P7-Z7,MAX(0,$C7-SUMPRODUCT(($D$3:$M$3<F$3)*($N7:$W7-$X7:$AG7)))) | AK7: =MIN(Q7-AA7,MAX(0,$C7-SUMPRODUCT(($D$3:$M$3<G$3)*($N7:$W7-$X7:$AG7)))) | AL7: =MIN(R7-AB7,MAX(0,$C7-SUMPRODUCT(($D$3:$M$3<H$3)*($N7:$W7-$X7:$AG7)))) | AM7: =MIN(S7-AC7,MAX(0,$C7-SUMPRODUCT(($D$3:$M$3<I$3)*($N7:$W7-$X7:$AG7)))) | AN7: =MIN(T7-AD7,MAX(0,$C7-SUMPRODUCT(($D$3:$M$3<J$3)*($N7:$W7-$X7:$AG7)))) | AO7: =MIN(U7-AE7,MAX(0,$C7-SUMPRODUCT(($D$3:$M$3<K$3)*($N7:$W7-$X7:$AG7)))) | ... AQ7: =MIN(W7-AG7,MAX(0,$C7-SUMPRODUCT(($D$3:$M$3<M$3)*($N7:$W7-$X7:$AG7)))) | AR7: =ROUND(N7-X7-AH7,2) | AS7: =ROUND(O7-Y7-AI7,2) | AT7: =ROUND(P7-Z7-AJ7,2) | AU7: =ROUND(Q7-AA7-AK7,2) | AV7: =ROUND(R7-AB7-AL7,2) | AW7: =ROUND(S7-AC7-AM7,2) | AX7: =ROUND(T7-AD7-AN7,2) | AY7: =ROUND(U7-AE7-AO7,2) | ... BA7: =ROUND(W7-AG7-AQ7,2) | BB7: =SUM(AR7:BA7)
A8: 4 | B8: =EOMONTH(TODAY(),3) | C8: =MAX(0,(SUM('My Loans'!$E$6:$E$15)+'My Loans'!$D$3)-SUM($X8:$AG8)) | D8: =MAX(0,AR7) | E8: =MAX(0,AS7) | F8: =MAX(0,AT7) | G8: =MAX(0,AU7) | H8: =MAX(0,AV7) | I8: =MAX(0,AW7) | J8: =MAX(0,AX7) | K8: =MAX(0,AY7) | ... M8: =MAX(0,BA7) | N8: =IF(D8<0.5,0,D8*(1+N('My Loans'!D6)/1200)) | O8: =IF(E8<0.5,0,E8*(1+N('My Loans'!D7)/1200)) | P8: =IF(F8<0.5,0,F8*(1+N('My Loans'!D8)/1200)) | Q8: =IF(G8<0.5,0,G8*(1+N('My Loans'!D9)/1200)) | R8: =IF(H8<0.5,0,H8*(1+N('My Loans'!D10)/1200)) | S8: =IF(I8<0.5,0,I8*(1+N('My Loans'!D11)/1200)) | T8: =IF(J8<0.5,0,J8*(1+N('My Loans'!D12)/1200)) | U8: =IF(K8<0.5,0,K8*(1+N('My Loans'!D13)/1200)) | V8: =IF(L8<0.5,0,L8*(1+N('My Loans'!D14)/1200)) | W8: =IF(M8<0.5,0,M8*(1+N('My Loans'!D15)/1200)) | X8: =MIN(N8,N('My Loans'!E6)) | Y8: =MIN(O8,N('My Loans'!E7)) | Z8: =MIN(P8,N('My Loans'!E8)) | AA8: =MIN(Q8,N('My Loans'!E9)) | AB8: =MIN(R8,N('My Loans'!E10)) | AC8: =MIN(S8,N('My Loans'!E11)) | AD8: =MIN(T8,N('My Loans'!E12)) | AE8: =MIN(U8,N('My Loans'!E13)) | AF8: =MIN(V8,N('My Loans'!E14)) | AG8: =MIN(W8,N('My Loans'!E15)) | AH8: =MIN(N8-X8,MAX(0,$C8-SUMPRODUCT(($D$3:$M$3<D$3)*($N8:$W8-$X8:$AG8)))) | AI8: =MIN(O8-Y8,MAX(0,$C8-SUMPRODUCT(($D$3:$M$3<E$3)*($N8:$W8-$X8:$AG8)))) | AJ8: =MIN(P8-Z8,MAX(0,$C8-SUMPRODUCT(($D$3:$M$3<F$3)*($N8:$W8-$X8:$AG8)))) | AK8: =MIN(Q8-AA8,MAX(0,$C8-SUMPRODUCT(($D$3:$M$3<G$3)*($N8:$W8-$X8:$AG8)))) | AL8: =MIN(R8-AB8,MAX(0,$C8-SUMPRODUCT(($D$3:$M$3<H$3)*($N8:$W8-$X8:$AG8)))) | AM8: =MIN(S8-AC8,MAX(0,$C8-SUMPRODUCT(($D$3:$M$3<I$3)*($N8:$W8-$X8:$AG8)))) | AN8: =MIN(T8-AD8,MAX(0,$C8-SUMPRODUCT(($D$3:$M$3<J$3)*($N8:$W8-$X8:$AG8)))) | AO8: =MIN(U8-AE8,MAX(0,$C8-SUMPRODUCT(($D$3:$M$3<K$3)*($N8:$W8-$X8:$AG8)))) | ... AQ8: =MIN(W8-AG8,MAX(0,$C8-SUMPRODUCT(($D$3:$M$3<M$3)*($N8:$W8-$X8:$AG8)))) | AR8: =ROUND(N8-X8-AH8,2) | AS8: =ROUND(O8-Y8-AI8,2) | AT8: =ROUND(P8-Z8-AJ8,2) | AU8: =ROUND(Q8-AA8-AK8,2) | AV8: =ROUND(R8-AB8-AL8,2) | AW8: =ROUND(S8-AC8-AM8,2) | AX8: =ROUND(T8-AD8-AN8,2) | AY8: =ROUND(U8-AE8-AO8,2) | ... BA8: =ROUND(W8-AG8-AQ8,2) | BB8: =SUM(AR8:BA8)
A9: 5 | B9: =EOMONTH(TODAY(),4) | C9: =MAX(0,(SUM('My Loans'!$E$6:$E$15)+'My Loans'!$D$3)-SUM($X9:$AG9)) | D9: =MAX(0,AR8) | E9: =MAX(0,AS8) | F9: =MAX(0,AT8) | G9: =MAX(0,AU8) | H9: =MAX(0,AV8) | I9: =MAX(0,AW8) | J9: =MAX(0,AX8) | K9: =MAX(0,AY8) | ... M9: =MAX(0,BA8) | N9: =IF(D9<0.5,0,D9*(1+N('My Loans'!D6)/1200)) | O9: =IF(E9<0.5,0,E9*(1+N('My Loans'!D7)/1200)) | P9: =IF(F9<0.5,0,F9*(1+N('My Loans'!D8)/1200)) | Q9: =IF(G9<0.5,0,G9*(1+N('My Loans'!D9)/1200)) | R9: =IF(H9<0.5,0,H9*(1+N('My Loans'!D10)/1200)) | S9: =IF(I9<0.5,0,I9*(1+N('My Loans'!D11)/1200)) | T9: =IF(J9<0.5,0,J9*(1+N('My Loans'!D12)/1200)) | U9: =IF(K9<0.5,0,K9*(1+N('My Loans'!D13)/1200)) | V9: =IF(L9<0.5,0,L9*(1+N('My Loans'!D14)/1200)) | W9: =IF(M9<0.5,0,M9*(1+N('My Loans'!D15)/1200)) | X9: =MIN(N9,N('My Loans'!E6)) | Y9: =MIN(O9,N('My Loans'!E7)) | Z9: =MIN(P9,N('My Loans'!E8)) | AA9: =MIN(Q9,N('My Loans'!E9)) | AB9: =MIN(R9,N('My Loans'!E10)) | AC9: =MIN(S9,N('My Loans'!E11)) | AD9: =MIN(T9,N('My Loans'!E12)) | AE9: =MIN(U9,N('My Loans'!E13)) | AF9: =MIN(V9,N('My Loans'!E14)) | AG9: =MIN(W9,N('My Loans'!E15)) | AH9: =MIN(N9-X9,MAX(0,$C9-SUMPRODUCT(($D$3:$M$3<D$3)*($N9:$W9-$X9:$AG9)))) | AI9: =MIN(O9-Y9,MAX(0,$C9-SUMPRODUCT(($D$3:$M$3<E$3)*($N9:$W9-$X9:$AG9)))) | AJ9: =MIN(P9-Z9,MAX(0,$C9-SUMPRODUCT(($D$3:$M$3<F$3)*($N9:$W9-$X9:$AG9)))) | AK9: =MIN(Q9-AA9,MAX(0,$C9-SUMPRODUCT(($D$3:$M$3<G$3)*($N9:$W9-$X9:$AG9)))) | AL9: =MIN(R9-AB9,MAX(0,$C9-SUMPRODUCT(($D$3:$M$3<H$3)*($N9:$W9-$X9:$AG9)))) | AM9: =MIN(S9-AC9,MAX(0,$C9-SUMPRODUCT(($D$3:$M$3<I$3)*($N9:$W9-$X9:$AG9)))) | AN9: =MIN(T9-AD9,MAX(0,$C9-SUMPRODUCT(($D$3:$M$3<J$3)*($N9:$W9-$X9:$AG9)))) | AO9: =MIN(U9-AE9,MAX(0,$C9-SUMPRODUCT(($D$3:$M$3<K$3)*($N9:$W9-$X9:$AG9)))) | ... AQ9: =MIN(W9-AG9,MAX(0,$C9-SUMPRODUCT(($D$3:$M$3<M$3)*($N9:$W9-$X9:$AG9)))) | AR9: =ROUND(N9-X9-AH9,2) | AS9: =ROUND(O9-Y9-AI9,2) | AT9: =ROUND(P9-Z9-AJ9,2) | AU9: =ROUND(Q9-AA9-AK9,2) | AV9: =ROUND(R9-AB9-AL9,2) | AW9: =ROUND(S9-AC9-AM9,2) | AX9: =ROUND(T9-AD9-AN9,2) | AY9: =ROUND(U9-AE9-AO9,2) | ... BA9: =ROUND(W9-AG9-AQ9,2) | BB9: =SUM(AR9:BA9)
A10: 6 | B10: =EOMONTH(TODAY(),5) | C10: =MAX(0,(SUM('My Loans'!$E$6:$E$15)+'My Loans'!$D$3)-SUM($X10:$AG10)) | D10: =MAX(0,AR9) | E10: =MAX(0,AS9) | F10: =MAX(0,AT9) | G10: =MAX(0,AU9) | H10: =MAX(0,AV9) | I10: =MAX(0,AW9) | J10: =MAX(0,AX9) | K10: =MAX(0,AY9) | ... M10: =MAX(0,BA9) | N10: =IF(D10<0.5,0,D10*(1+N('My Loans'!D6)/1200)) | O10: =IF(E10<0.5,0,E10*(1+N('My Loans'!D7)/1200)) | P10: =IF(F10<0.5,0,F10*(1+N('My Loans'!D8)/1200)) | Q10: =IF(G10<0.5,0,G10*(1+N('My Loans'!D9)/1200)) | R10: =IF(H10<0.5,0,H10*(1+N('My Loans'!D10)/1200)) | S10: =IF(I10<0.5,0,I10*(1+N('My Loans'!D11)/1200)) | T10: =IF(J10<0.5,0,J10*(1+N('My Loans'!D12)/1200)) | U10: =IF(K10<0.5,0,K10*(1+N('My Loans'!D13)/1200)) | V10: =IF(L10<0.5,0,L10*(1+N('My Loans'!D14)/1200)) | W10: =IF(M10<0.5,0,M10*(1+N('My Loans'!D15)/1200)) | X10: =MIN(N10,N('My Loans'!E6)) | Y10: =MIN(O10,N('My Loans'!E7)) | Z10: =MIN(P10,N('My Loans'!E8)) | AA10: =MIN(Q10,N('My Loans'!E9)) | AB10: =MIN(R10,N('My Loans'!E10)) | AC10: =MIN(S10,N('My Loans'!E11)) | AD10: =MIN(T10,N('My Loans'!E12)) | AE10: =MIN(U10,N('My Loans'!E13)) | AF10: =MIN(V10,N('My Loans'!E14)) | AG10: =MIN(W10,N('My Loans'!E15)) | AH10: =MIN(N10-X10,MAX(0,$C10-SUMPRODUCT(($D$3:$M$3<D$3)*($N10:$W10-$X10:$AG10)))) | AI10: =MIN(O10-Y10,MAX(0,$C10-SUMPRODUCT(($D$3:$M$3<E$3)*($N10:$W10-$X10:$AG10)))) | AJ10: =MIN(P10-Z10,MAX(0,$C10-SUMPRODUCT(($D$3:$M$3<F$3)*($N10:$W10-$X10:$AG10)))) | AK10: =MIN(Q10-AA10,MAX(0,$C10-SUMPRODUCT(($D$3:$M$3<G$3)*($N10:$W10-$X10:$AG10)))) | AL10: =MIN(R10-AB10,MAX(0,$C10-SUMPRODUCT(($D$3:$M$3<H$3)*($N10:$W10-$X10:$AG10)))) | AM10: =MIN(S10-AC10,MAX(0,$C10-SUMPRODUCT(($D$3:$M$3<I$3)*($N10:$W10-$X10:$AG10)))) | AN10: =MIN(T10-AD10,MAX(0,$C10-SUMPRODUCT(($D$3:$M$3<J$3)*($N10:$W10-$X10:$AG10)))) | AO10: =MIN(U10-AE10,MAX(0,$C10-SUMPRODUCT(($D$3:$M$3<K$3)*($N10:$W10-$X10:$AG10)))) | ... AQ10: =MIN(W10-AG10,MAX(0,$C10-SUMPRODUCT(($D$3:$M$3<M$3)*($N10:$W10-$X10:$AG10)))) | AR10: =ROUND(N10-X10-AH10,2) | AS10: =ROUND(O10-Y10-AI10,2) | AT10: =ROUND(P10-Z10-AJ10,2) | AU10: =ROUND(Q10-AA10-AK10,2) | AV10: =ROUND(R10-AB10-AL10,2) | AW10: =ROUND(S10-AC10-AM10,2) | AX10: =ROUND(T10-AD10-AN10,2) | AY10: =ROUND(U10-AE10-AO10,2) | ... BA10: =ROUND(W10-AG10-AQ10,2) | BB10: =SUM(AR10:BA10)
A11: 7 | B11: =EOMONTH(TODAY(),6) | C11: =MAX(0,(SUM('My Loans'!$E$6:$E$15)+'My Loans'!$D$3)-SUM($X11:$AG11)) | D11: =MAX(0,AR10) | E11: =MAX(0,AS10) | F11: =MAX(0,AT10) | G11: =MAX(0,AU10) | H11: =MAX(0,AV10) | I11: =MAX(0,AW10) | J11: =MAX(0,AX10) | K11: =MAX(0,AY10) | ... M11: =MAX(0,BA10) | N11: =IF(D11<0.5,0,D11*(1+N('My Loans'!D6)/1200)) | O11: =IF(E11<0.5,0,E11*(1+N('My Loans'!D7)/1200)) | P11: =IF(F11<0.5,0,F11*(1+N('My Loans'!D8)/1200)) | Q11: =IF(G11<0.5,0,G11*(1+N('My Loans'!D9)/1200)) | R11: =IF(H11<0.5,0,H11*(1+N('My Loans'!D10)/1200)) | S11: =IF(I11<0.5,0,I11*(1+N('My Loans'!D11)/1200)) | T11: =IF(J11<0.5,0,J11*(1+N('My Loans'!D12)/1200)) | U11: =IF(K11<0.5,0,K11*(1+N('My Loans'!D13)/1200)) | V11: =IF(L11<0.5,0,L11*(1+N('My Loans'!D14)/1200)) | W11: =IF(M11<0.5,0,M11*(1+N('My Loans'!D15)/1200)) | X11: =MIN(N11,N('My Loans'!E6)) | Y11: =MIN(O11,N('My Loans'!E7)) | Z11: =MIN(P11,N('My Loans'!E8)) | AA11: =MIN(Q11,N('My Loans'!E9)) | AB11: =MIN(R11,N('My Loans'!E10)) | AC11: =MIN(S11,N('My Loans'!E11)) | AD11: =MIN(T11,N('My Loans'!E12)) | AE11: =MIN(U11,N('My Loans'!E13)) | AF11: =MIN(V11,N('My Loans'!E14)) | AG11: =MIN(W11,N('My Loans'!E15)) | AH11: =MIN(N11-X11,MAX(0,$C11-SUMPRODUCT(($D$3:$M$3<D$3)*($N11:$W11-$X11:$AG11)))) | AI11: =MIN(O11-Y11,MAX(0,$C11-SUMPRODUCT(($D$3:$M$3<E$3)*($N11:$W11-$X11:$AG11)))) | AJ11: =MIN(P11-Z11,MAX(0,$C11-SUMPRODUCT(($D$3:$M$3<F$3)*($N11:$W11-$X11:$AG11)))) | AK11: =MIN(Q11-AA11,MAX(0,$C11-SUMPRODUCT(($D$3:$M$3<G$3)*($N11:$W11-$X11:$AG11)))) | AL11: =MIN(R11-AB11,MAX(0,$C11-SUMPRODUCT(($D$3:$M$3<H$3)*($N11:$W11-$X11:$AG11)))) | AM11: =MIN(S11-AC11,MAX(0,$C11-SUMPRODUCT(($D$3:$M$3<I$3)*($N11:$W11-$X11:$AG11)))) | AN11: =MIN(T11-AD11,MAX(0,$C11-SUMPRODUCT(($D$3:$M$3<J$3)*($N11:$W11-$X11:$AG11)))) | AO11: =MIN(U11-AE11,MAX(0,$C11-SUMPRODUCT(($D$3:$M$3<K$3)*($N11:$W11-$X11:$AG11)))) | ... AQ11: =MIN(W11-AG11,MAX(0,$C11-SUMPRODUCT(($D$3:$M$3<M$3)*($N11:$W11-$X11:$AG11)))) | AR11: =ROUND(N11-X11-AH11,2) | AS11: =ROUND(O11-Y11-AI11,2) | AT11: =ROUND(P11-Z11-AJ11,2) | AU11: =ROUND(Q11-AA11-AK11,2) | AV11: =ROUND(R11-AB11-AL11,2) | AW11: =ROUND(S11-AC11-AM11,2) | AX11: =ROUND(T11-AD11-AN11,2) | AY11: =ROUND(U11-AE11-AO11,2) | ... BA11: =ROUND(W11-AG11-AQ11,2) | BB11: =SUM(AR11:BA11)
A12: 8 | B12: =EOMONTH(TODAY(),7) | C12: =MAX(0,(SUM('My Loans'!$E$6:$E$15)+'My Loans'!$D$3)-SUM($X12:$AG12)) | D12: =MAX(0,AR11) | E12: =MAX(0,AS11) | F12: =MAX(0,AT11) | G12: =MAX(0,AU11) | H12: =MAX(0,AV11) | I12: =MAX(0,AW11) | J12: =MAX(0,AX11) | K12: =MAX(0,AY11) | ... M12: =MAX(0,BA11) | N12: =IF(D12<0.5,0,D12*(1+N('My Loans'!D6)/1200)) | O12: =IF(E12<0.5,0,E12*(1+N('My Loans'!D7)/1200)) | P12: =IF(F12<0.5,0,F12*(1+N('My Loans'!D8)/1200)) | Q12: =IF(G12<0.5,0,G12*(1+N('My Loans'!D9)/1200)) | R12: =IF(H12<0.5,0,H12*(1+N('My Loans'!D10)/1200)) | S12: =IF(I12<0.5,0,I12*(1+N('My Loans'!D11)/1200)) | T12: =IF(J12<0.5,0,J12*(1+N('My Loans'!D12)/1200)) | U12: =IF(K12<0.5,0,K12*(1+N('My Loans'!D13)/1200)) | V12: =IF(L12<0.5,0,L12*(1+N('My Loans'!D14)/1200)) | W12: =IF(M12<0.5,0,M12*(1+N('My Loans'!D15)/1200)) | X12: =MIN(N12,N('My Loans'!E6)) | Y12: =MIN(O12,N('My Loans'!E7)) | Z12: =MIN(P12,N('My Loans'!E8)) | AA12: =MIN(Q12,N('My Loans'!E9)) | AB12: =MIN(R12,N('My Loans'!E10)) | AC12: =MIN(S12,N('My Loans'!E11)) | AD12: =MIN(T12,N('My Loans'!E12)) | AE12: =MIN(U12,N('My Loans'!E13)) | AF12: =MIN(V12,N('My Loans'!E14)) | AG12: =MIN(W12,N('My Loans'!E15)) | AH12: =MIN(N12-X12,MAX(0,$C12-SUMPRODUCT(($D$3:$M$3<D$3)*($N12:$W12-$X12:$AG12)))) | AI12: =MIN(O12-Y12,MAX(0,$C12-SUMPRODUCT(($D$3:$M$3<E$3)*($N12:$W12-$X12:$AG12)))) | AJ12: =MIN(P12-Z12,MAX(0,$C12-SUMPRODUCT(($D$3:$M$3<F$3)*($N12:$W12-$X12:$AG12)))) | AK12: =MIN(Q12-AA12,MAX(0,$C12-SUMPRODUCT(($D$3:$M$3<G$3)*($N12:$W12-$X12:$AG12)))) | AL12: =MIN(R12-AB12,MAX(0,$C12-SUMPRODUCT(($D$3:$M$3<H$3)*($N12:$W12-$X12:$AG12)))) | AM12: =MIN(S12-AC12,MAX(0,$C12-SUMPRODUCT(($D$3:$M$3<I$3)*($N12:$W12-$X12:$AG12)))) | AN12: =MIN(T12-AD12,MAX(0,$C12-SUMPRODUCT(($D$3:$M$3<J$3)*($N12:$W12-$X12:$AG12)))) | AO12: =MIN(U12-AE12,MAX(0,$C12-SUMPRODUCT(($D$3:$M$3<K$3)*($N12:$W12-$X12:$AG12)))) | ... AQ12: =MIN(W12-AG12,MAX(0,$C12-SUMPRODUCT(($D$3:$M$3<M$3)*($N12:$W12-$X12:$AG12)))) | AR12: =ROUND(N12-X12-AH12,2) | AS12: =ROUND(O12-Y12-AI12,2) | AT12: =ROUND(P12-Z12-AJ12,2) | AU12: =ROUND(Q12-AA12-AK12,2) | AV12: =ROUND(R12-AB12-AL12,2) | AW12: =ROUND(S12-AC12-AM12,2) | AX12: =ROUND(T12-AD12-AN12,2) | AY12: =ROUND(U12-AE12-AO12,2) | ... BA12: =ROUND(W12-AG12-AQ12,2) | BB12: =SUM(AR12:BA12)
A13: 9 | B13: =EOMONTH(TODAY(),8) | C13: =MAX(0,(SUM('My Loans'!$E$6:$E$15)+'My Loans'!$D$3)-SUM($X13:$AG13)) | D13: =MAX(0,AR12) | E13: =MAX(0,AS12) | F13: =MAX(0,AT12) | G13: =MAX(0,AU12) | H13: =MAX(0,AV12) | I13: =MAX(0,AW12) | J13: =MAX(0,AX12) | K13: =MAX(0,AY12) | ... M13: =MAX(0,BA12) | N13: =IF(D13<0.5,0,D13*(1+N('My Loans'!D6)/1200)) | O13: =IF(E13<0.5,0,E13*(1+N('My Loans'!D7)/1200)) | P13: =IF(F13<0.5,0,F13*(1+N('My Loans'!D8)/1200)) | Q13: =IF(G13<0.5,0,G13*(1+N('My Loans'!D9)/1200)) | R13: =IF(H13<0.5,0,H13*(1+N('My Loans'!D10)/1200)) | S13: =IF(I13<0.5,0,I13*(1+N('My Loans'!D11)/1200)) | T13: =IF(J13<0.5,0,J13*(1+N('My Loans'!D12)/1200)) | U13: =IF(K13<0.5,0,K13*(1+N('My Loans'!D13)/1200)) | V13: =IF(L13<0.5,0,L13*(1+N('My Loans'!D14)/1200)) | W13: =IF(M13<0.5,0,M13*(1+N('My Loans'!D15)/1200)) | X13: =MIN(N13,N('My Loans'!E6)) | Y13: =MIN(O13,N('My Loans'!E7)) | Z13: =MIN(P13,N('My Loans'!E8)) | AA13: =MIN(Q13,N('My Loans'!E9)) | AB13: =MIN(R13,N('My Loans'!E10)) | AC13: =MIN(S13,N('My Loans'!E11)) | AD13: =MIN(T13,N('My Loans'!E12)) | AE13: =MIN(U13,N('My Loans'!E13)) | AF13: =MIN(V13,N('My Loans'!E14)) | AG13: =MIN(W13,N('My Loans'!E15)) | AH13: =MIN(N13-X13,MAX(0,$C13-SUMPRODUCT(($D$3:$M$3<D$3)*($N13:$W13-$X13:$AG13)))) | AI13: =MIN(O13-Y13,MAX(0,$C13-SUMPRODUCT(($D$3:$M$3<E$3)*($N13:$W13-$X13:$AG13)))) | AJ13: =MIN(P13-Z13,MAX(0,$C13-SUMPRODUCT(($D$3:$M$3<F$3)*($N13:$W13-$X13:$AG13)))) | AK13: =MIN(Q13-AA13,MAX(0,$C13-SUMPRODUCT(($D$3:$M$3<G$3)*($N13:$W13-$X13:$AG13)))) | AL13: =MIN(R13-AB13,MAX(0,$C13-SUMPRODUCT(($D$3:$M$3<H$3)*($N13:$W13-$X13:$AG13)))) | AM13: =MIN(S13-AC13,MAX(0,$C13-SUMPRODUCT(($D$3:$M$3<I$3)*($N13:$W13-$X13:$AG13)))) | AN13: =MIN(T13-AD13,MAX(0,$C13-SUMPRODUCT(($D$3:$M$3<J$3)*($N13:$W13-$X13:$AG13)))) | AO13: =MIN(U13-AE13,MAX(0,$C13-SUMPRODUCT(($D$3:$M$3<K$3)*($N13:$W13-$X13:$AG13)))) | ... AQ13: =MIN(W13-AG13,MAX(0,$C13-SUMPRODUCT(($D$3:$M$3<M$3)*($N13:$W13-$X13:$AG13)))) | AR13: =ROUND(N13-X13-AH13,2) | AS13: =ROUND(O13-Y13-AI13,2) | AT13: =ROUND(P13-Z13-AJ13,2) | AU13: =ROUND(Q13-AA13-AK13,2) | AV13: =ROUND(R13-AB13-AL13,2) | AW13: =ROUND(S13-AC13-AM13,2) | AX13: =ROUND(T13-AD13-AN13,2) | AY13: =ROUND(U13-AE13-AO13,2) | ... BA13: =ROUND(W13-AG13-AQ13,2) | BB13: =SUM(AR13:BA13)
A14: 10 | B14: =EOMONTH(TODAY(),9) | C14: =MAX(0,(SUM('My Loans'!$E$6:$E$15)+'My Loans'!$D$3)-SUM($X14:$AG14)) | D14: =MAX(0,AR13) | E14: =MAX(0,AS13) | F14: =MAX(0,AT13) | G14: =MAX(0,AU13) | H14: =MAX(0,AV13) | I14: =MAX(0,AW13) | J14: =MAX(0,AX13) | K14: =MAX(0,AY13) | ... M14: =MAX(0,BA13) | N14: =IF(D14<0.5,0,D14*(1+N('My Loans'!D6)/1200)) | O14: =IF(E14<0.5,0,E14*(1+N('My Loans'!D7)/1200)) | P14: =IF(F14<0.5,0,F14*(1+N('My Loans'!D8)/1200)) | Q14: =IF(G14<0.5,0,G14*(1+N('My Loans'!D9)/1200)) | R14: =IF(H14<0.5,0,H14*(1+N('My Loans'!D10)/1200)) | S14: =IF(I14<0.5,0,I14*(1+N('My Loans'!D11)/1200)) | T14: =IF(J14<0.5,0,J14*(1+N('My Loans'!D12)/1200)) | U14: =IF(K14<0.5,0,K14*(1+N('My Loans'!D13)/1200)) | V14: =IF(L14<0.5,0,L14*(1+N('My Loans'!D14)/1200)) | W14: =IF(M14<0.5,0,M14*(1+N('My Loans'!D15)/1200)) | X14: =MIN(N14,N('My Loans'!E6)) | Y14: =MIN(O14,N('My Loans'!E7)) | Z14: =MIN(P14,N('My Loans'!E8)) | AA14: =MIN(Q14,N('My Loans'!E9)) | AB14: =MIN(R14,N('My Loans'!E10)) | AC14: =MIN(S14,N('My Loans'!E11)) | AD14: =MIN(T14,N('My Loans'!E12)) | AE14: =MIN(U14,N('My Loans'!E13)) | AF14: =MIN(V14,N('My Loans'!E14)) | AG14: =MIN(W14,N('My Loans'!E15)) | AH14: =MIN(N14-X14,MAX(0,$C14-SUMPRODUCT(($D$3:$M$3<D$3)*($N14:$W14-$X14:$AG14)))) | AI14: =MIN(O14-Y14,MAX(0,$C14-SUMPRODUCT(($D$3:$M$3<E$3)*($N14:$W14-$X14:$AG14)))) | AJ14: =MIN(P14-Z14,MAX(0,$C14-SUMPRODUCT(($D$3:$M$3<F$3)*($N14:$W14-$X14:$AG14)))) | AK14: =MIN(Q14-AA14,MAX(0,$C14-SUMPRODUCT(($D$3:$M$3<G$3)*($N14:$W14-$X14:$AG14)))) | AL14: =MIN(R14-AB14,MAX(0,$C14-SUMPRODUCT(($D$3:$M$3<H$3)*($N14:$W14-$X14:$AG14)))) | AM14: =MIN(S14-AC14,MAX(0,$C14-SUMPRODUCT(($D$3:$M$3<I$3)*($N14:$W14-$X14:$AG14)))) | AN14: =MIN(T14-AD14,MAX(0,$C14-SUMPRODUCT(($D$3:$M$3<J$3)*($N14:$W14-$X14:$AG14)))) | AO14: =MIN(U14-AE14,MAX(0,$C14-SUMPRODUCT(($D$3:$M$3<K$3)*($N14:$W14-$X14:$AG14)))) | ... AQ14: =MIN(W14-AG14,MAX(0,$C14-SUMPRODUCT(($D$3:$M$3<M$3)*($N14:$W14-$X14:$AG14)))) | AR14: =ROUND(N14-X14-AH14,2) | AS14: =ROUND(O14-Y14-AI14,2) | AT14: =ROUND(P14-Z14-AJ14,2) | AU14: =ROUND(Q14-AA14-AK14,2) | AV14: =ROUND(R14-AB14-AL14,2) | AW14: =ROUND(S14-AC14-AM14,2) | AX14: =ROUND(T14-AD14-AN14,2) | AY14: =ROUND(U14-AE14-AO14,2) | ... BA14: =ROUND(W14-AG14-AQ14,2) | BB14: =SUM(AR14:BA14)
A15: 11 | B15: =EOMONTH(TODAY(),10) | C15: =MAX(0,(SUM('My Loans'!$E$6:$E$15)+'My Loans'!$D$3)-SUM($X15:$AG15)) | D15: =MAX(0,AR14) | E15: =MAX(0,AS14) | F15: =MAX(0,AT14) | G15: =MAX(0,AU14) | H15: =MAX(0,AV14) | I15: =MAX(0,AW14) | J15: =MAX(0,AX14) | K15: =MAX(0,AY14) | ... M15: =MAX(0,BA14) | N15: =IF(D15<0.5,0,D15*(1+N('My Loans'!D6)/1200)) | O15: =IF(E15<0.5,0,E15*(1+N('My Loans'!D7)/1200)) | P15: =IF(F15<0.5,0,F15*(1+N('My Loans'!D8)/1200)) | Q15: =IF(G15<0.5,0,G15*(1+N('My Loans'!D9)/1200)) | R15: =IF(H15<0.5,0,H15*(1+N('My Loans'!D10)/1200)) | S15: =IF(I15<0.5,0,I15*(1+N('My Loans'!D11)/1200)) | T15: =IF(J15<0.5,0,J15*(1+N('My Loans'!D12)/1200)) | U15: =IF(K15<0.5,0,K15*(1+N('My Loans'!D13)/1200)) | V15: =IF(L15<0.5,0,L15*(1+N('My Loans'!D14)/1200)) | W15: =IF(M15<0.5,0,M15*(1+N('My Loans'!D15)/1200)) | X15: =MIN(N15,N('My Loans'!E6)) | Y15: =MIN(O15,N('My Loans'!E7)) | Z15: =MIN(P15,N('My Loans'!E8)) | AA15: =MIN(Q15,N('My Loans'!E9)) | AB15: =MIN(R15,N('My Loans'!E10)) | AC15: =MIN(S15,N('My Loans'!E11)) | AD15: =MIN(T15,N('My Loans'!E12)) | AE15: =MIN(U15,N('My Loans'!E13)) | AF15: =MIN(V15,N('My Loans'!E14)) | AG15: =MIN(W15,N('My Loans'!E15)) | AH15: =MIN(N15-X15,MAX(0,$C15-SUMPRODUCT(($D$3:$M$3<D$3)*($N15:$W15-$X15:$AG15)))) | AI15: =MIN(O15-Y15,MAX(0,$C15-SUMPRODUCT(($D$3:$M$3<E$3)*($N15:$W15-$X15:$AG15)))) | AJ15: =MIN(P15-Z15,MAX(0,$C15-SUMPRODUCT(($D$3:$M$3<F$3)*($N15:$W15-$X15:$AG15)))) | AK15: =MIN(Q15-AA15,MAX(0,$C15-SUMPRODUCT(($D$3:$M$3<G$3)*($N15:$W15-$X15:$AG15)))) | AL15: =MIN(R15-AB15,MAX(0,$C15-SUMPRODUCT(($D$3:$M$3<H$3)*($N15:$W15-$X15:$AG15)))) | AM15: =MIN(S15-AC15,MAX(0,$C15-SUMPRODUCT(($D$3:$M$3<I$3)*($N15:$W15-$X15:$AG15)))) | AN15: =MIN(T15-AD15,MAX(0,$C15-SUMPRODUCT(($D$3:$M$3<J$3)*($N15:$W15-$X15:$AG15)))) | AO15: =MIN(U15-AE15,MAX(0,$C15-SUMPRODUCT(($D$3:$M$3<K$3)*($N15:$W15-$X15:$AG15)))) | ... AQ15: =MIN(W15-AG15,MAX(0,$C15-SUMPRODUCT(($D$3:$M$3<M$3)*($N15:$W15-$X15:$AG15)))) | AR15: =ROUND(N15-X15-AH15,2) | AS15: =ROUND(O15-Y15-AI15,2) | AT15: =ROUND(P15-Z15-AJ15,2) | AU15: =ROUND(Q15-AA15-AK15,2) | AV15: =ROUND(R15-AB15-AL15,2) | AW15: =ROUND(S15-AC15-AM15,2) | AX15: =ROUND(T15-AD15-AN15,2) | AY15: =ROUND(U15-AE15-AO15,2) | ... BA15: =ROUND(W15-AG15-AQ15,2) | BB15: =SUM(AR15:BA15)
A16: 12 | B16: =EOMONTH(TODAY(),11) | C16: =MAX(0,(SUM('My Loans'!$E$6:$E$15)+'My Loans'!$D$3)-SUM($X16:$AG16)) | D16: =MAX(0,AR15) | E16: =MAX(0,AS15) | F16: =MAX(0,AT15) | G16: =MAX(0,AU15) | H16: =MAX(0,AV15) | I16: =MAX(0,AW15) | J16: =MAX(0,AX15) | K16: =MAX(0,AY15) | ... M16: =MAX(0,BA15) | N16: =IF(D16<0.5,0,D16*(1+N('My Loans'!D6)/1200)) | O16: =IF(E16<0.5,0,E16*(1+N('My Loans'!D7)/1200)) | P16: =IF(F16<0.5,0,F16*(1+N('My Loans'!D8)/1200)) | Q16: =IF(G16<0.5,0,G16*(1+N('My Loans'!D9)/1200)) | R16: =IF(H16<0.5,0,H16*(1+N('My Loans'!D10)/1200)) | S16: =IF(I16<0.5,0,I16*(1+N('My Loans'!D11)/1200)) | T16: =IF(J16<0.5,0,J16*(1+N('My Loans'!D12)/1200)) | U16: =IF(K16<0.5,0,K16*(1+N('My Loans'!D13)/1200)) | V16: =IF(L16<0.5,0,L16*(1+N('My Loans'!D14)/1200)) | W16: =IF(M16<0.5,0,M16*(1+N('My Loans'!D15)/1200)) | X16: =MIN(N16,N('My Loans'!E6)) | Y16: =MIN(O16,N('My Loans'!E7)) | Z16: =MIN(P16,N('My Loans'!E8)) | AA16: =MIN(Q16,N('My Loans'!E9)) | AB16: =MIN(R16,N('My Loans'!E10)) | AC16: =MIN(S16,N('My Loans'!E11)) | AD16: =MIN(T16,N('My Loans'!E12)) | AE16: =MIN(U16,N('My Loans'!E13)) | AF16: =MIN(V16,N('My Loans'!E14)) | AG16: =MIN(W16,N('My Loans'!E15)) | AH16: =MIN(N16-X16,MAX(0,$C16-SUMPRODUCT(($D$3:$M$3<D$3)*($N16:$W16-$X16:$AG16)))) | AI16: =MIN(O16-Y16,MAX(0,$C16-SUMPRODUCT(($D$3:$M$3<E$3)*($N16:$W16-$X16:$AG16)))) | AJ16: =MIN(P16-Z16,MAX(0,$C16-SUMPRODUCT(($D$3:$M$3<F$3)*($N16:$W16-$X16:$AG16)))) | AK16: =MIN(Q16-AA16,MAX(0,$C16-SUMPRODUCT(($D$3:$M$3<G$3)*($N16:$W16-$X16:$AG16)))) | AL16: =MIN(R16-AB16,MAX(0,$C16-SUMPRODUCT(($D$3:$M$3<H$3)*($N16:$W16-$X16:$AG16)))) | AM16: =MIN(S16-AC16,MAX(0,$C16-SUMPRODUCT(($D$3:$M$3<I$3)*($N16:$W16-$X16:$AG16)))) | AN16: =MIN(T16-AD16,MAX(0,$C16-SUMPRODUCT(($D$3:$M$3<J$3)*($N16:$W16-$X16:$AG16)))) | AO16: =MIN(U16-AE16,MAX(0,$C16-SUMPRODUCT(($D$3:$M$3<K$3)*($N16:$W16-$X16:$AG16)))) | ... AQ16: =MIN(W16-AG16,MAX(0,$C16-SUMPRODUCT(($D$3:$M$3<M$3)*($N16:$W16-$X16:$AG16)))) | AR16: =ROUND(N16-X16-AH16,2) | AS16: =ROUND(O16-Y16-AI16,2) | AT16: =ROUND(P16-Z16-AJ16,2) | AU16: =ROUND(Q16-AA16-AK16,2) | AV16: =ROUND(R16-AB16-AL16,2) | AW16: =ROUND(S16-AC16-AM16,2) | AX16: =ROUND(T16-AD16-AN16,2) | AY16: =ROUND(U16-AE16-AO16,2) | ... BA16: =ROUND(W16-AG16-AQ16,2) | BB16: =SUM(AR16:BA16)
A17: 13 | B17: =EOMONTH(TODAY(),12) | C17: =MAX(0,(SUM('My Loans'!$E$6:$E$15)+'My Loans'!$D$3)-SUM($X17:$AG17)) | D17: =MAX(0,AR16) | E17: =MAX(0,AS16) | F17: =MAX(0,AT16) | G17: =MAX(0,AU16) | H17: =MAX(0,AV16) | I17: =MAX(0,AW16) | J17: =MAX(0,AX16) | K17: =MAX(0,AY16) | ... M17: =MAX(0,BA16) | N17: =IF(D17<0.5,0,D17*(1+N('My Loans'!D6)/1200)) | O17: =IF(E17<0.5,0,E17*(1+N('My Loans'!D7)/1200)) | P17: =IF(F17<0.5,0,F17*(1+N('My Loans'!D8)/1200)) | Q17: =IF(G17<0.5,0,G17*(1+N('My Loans'!D9)/1200)) | R17: =IF(H17<0.5,0,H17*(1+N('My Loans'!D10)/1200)) | S17: =IF(I17<0.5,0,I17*(1+N('My Loans'!D11)/1200)) | T17: =IF(J17<0.5,0,J17*(1+N('My Loans'!D12)/1200)) | U17: =IF(K17<0.5,0,K17*(1+N('My Loans'!D13)/1200)) | V17: =IF(L17<0.5,0,L17*(1+N('My Loans'!D14)/1200)) | W17: =IF(M17<0.5,0,M17*(1+N('My Loans'!D15)/1200)) | X17: =MIN(N17,N('My Loans'!E6)) | Y17: =MIN(O17,N('My Loans'!E7)) | Z17: =MIN(P17,N('My Loans'!E8)) | AA17: =MIN(Q17,N('My Loans'!E9)) | AB17: =MIN(R17,N('My Loans'!E10)) | AC17: =MIN(S17,N('My Loans'!E11)) | AD17: =MIN(T17,N('My Loans'!E12)) | AE17: =MIN(U17,N('My Loans'!E13)) | AF17: =MIN(V17,N('My Loans'!E14)) | AG17: =MIN(W17,N('My Loans'!E15)) | AH17: =MIN(N17-X17,MAX(0,$C17-SUMPRODUCT(($D$3:$M$3<D$3)*($N17:$W17-$X17:$AG17)))) | AI17: =MIN(O17-Y17,MAX(0,$C17-SUMPRODUCT(($D$3:$M$3<E$3)*($N17:$W17-$X17:$AG17)))) | AJ17: =MIN(P17-Z17,MAX(0,$C17-SUMPRODUCT(($D$3:$M$3<F$3)*($N17:$W17-$X17:$AG17)))) | AK17: =MIN(Q17-AA17,MAX(0,$C17-SUMPRODUCT(($D$3:$M$3<G$3)*($N17:$W17-$X17:$AG17)))) | AL17: =MIN(R17-AB17,MAX(0,$C17-SUMPRODUCT(($D$3:$M$3<H$3)*($N17:$W17-$X17:$AG17)))) | AM17: =MIN(S17-AC17,MAX(0,$C17-SUMPRODUCT(($D$3:$M$3<I$3)*($N17:$W17-$X17:$AG17)))) | AN17: =MIN(T17-AD17,MAX(0,$C17-SUMPRODUCT(($D$3:$M$3<J$3)*($N17:$W17-$X17:$AG17)))) | AO17: =MIN(U17-AE17,MAX(0,$C17-SUMPRODUCT(($D$3:$M$3<K$3)*($N17:$W17-$X17:$AG17)))) | ... AQ17: =MIN(W17-AG17,MAX(0,$C17-SUMPRODUCT(($D$3:$M$3<M$3)*($N17:$W17-$X17:$AG17)))) | AR17: =ROUND(N17-X17-AH17,2) | AS17: =ROUND(O17-Y17-AI17,2) | AT17: =ROUND(P17-Z17-AJ17,2) | AU17: =ROUND(Q17-AA17-AK17,2) | AV17: =ROUND(R17-AB17-AL17,2) | AW17: =ROUND(S17-AC17-AM17,2) | AX17: =ROUND(T17-AD17-AN17,2) | AY17: =ROUND(U17-AE17-AO17,2) | ... BA17: =ROUND(W17-AG17-AQ17,2) | BB17: =SUM(AR17:BA17)
A18: 14 | B18: =EOMONTH(TODAY(),13) | C18: =MAX(0,(SUM('My Loans'!$E$6:$E$15)+'My Loans'!$D$3)-SUM($X18:$AG18)) | D18: =MAX(0,AR17) | E18: =MAX(0,AS17) | F18: =MAX(0,AT17) | G18: =MAX(0,AU17) | H18: =MAX(0,AV17) | I18: =MAX(0,AW17) | J18: =MAX(0,AX17) | K18: =MAX(0,AY17) | ... M18: =MAX(0,BA17) | N18: =IF(D18<0.5,0,D18*(1+N('My Loans'!D6)/1200)) | O18: =IF(E18<0.5,0,E18*(1+N('My Loans'!D7)/1200)) | P18: =IF(F18<0.5,0,F18*(1+N('My Loans'!D8)/1200)) | Q18: =IF(G18<0.5,0,G18*(1+N('My Loans'!D9)/1200)) | R18: =IF(H18<0.5,0,H18*(1+N('My Loans'!D10)/1200)) | S18: =IF(I18<0.5,0,I18*(1+N('My Loans'!D11)/1200)) | T18: =IF(J18<0.5,0,J18*(1+N('My Loans'!D12)/1200)) | U18: =IF(K18<0.5,0,K18*(1+N('My Loans'!D13)/1200)) | V18: =IF(L18<0.5,0,L18*(1+N('My Loans'!D14)/1200)) | W18: =IF(M18<0.5,0,M18*(1+N('My Loans'!D15)/1200)) | X18: =MIN(N18,N('My Loans'!E6)) | Y18: =MIN(O18,N('My Loans'!E7)) | Z18: =MIN(P18,N('My Loans'!E8)) | AA18: =MIN(Q18,N('My Loans'!E9)) | AB18: =MIN(R18,N('My Loans'!E10)) | AC18: =MIN(S18,N('My Loans'!E11)) | AD18: =MIN(T18,N('My Loans'!E12)) | AE18: =MIN(U18,N('My Loans'!E13)) | AF18: =MIN(V18,N('My Loans'!E14)) | AG18: =MIN(W18,N('My Loans'!E15)) | AH18: =MIN(N18-X18,MAX(0,$C18-SUMPRODUCT(($D$3:$M$3<D$3)*($N18:$W18-$X18:$AG18)))) | AI18: =MIN(O18-Y18,MAX(0,$C18-SUMPRODUCT(($D$3:$M$3<E$3)*($N18:$W18-$X18:$AG18)))) | AJ18: =MIN(P18-Z18,MAX(0,$C18-SUMPRODUCT(($D$3:$M$3<F$3)*($N18:$W18-$X18:$AG18)))) | AK18: =MIN(Q18-AA18,MAX(0,$C18-SUMPRODUCT(($D$3:$M$3<G$3)*($N18:$W18-$X18:$AG18)))) | AL18: =MIN(R18-AB18,MAX(0,$C18-SUMPRODUCT(($D$3:$M$3<H$3)*($N18:$W18-$X18:$AG18)))) | AM18: =MIN(S18-AC18,MAX(0,$C18-SUMPRODUCT(($D$3:$M$3<I$3)*($N18:$W18-$X18:$AG18)))) | AN18: =MIN(T18-AD18,MAX(0,$C18-SUMPRODUCT(($D$3:$M$3<J$3)*($N18:$W18-$X18:$AG18)))) | AO18: =MIN(U18-AE18,MAX(0,$C18-SUMPRODUCT(($D$3:$M$3<K$3)*($N18:$W18-$X18:$AG18)))) | ... AQ18: =MIN(W18-AG18,MAX(0,$C18-SUMPRODUCT(($D$3:$M$3<M$3)*($N18:$W18-$X18:$AG18)))) | AR18: =ROUND(N18-X18-AH18,2) | AS18: =ROUND(O18-Y18-AI18,2) | AT18: =ROUND(P18-Z18-AJ18,2) | AU18: =ROUND(Q18-AA18-AK18,2) | AV18: =ROUND(R18-AB18-AL18,2) | AW18: =ROUND(S18-AC18-AM18,2) | AX18: =ROUND(T18-AD18-AN18,2) | AY18: =ROUND(U18-AE18-AO18,2) | ... BA18: =ROUND(W18-AG18-AQ18,2) | BB18: =SUM(AR18:BA18)
A19: 15 | B19: =EOMONTH(TODAY(),14) | C19: =MAX(0,(SUM('My Loans'!$E$6:$E$15)+'My Loans'!$D$3)-SUM($X19:$AG19)) | D19: =MAX(0,AR18) | E19: =MAX(0,AS18) | F19: =MAX(0,AT18) | G19: =MAX(0,AU18) | H19: =MAX(0,AV18) | I19: =MAX(0,AW18) | J19: =MAX(0,AX18) | K19: =MAX(0,AY18) | ... M19: =MAX(0,BA18) | N19: =IF(D19<0.5,0,D19*(1+N('My Loans'!D6)/1200)) | O19: =IF(E19<0.5,0,E19*(1+N('My Loans'!D7)/1200)) | P19: =IF(F19<0.5,0,F19*(1+N('My Loans'!D8)/1200)) | Q19: =IF(G19<0.5,0,G19*(1+N('My Loans'!D9)/1200)) | R19: =IF(H19<0.5,0,H19*(1+N('My Loans'!D10)/1200)) | S19: =IF(I19<0.5,0,I19*(1+N('My Loans'!D11)/1200)) | T19: =IF(J19<0.5,0,J19*(1+N('My Loans'!D12)/1200)) | U19: =IF(K19<0.5,0,K19*(1+N('My Loans'!D13)/1200)) | V19: =IF(L19<0.5,0,L19*(1+N('My Loans'!D14)/1200)) | W19: =IF(M19<0.5,0,M19*(1+N('My Loans'!D15)/1200)) | X19: =MIN(N19,N('My Loans'!E6)) | Y19: =MIN(O19,N('My Loans'!E7)) | Z19: =MIN(P19,N('My Loans'!E8)) | AA19: =MIN(Q19,N('My Loans'!E9)) | AB19: =MIN(R19,N('My Loans'!E10)) | AC19: =MIN(S19,N('My Loans'!E11)) | AD19: =MIN(T19,N('My Loans'!E12)) | AE19: =MIN(U19,N('My Loans'!E13)) | AF19: =MIN(V19,N('My Loans'!E14)) | AG19: =MIN(W19,N('My Loans'!E15)) | AH19: =MIN(N19-X19,MAX(0,$C19-SUMPRODUCT(($D$3:$M$3<D$3)*($N19:$W19-$X19:$AG19)))) | AI19: =MIN(O19-Y19,MAX(0,$C19-SUMPRODUCT(($D$3:$M$3<E$3)*($N19:$W19-$X19:$AG19)))) | AJ19: =MIN(P19-Z19,MAX(0,$C19-SUMPRODUCT(($D$3:$M$3<F$3)*($N19:$W19-$X19:$AG19)))) | AK19: =MIN(Q19-AA19,MAX(0,$C19-SUMPRODUCT(($D$3:$M$3<G$3)*($N19:$W19-$X19:$AG19)))) | AL19: =MIN(R19-AB19,MAX(0,$C19-SUMPRODUCT(($D$3:$M$3<H$3)*($N19:$W19-$X19:$AG19)))) | AM19: =MIN(S19-AC19,MAX(0,$C19-SUMPRODUCT(($D$3:$M$3<I$3)*($N19:$W19-$X19:$AG19)))) | AN19: =MIN(T19-AD19,MAX(0,$C19-SUMPRODUCT(($D$3:$M$3<J$3)*($N19:$W19-$X19:$AG19)))) | AO19: =MIN(U19-AE19,MAX(0,$C19-SUMPRODUCT(($D$3:$M$3<K$3)*($N19:$W19-$X19:$AG19)))) | ... AQ19: =MIN(W19-AG19,MAX(0,$C19-SUMPRODUCT(($D$3:$M$3<M$3)*($N19:$W19-$X19:$AG19)))) | AR19: =ROUND(N19-X19-AH19,2) | AS19: =ROUND(O19-Y19-AI19,2) | AT19: =ROUND(P19-Z19-AJ19,2) | AU19: =ROUND(Q19-AA19-AK19,2) | AV19: =ROUND(R19-AB19-AL19,2) | AW19: =ROUND(S19-AC19-AM19,2) | AX19: =ROUND(T19-AD19-AN19,2) | AY19: =ROUND(U19-AE19-AO19,2) | ... BA19: =ROUND(W19-AG19-AQ19,2) | BB19: =SUM(AR19:BA19)
A20: 16 | B20: =EOMONTH(TODAY(),15) | C20: =MAX(0,(SUM('My Loans'!$E$6:$E$15)+'My Loans'!$D$3)-SUM($X20:$AG20)) | D20: =MAX(0,AR19) | E20: =MAX(0,AS19) | F20: =MAX(0,AT19) | G20: =MAX(0,AU19) | H20: =MAX(0,AV19) | I20: =MAX(0,AW19) | J20: =MAX(0,AX19) | K20: =MAX(0,AY19) | ... M20: =MAX(0,BA19) | N20: =IF(D20<0.5,0,D20*(1+N('My Loans'!D6)/1200)) | O20: =IF(E20<0.5,0,E20*(1+N('My Loans'!D7)/1200)) | P20: =IF(F20<0.5,0,F20*(1+N('My Loans'!D8)/1200)) | Q20: =IF(G20<0.5,0,G20*(1+N('My Loans'!D9)/1200)) | R20: =IF(H20<0.5,0,H20*(1+N('My Loans'!D10)/1200)) | S20: =IF(I20<0.5,0,I20*(1+N('My Loans'!D11)/1200)) | T20: =IF(J20<0.5,0,J20*(1+N('My Loans'!D12)/1200)) | U20: =IF(K20<0.5,0,K20*(1+N('My Loans'!D13)/1200)) | V20: =IF(L20<0.5,0,L20*(1+N('My Loans'!D14)/1200)) | W20: =IF(M20<0.5,0,M20*(1+N('My Loans'!D15)/1200)) | X20: =MIN(N20,N('My Loans'!E6)) | Y20: =MIN(O20,N('My Loans'!E7)) | Z20: =MIN(P20,N('My Loans'!E8)) | AA20: =MIN(Q20,N('My Loans'!E9)) | AB20: =MIN(R20,N('My Loans'!E10)) | AC20: =MIN(S20,N('My Loans'!E11)) | AD20: =MIN(T20,N('My Loans'!E12)) | AE20: =MIN(U20,N('My Loans'!E13)) | AF20: =MIN(V20,N('My Loans'!E14)) | AG20: =MIN(W20,N('My Loans'!E15)) | AH20: =MIN(N20-X20,MAX(0,$C20-SUMPRODUCT(($D$3:$M$3<D$3)*($N20:$W20-$X20:$AG20)))) | AI20: =MIN(O20-Y20,MAX(0,$C20-SUMPRODUCT(($D$3:$M$3<E$3)*($N20:$W20-$X20:$AG20)))) | AJ20: =MIN(P20-Z20,MAX(0,$C20-SUMPRODUCT(($D$3:$M$3<F$3)*($N20:$W20-$X20:$AG20)))) | AK20: =MIN(Q20-AA20,MAX(0,$C20-SUMPRODUCT(($D$3:$M$3<G$3)*($N20:$W20-$X20:$AG20)))) | AL20: =MIN(R20-AB20,MAX(0,$C20-SUMPRODUCT(($D$3:$M$3<H$3)*($N20:$W20-$X20:$AG20)))) | AM20: =MIN(S20-AC20,MAX(0,$C20-SUMPRODUCT(($D$3:$M$3<I$3)*($N20:$W20-$X20:$AG20)))) | AN20: =MIN(T20-AD20,MAX(0,$C20-SUMPRODUCT(($D$3:$M$3<J$3)*($N20:$W20-$X20:$AG20)))) | AO20: =MIN(U20-AE20,MAX(0,$C20-SUMPRODUCT(($D$3:$M$3<K$3)*($N20:$W20-$X20:$AG20)))) | ... AQ20: =MIN(W20-AG20,MAX(0,$C20-SUMPRODUCT(($D$3:$M$3<M$3)*($N20:$W20-$X20:$AG20)))) | AR20: =ROUND(N20-X20-AH20,2) | AS20: =ROUND(O20-Y20-AI20,2) | AT20: =ROUND(P20-Z20-AJ20,2) | AU20: =ROUND(Q20-AA20-AK20,2) | AV20: =ROUND(R20-AB20-AL20,2) | AW20: =ROUND(S20-AC20-AM20,2) | AX20: =ROUND(T20-AD20-AN20,2) | AY20: =ROUND(U20-AE20-AO20,2) | ... BA20: =ROUND(W20-AG20-AQ20,2) | BB20: =SUM(AR20:BA20)
A21: 17 | B21: =EOMONTH(TODAY(),16) | C21: =MAX(0,(SUM('My Loans'!$E$6:$E$15)+'My Loans'!$D$3)-SUM($X21:$AG21)) | D21: =MAX(0,AR20) | E21: =MAX(0,AS20) | F21: =MAX(0,AT20) | G21: =MAX(0,AU20) | H21: =MAX(0,AV20) | I21: =MAX(0,AW20) | J21: =MAX(0,AX20) | K21: =MAX(0,AY20) | ... M21: =MAX(0,BA20) | N21: =IF(D21<0.5,0,D21*(1+N('My Loans'!D6)/1200)) | O21: =IF(E21<0.5,0,E21*(1+N('My Loans'!D7)/1200)) | P21: =IF(F21<0.5,0,F21*(1+N('My Loans'!D8)/1200)) | Q21: =IF(G21<0.5,0,G21*(1+N('My Loans'!D9)/1200)) | R21: =IF(H21<0.5,0,H21*(1+N('My Loans'!D10)/1200)) | S21: =IF(I21<0.5,0,I21*(1+N('My Loans'!D11)/1200)) | T21: =IF(J21<0.5,0,J21*(1+N('My Loans'!D12)/1200)) | U21: =IF(K21<0.5,0,K21*(1+N('My Loans'!D13)/1200)) | V21: =IF(L21<0.5,0,L21*(1+N('My Loans'!D14)/1200)) | W21: =IF(M21<0.5,0,M21*(1+N('My Loans'!D15)/1200)) | X21: =MIN(N21,N('My Loans'!E6)) | Y21: =MIN(O21,N('My Loans'!E7)) | Z21: =MIN(P21,N('My Loans'!E8)) | AA21: =MIN(Q21,N('My Loans'!E9)) | AB21: =MIN(R21,N('My Loans'!E10)) | AC21: =MIN(S21,N('My Loans'!E11)) | AD21: =MIN(T21,N('My Loans'!E12)) | AE21: =MIN(U21,N('My Loans'!E13)) | AF21: =MIN(V21,N('My Loans'!E14)) | AG21: =MIN(W21,N('My Loans'!E15)) | AH21: =MIN(N21-X21,MAX(0,$C21-SUMPRODUCT(($D$3:$M$3<D$3)*($N21:$W21-$X21:$AG21)))) | AI21: =MIN(O21-Y21,MAX(0,$C21-SUMPRODUCT(($D$3:$M$3<E$3)*($N21:$W21-$X21:$AG21)))) | AJ21: =MIN(P21-Z21,MAX(0,$C21-SUMPRODUCT(($D$3:$M$3<F$3)*($N21:$W21-$X21:$AG21)))) | AK21: =MIN(Q21-AA21,MAX(0,$C21-SUMPRODUCT(($D$3:$M$3<G$3)*($N21:$W21-$X21:$AG21)))) | AL21: =MIN(R21-AB21,MAX(0,$C21-SUMPRODUCT(($D$3:$M$3<H$3)*($N21:$W21-$X21:$AG21)))) | AM21: =MIN(S21-AC21,MAX(0,$C21-SUMPRODUCT(($D$3:$M$3<I$3)*($N21:$W21-$X21:$AG21)))) | AN21: =MIN(T21-AD21,MAX(0,$C21-SUMPRODUCT(($D$3:$M$3<J$3)*($N21:$W21-$X21:$AG21)))) | AO21: =MIN(U21-AE21,MAX(0,$C21-SUMPRODUCT(($D$3:$M$3<K$3)*($N21:$W21-$X21:$AG21)))) | ... AQ21: =MIN(W21-AG21,MAX(0,$C21-SUMPRODUCT(($D$3:$M$3<M$3)*($N21:$W21-$X21:$AG21)))) | AR21: =ROUND(N21-X21-AH21,2) | AS21: =ROUND(O21-Y21-AI21,2) | AT21: =ROUND(P21-Z21-AJ21,2) | AU21: =ROUND(Q21-AA21-AK21,2) | AV21: =ROUND(R21-AB21-AL21,2) | AW21: =ROUND(S21-AC21-AM21,2) | AX21: =ROUND(T21-AD21-AN21,2) | AY21: =ROUND(U21-AE21-AO21,2) | ... BA21: =ROUND(W21-AG21-AQ21,2) | BB21: =SUM(AR21:BA21)
A22: 18 | B22: =EOMONTH(TODAY(),17) | C22: =MAX(0,(SUM('My Loans'!$E$6:$E$15)+'My Loans'!$D$3)-SUM($X22:$AG22)) | D22: =MAX(0,AR21) | E22: =MAX(0,AS21) | F22: =MAX(0,AT21) | G22: =MAX(0,AU21) | H22: =MAX(0,AV21) | I22: =MAX(0,AW21) | J22: =MAX(0,AX21) | K22: =MAX(0,AY21) | ... M22: =MAX(0,BA21) | N22: =IF(D22<0.5,0,D22*(1+N('My Loans'!D6)/1200)) | O22: =IF(E22<0.5,0,E22*(1+N('My Loans'!D7)/1200)) | P22: =IF(F22<0.5,0,F22*(1+N('My Loans'!D8)/1200)) | Q22: =IF(G22<0.5,0,G22*(1+N('My Loans'!D9)/1200)) | R22: =IF(H22<0.5,0,H22*(1+N('My Loans'!D10)/1200)) | S22: =IF(I22<0.5,0,I22*(1+N('My Loans'!D11)/1200)) | T22: =IF(J22<0.5,0,J22*(1+N('My Loans'!D12)/1200)) | U22: =IF(K22<0.5,0,K22*(1+N('My Loans'!D13)/1200)) | V22: =IF(L22<0.5,0,L22*(1+N('My Loans'!D14)/1200)) | W22: =IF(M22<0.5,0,M22*(1+N('My Loans'!D15)/1200)) | X22: =MIN(N22,N('My Loans'!E6)) | Y22: =MIN(O22,N('My Loans'!E7)) | Z22: =MIN(P22,N('My Loans'!E8)) | AA22: =MIN(Q22,N('My Loans'!E9)) | AB22: =MIN(R22,N('My Loans'!E10)) | AC22: =MIN(S22,N('My Loans'!E11)) | AD22: =MIN(T22,N('My Loans'!E12)) | AE22: =MIN(U22,N('My Loans'!E13)) | AF22: =MIN(V22,N('My Loans'!E14)) | AG22: =MIN(W22,N('My Loans'!E15)) | AH22: =MIN(N22-X22,MAX(0,$C22-SUMPRODUCT(($D$3:$M$3<D$3)*($N22:$W22-$X22:$AG22)))) | AI22: =MIN(O22-Y22,MAX(0,$C22-SUMPRODUCT(($D$3:$M$3<E$3)*($N22:$W22-$X22:$AG22)))) | AJ22: =MIN(P22-Z22,MAX(0,$C22-SUMPRODUCT(($D$3:$M$3<F$3)*($N22:$W22-$X22:$AG22)))) | AK22: =MIN(Q22-AA22,MAX(0,$C22-SUMPRODUCT(($D$3:$M$3<G$3)*($N22:$W22-$X22:$AG22)))) | AL22: =MIN(R22-AB22,MAX(0,$C22-SUMPRODUCT(($D$3:$M$3<H$3)*($N22:$W22-$X22:$AG22)))) | AM22: =MIN(S22-AC22,MAX(0,$C22-SUMPRODUCT(($D$3:$M$3<I$3)*($N22:$W22-$X22:$AG22)))) | AN22: =MIN(T22-AD22,MAX(0,$C22-SUMPRODUCT(($D$3:$M$3<J$3)*($N22:$W22-$X22:$AG22)))) | AO22: =MIN(U22-AE22,MAX(0,$C22-SUMPRODUCT(($D$3:$M$3<K$3)*($N22:$W22-$X22:$AG22)))) | ... AQ22: =MIN(W22-AG22,MAX(0,$C22-SUMPRODUCT(($D$3:$M$3<M$3)*($N22:$W22-$X22:$AG22)))) | AR22: =ROUND(N22-X22-AH22,2) | AS22: =ROUND(O22-Y22-AI22,2) | AT22: =ROUND(P22-Z22-AJ22,2) | AU22: =ROUND(Q22-AA22-AK22,2) | AV22: =ROUND(R22-AB22-AL22,2) | AW22: =ROUND(S22-AC22-AM22,2) | AX22: =ROUND(T22-AD22-AN22,2) | AY22: =ROUND(U22-AE22-AO22,2) | ... BA22: =ROUND(W22-AG22-AQ22,2) | BB22: =SUM(AR22:BA22)
A23: 19 | B23: =EOMONTH(TODAY(),18) | C23: =MAX(0,(SUM('My Loans'!$E$6:$E$15)+'My Loans'!$D$3)-SUM($X23:$AG23)) | D23: =MAX(0,AR22) | E23: =MAX(0,AS22) | F23: =MAX(0,AT22) | G23: =MAX(0,AU22) | H23: =MAX(0,AV22) | I23: =MAX(0,AW22) | J23: =MAX(0,AX22) | K23: =MAX(0,AY22) | ... M23: =MAX(0,BA22) | N23: =IF(D23<0.5,0,D23*(1+N('My Loans'!D6)/1200)) | O23: =IF(E23<0.5,0,E23*(1+N('My Loans'!D7)/1200)) | P23: =IF(F23<0.5,0,F23*(1+N('My Loans'!D8)/1200)) | Q23: =IF(G23<0.5,0,G23*(1+N('My Loans'!D9)/1200)) | R23: =IF(H23<0.5,0,H23*(1+N('My Loans'!D10)/1200)) | S23: =IF(I23<0.5,0,I23*(1+N('My Loans'!D11)/1200)) | T23: =IF(J23<0.5,0,J23*(1+N('My Loans'!D12)/1200)) | U23: =IF(K23<0.5,0,K23*(1+N('My Loans'!D13)/1200)) | V23: =IF(L23<0.5,0,L23*(1+N('My Loans'!D14)/1200)) | W23: =IF(M23<0.5,0,M23*(1+N('My Loans'!D15)/1200)) | X23: =MIN(N23,N('My Loans'!E6)) | Y23: =MIN(O23,N('My Loans'!E7)) | Z23: =MIN(P23,N('My Loans'!E8)) | AA23: =MIN(Q23,N('My Loans'!E9)) | AB23: =MIN(R23,N('My Loans'!E10)) | AC23: =MIN(S23,N('My Loans'!E11)) | AD23: =MIN(T23,N('My Loans'!E12)) | AE23: =MIN(U23,N('My Loans'!E13)) | AF23: =MIN(V23,N('My Loans'!E14)) | AG23: =MIN(W23,N('My Loans'!E15)) | AH23: =MIN(N23-X23,MAX(0,$C23-SUMPRODUCT(($D$3:$M$3<D$3)*($N23:$W23-$X23:$AG23)))) | AI23: =MIN(O23-Y23,MAX(0,$C23-SUMPRODUCT(($D$3:$M$3<E$3)*($N23:$W23-$X23:$AG23)))) | AJ23: =MIN(P23-Z23,MAX(0,$C23-SUMPRODUCT(($D$3:$M$3<F$3)*($N23:$W23-$X23:$AG23)))) | AK23: =MIN(Q23-AA23,MAX(0,$C23-SUMPRODUCT(($D$3:$M$3<G$3)*($N23:$W23-$X23:$AG23)))) | AL23: =MIN(R23-AB23,MAX(0,$C23-SUMPRODUCT(($D$3:$M$3<H$3)*($N23:$W23-$X23:$AG23)))) | AM23: =MIN(S23-AC23,MAX(0,$C23-SUMPRODUCT(($D$3:$M$3<I$3)*($N23:$W23-$X23:$AG23)))) | AN23: =MIN(T23-AD23,MAX(0,$C23-SUMPRODUCT(($D$3:$M$3<J$3)*($N23:$W23-$X23:$AG23)))) | AO23: =MIN(U23-AE23,MAX(0,$C23-SUMPRODUCT(($D$3:$M$3<K$3)*($N23:$W23-$X23:$AG23)))) | ... AQ23: =MIN(W23-AG23,MAX(0,$C23-SUMPRODUCT(($D$3:$M$3<M$3)*($N23:$W23-$X23:$AG23)))) | AR23: =ROUND(N23-X23-AH23,2) | AS23: =ROUND(O23-Y23-AI23,2) | AT23: =ROUND(P23-Z23-AJ23,2) | AU23: =ROUND(Q23-AA23-AK23,2) | AV23: =ROUND(R23-AB23-AL23,2) | AW23: =ROUND(S23-AC23-AM23,2) | AX23: =ROUND(T23-AD23-AN23,2) | AY23: =ROUND(U23-AE23-AO23,2) | ... BA23: =ROUND(W23-AG23-AQ23,2) | BB23: =SUM(AR23:BA23)
A24: 20 | B24: =EOMONTH(TODAY(),19) | C24: =MAX(0,(SUM('My Loans'!$E$6:$E$15)+'My Loans'!$D$3)-SUM($X24:$AG24)) | D24: =MAX(0,AR23) | E24: =MAX(0,AS23) | F24: =MAX(0,AT23) | G24: =MAX(0,AU23) | H24: =MAX(0,AV23) | I24: =MAX(0,AW23) | J24: =MAX(0,AX23) | K24: =MAX(0,AY23) | ... M24: =MAX(0,BA23) | N24: =IF(D24<0.5,0,D24*(1+N('My Loans'!D6)/1200)) | O24: =IF(E24<0.5,0,E24*(1+N('My Loans'!D7)/1200)) | P24: =IF(F24<0.5,0,F24*(1+N('My Loans'!D8)/1200)) | Q24: =IF(G24<0.5,0,G24*(1+N('My Loans'!D9)/1200)) | R24: =IF(H24<0.5,0,H24*(1+N('My Loans'!D10)/1200)) | S24: =IF(I24<0.5,0,I24*(1+N('My Loans'!D11)/1200)) | T24: =IF(J24<0.5,0,J24*(1+N('My Loans'!D12)/1200)) | U24: =IF(K24<0.5,0,K24*(1+N('My Loans'!D13)/1200)) | V24: =IF(L24<0.5,0,L24*(1+N('My Loans'!D14)/1200)) | W24: =IF(M24<0.5,0,M24*(1+N('My Loans'!D15)/1200)) | X24: =MIN(N24,N('My Loans'!E6)) | Y24: =MIN(O24,N('My Loans'!E7)) | Z24: =MIN(P24,N('My Loans'!E8)) | AA24: =MIN(Q24,N('My Loans'!E9)) | AB24: =MIN(R24,N('My Loans'!E10)) | AC24: =MIN(S24,N('My Loans'!E11)) | AD24: =MIN(T24,N('My Loans'!E12)) | AE24: =MIN(U24,N('My Loans'!E13)) | AF24: =MIN(V24,N('My Loans'!E14)) | AG24: =MIN(W24,N('My Loans'!E15)) | AH24: =MIN(N24-X24,MAX(0,$C24-SUMPRODUCT(($D$3:$M$3<D$3)*($N24:$W24-$X24:$AG24)))) | AI24: =MIN(O24-Y24,MAX(0,$C24-SUMPRODUCT(($D$3:$M$3<E$3)*($N24:$W24-$X24:$AG24)))) | AJ24: =MIN(P24-Z24,MAX(0,$C24-SUMPRODUCT(($D$3:$M$3<F$3)*($N24:$W24-$X24:$AG24)))) | AK24: =MIN(Q24-AA24,MAX(0,$C24-SUMPRODUCT(($D$3:$M$3<G$3)*($N24:$W24-$X24:$AG24)))) | AL24: =MIN(R24-AB24,MAX(0,$C24-SUMPRODUCT(($D$3:$M$3<H$3)*($N24:$W24-$X24:$AG24)))) | AM24: =MIN(S24-AC24,MAX(0,$C24-SUMPRODUCT(($D$3:$M$3<I$3)*($N24:$W24-$X24:$AG24)))) | AN24: =MIN(T24-AD24,MAX(0,$C24-SUMPRODUCT(($D$3:$M$3<J$3)*($N24:$W24-$X24:$AG24)))) | AO24: =MIN(U24-AE24,MAX(0,$C24-SUMPRODUCT(($D$3:$M$3<K$3)*($N24:$W24-$X24:$AG24)))) | ... AQ24: =MIN(W24-AG24,MAX(0,$C24-SUMPRODUCT(($D$3:$M$3<M$3)*($N24:$W24-$X24:$AG24)))) | AR24: =ROUND(N24-X24-AH24,2) | AS24: =ROUND(O24-Y24-AI24,2) | AT24: =ROUND(P24-Z24-AJ24,2) | AU24: =ROUND(Q24-AA24-AK24,2) | AV24: =ROUND(R24-AB24-AL24,2) | AW24: =ROUND(S24-AC24-AM24,2) | AX24: =ROUND(T24-AD24-AN24,2) | AY24: =ROUND(U24-AE24-AO24,2) | ... BA24: =ROUND(W24-AG24-AQ24,2) | BB24: =SUM(AR24:BA24)
A25: 21 | B25: =EOMONTH(TODAY(),20) | C25: =MAX(0,(SUM('My Loans'!$E$6:$E$15)+'My Loans'!$D$3)-SUM($X25:$AG25)) | D25: =MAX(0,AR24) | E25: =MAX(0,AS24) | F25: =MAX(0,AT24) | G25: =MAX(0,AU24) | H25: =MAX(0,AV24) | I25: =MAX(0,AW24) | J25: =MAX(0,AX24) | K25: =MAX(0,AY24) | ... M25: =MAX(0,BA24) | N25: =IF(D25<0.5,0,D25*(1+N('My Loans'!D6)/1200)) | O25: =IF(E25<0.5,0,E25*(1+N('My Loans'!D7)/1200)) | P25: =IF(F25<0.5,0,F25*(1+N('My Loans'!D8)/1200)) | Q25: =IF(G25<0.5,0,G25*(1+N('My Loans'!D9)/1200)) | R25: =IF(H25<0.5,0,H25*(1+N('My Loans'!D10)/1200)) | S25: =IF(I25<0.5,0,I25*(1+N('My Loans'!D11)/1200)) | T25: =IF(J25<0.5,0,J25*(1+N('My Loans'!D12)/1200)) | U25: =IF(K25<0.5,0,K25*(1+N('My Loans'!D13)/1200)) | V25: =IF(L25<0.5,0,L25*(1+N('My Loans'!D14)/1200)) | W25: =IF(M25<0.5,0,M25*(1+N('My Loans'!D15)/1200)) | X25: =MIN(N25,N('My Loans'!E6)) | Y25: =MIN(O25,N('My Loans'!E7)) | Z25: =MIN(P25,N('My Loans'!E8)) | AA25: =MIN(Q25,N('My Loans'!E9)) | AB25: =MIN(R25,N('My Loans'!E10)) | AC25: =MIN(S25,N('My Loans'!E11)) | AD25: =MIN(T25,N('My Loans'!E12)) | AE25: =MIN(U25,N('My Loans'!E13)) | AF25: =MIN(V25,N('My Loans'!E14)) | AG25: =MIN(W25,N('My Loans'!E15)) | AH25: =MIN(N25-X25,MAX(0,$C25-SUMPRODUCT(($D$3:$M$3<D$3)*($N25:$W25-$X25:$AG25)))) | AI25: =MIN(O25-Y25,MAX(0,$C25-SUMPRODUCT(($D$3:$M$3<E$3)*($N25:$W25-$X25:$AG25)))) | AJ25: =MIN(P25-Z25,MAX(0,$C25-SUMPRODUCT(($D$3:$M$3<F$3)*($N25:$W25-$X25:$AG25)))) | AK25: =MIN(Q25-AA25,MAX(0,$C25-SUMPRODUCT(($D$3:$M$3<G$3)*($N25:$W25-$X25:$AG25)))) | AL25: =MIN(R25-AB25,MAX(0,$C25-SUMPRODUCT(($D$3:$M$3<H$3)*($N25:$W25-$X25:$AG25)))) | AM25: =MIN(S25-AC25,MAX(0,$C25-SUMPRODUCT(($D$3:$M$3<I$3)*($N25:$W25-$X25:$AG25)))) | AN25: =MIN(T25-AD25,MAX(0,$C25-SUMPRODUCT(($D$3:$M$3<J$3)*($N25:$W25-$X25:$AG25)))) | AO25: =MIN(U25-AE25,MAX(0,$C25-SUMPRODUCT(($D$3:$M$3<K$3)*($N25:$W25-$X25:$AG25)))) | ... AQ25: =MIN(W25-AG25,MAX(0,$C25-SUMPRODUCT(($D$3:$M$3<M$3)*($N25:$W25-$X25:$AG25)))) | AR25: =ROUND(N25-X25-AH25,2) | AS25: =ROUND(O25-Y25-AI25,2) | AT25: =ROUND(P25-Z25-AJ25,2) | AU25: =ROUND(Q25-AA25-AK25,2) | AV25: =ROUND(R25-AB25-AL25,2) | AW25: =ROUND(S25-AC25-AM25,2) | AX25: =ROUND(T25-AD25-AN25,2) | AY25: =ROUND(U25-AE25-AO25,2) | ... BA25: =ROUND(W25-AG25-AQ25,2) | BB25: =SUM(AR25:BA25)
