Workbook

Sheet How to use
B1: GST Compliance Kit — Invoice, Registers, 3B Working, ITC Reconciliation & Due Dates
B2: Rajput Lalit & Associates · www.rajputlalitassociates.in · WhatsApp +91 93549 53603
B4: Steps
A5: 1 | B5: Open the 'Settings' sheet and enter your business name, address, GSTIN, state and bank details once.
A6: 2 | B6: Open 'Invoice'. Enter invoice number, date, buyer details and pick the buyer's state (place of supply).
A7: 3 | B7: Add items (up to 15 lines): description, HSN/SAC, quantity, rate, discount % and GST rate. Taxable value, CGST+SGST (same state) or IGST (other state) and totals are calculated automatically.
A8: 4 | B8: Type the amount in words, then print (File → Print, A4, 'Fit sheet on one page') or save as PDF.
A9: 5 | B9: Copy the invoice summary into 'Sales Register' — one row per invoice. 'Monthly Summary' fills itself and gives you the numbers for GSTR-1 / GSTR-3B.
A10: 6 | B10: For the HSN-wise table in GSTR-1, log item lines in 'HSN Register'; 'HSN Summary' adds them up per HSN code.
A11: 7 | B11: For the next invoice: File → Save As with a new name, or clear the yellow cells and change the invoice number.
A12: 8 | B12: Record every purchase bill in 'Purchase Register' and mark whether its ITC is eligible.
A13: 9 | B13: Each month download GSTR-2B from the GST portal (Returns → GSTR-2B → Download Excel) and paste the B2B invoice lines into 'GSTR-2B Data'. Both sheets then show, invoice by invoice, what matches and what doesn't.
A14: 10 | B14: 'ITC Reconciliation' summarises the result — chase suppliers for invoices that are not in your 2B before you claim that credit.
A15: 11 | B15: 'GSTR-3B Working' puts output tax and matched ITC side by side for each month and shows the cash you need to arrange.
A16: 12 | B16: 'Due Date Calendar' lists every GST due date for FY 2026-27. Enter the date you filed — the status column turns to 'OVERDUE' on its own when a date is missed.
A17: 13 | B17: Filed late? 'Late Fee & Interest' works out the late fee (with the legal cap) and 18% interest.
B19: Good to know
B20: • Rates in the drop-down follow the GST rate structure in force from 22 September 2025 (0%, 0.25%, 3%, 5%, 18%, 40%). You can type any other rate if needed.
B21: • If the buyer has a GSTIN the sale is B2B, otherwise B2C — the register marks this for you.
B22: • Invoice numbers must be consecutive, unique for the financial year and at most 16 characters.
B23: • If your turnover is above the e-invoicing limit (currently ₹5 crore), invoices must also be reported on the IRP.
B25: Cells shaded light yellow are for your entries. White cells contain formulas — please don't type over them.
B27: Licensed for use in your own business. Please do not resell or share publicly. This template is a working aid, not professional advice.

Sheet Settings
A1: Your business details
A2: Fill once — used on every invoice
A4: Business / trade name | B4: Your Business Name
A5: Address line 1 | B5: Shop No., Street
A6: Address line 2 | B6: City, State - PIN
A7: GSTIN | B7: 06ABCDE1234F1Z5
A8: Your state (code - name) | B8: 06 - Haryana
A9: Phone | B9: +91
A10: Email
A11: Bank name
A12: Account number
A13: IFSC
A14: UPI ID (optional)
A15: Terms line | B15: Goods once sold will not be taken back. Subject to local jurisdiction.

Sheet Invoice
A1: TAX INVOICE
A2: =Settings!B4 | I2: Invoice No. | K2: INV/26-27/001
A3: =Settings!B5&", "&Settings!B6 | I3: Invoice date | K3: =TODAY()
A4: ="GSTIN: "&Settings!B7&" | State: "&Settings!B8 | I4: Reverse charge | K4: No
A5: ="Ph: "&Settings!B9&" "&Settings!B10 | I5: Supply type | K5: =IF(D11="","",IF(LEFT(D11,2)=LEFT(Settings!B8,2),"Intra-state (CGST+SGST)","Inter-state (IGST)"))
A7: Bill to
B8: Name
B9: Address
B10: GSTIN (blank if unregistered)
B11: Place of supply | D11: 06 - Haryana
A13: # | B13: Description of goods / services | C13: HSN/SAC | D13: Qty | E13: Unit | F13: Rate | G13: Disc % | H13: Taxable value | I13: GST % | J13: CGST | K13: SGST/UTGST | L13: IGST | M13: Total
A14: 1 | H14: =IF(D14="","",ROUND(D14*F14*(1-G14/100),2)) | J14: =IF(H14="","",IF(LEFT($D$11,2)=LEFT(Settings!$B$8,2),ROUND(H14*I14/200,2),0)) | K14: =IF(H14="","",IF(LEFT($D$11,2)=LEFT(Settings!$B$8,2),ROUND(H14*I14/200,2),0)) | L14: =IF(H14="","",IF(LEFT($D$11,2)=LEFT(Settings!$B$8,2),0,ROUND(H14*I14/100,2))) | M14: =IF(H14="","",H14+J14+K14+L14)
A15: 2 | H15: =IF(D15="","",ROUND(D15*F15*(1-G15/100),2)) | J15: =IF(H15="","",IF(LEFT($D$11,2)=LEFT(Settings!$B$8,2),ROUND(H15*I15/200,2),0)) | K15: =IF(H15="","",IF(LEFT($D$11,2)=LEFT(Settings!$B$8,2),ROUND(H15*I15/200,2),0)) | L15: =IF(H15="","",IF(LEFT($D$11,2)=LEFT(Settings!$B$8,2),0,ROUND(H15*I15/100,2))) | M15: =IF(H15="","",H15+J15+K15+L15)
A16: 3 | H16: =IF(D16="","",ROUND(D16*F16*(1-G16/100),2)) | J16: =IF(H16="","",IF(LEFT($D$11,2)=LEFT(Settings!$B$8,2),ROUND(H16*I16/200,2),0)) | K16: =IF(H16="","",IF(LEFT($D$11,2)=LEFT(Settings!$B$8,2),ROUND(H16*I16/200,2),0)) | L16: =IF(H16="","",IF(LEFT($D$11,2)=LEFT(Settings!$B$8,2),0,ROUND(H16*I16/100,2))) | M16: =IF(H16="","",H16+J16+K16+L16)
A17: 4 | H17: =IF(D17="","",ROUND(D17*F17*(1-G17/100),2)) | J17: =IF(H17="","",IF(LEFT($D$11,2)=LEFT(Settings!$B$8,2),ROUND(H17*I17/200,2),0)) | K17: =IF(H17="","",IF(LEFT($D$11,2)=LEFT(Settings!$B$8,2),ROUND(H17*I17/200,2),0)) | L17: =IF(H17="","",IF(LEFT($D$11,2)=LEFT(Settings!$B$8,2),0,ROUND(H17*I17/100,2))) | M17: =IF(H17="","",H17+J17+K17+L17)
A18: 5 | H18: =IF(D18="","",ROUND(D18*F18*(1-G18/100),2)) | J18: =IF(H18="","",IF(LEFT($D$11,2)=LEFT(Settings!$B$8,2),ROUND(H18*I18/200,2),0)) | K18: =IF(H18="","",IF(LEFT($D$11,2)=LEFT(Settings!$B$8,2),ROUND(H18*I18/200,2),0)) | L18: =IF(H18="","",IF(LEFT($D$11,2)=LEFT(Settings!$B$8,2),0,ROUND(H18*I18/100,2))) | M18: =IF(H18="","",H18+J18+K18+L18)
A19: 6 | H19: =IF(D19="","",ROUND(D19*F19*(1-G19/100),2)) | J19: =IF(H19="","",IF(LEFT($D$11,2)=LEFT(Settings!$B$8,2),ROUND(H19*I19/200,2),0)) | K19: =IF(H19="","",IF(LEFT($D$11,2)=LEFT(Settings!$B$8,2),ROUND(H19*I19/200,2),0)) | L19: =IF(H19="","",IF(LEFT($D$11,2)=LEFT(Settings!$B$8,2),0,ROUND(H19*I19/100,2))) | M19: =IF(H19="","",H19+J19+K19+L19)
A20: 7 | H20: =IF(D20="","",ROUND(D20*F20*(1-G20/100),2)) | J20: =IF(H20="","",IF(LEFT($D$11,2)=LEFT(Settings!$B$8,2),ROUND(H20*I20/200,2),0)) | K20: =IF(H20="","",IF(LEFT($D$11,2)=LEFT(Settings!$B$8,2),ROUND(H20*I20/200,2),0)) | L20: =IF(H20="","",IF(LEFT($D$11,2)=LEFT(Settings!$B$8,2),0,ROUND(H20*I20/100,2))) | M20: =IF(H20="","",H20+J20+K20+L20)
A21: 8 | H21: =IF(D21="","",ROUND(D21*F21*(1-G21/100),2)) | J21: =IF(H21="","",IF(LEFT($D$11,2)=LEFT(Settings!$B$8,2),ROUND(H21*I21/200,2),0)) | K21: =IF(H21="","",IF(LEFT($D$11,2)=LEFT(Settings!$B$8,2),ROUND(H21*I21/200,2),0)) | L21: =IF(H21="","",IF(LEFT($D$11,2)=LEFT(Settings!$B$8,2),0,ROUND(H21*I21/100,2))) | M21: =IF(H21="","",H21+J21+K21+L21)
A22: 9 | H22: =IF(D22="","",ROUND(D22*F22*(1-G22/100),2)) | J22: =IF(H22="","",IF(LEFT($D$11,2)=LEFT(Settings!$B$8,2),ROUND(H22*I22/200,2),0)) | K22: =IF(H22="","",IF(LEFT($D$11,2)=LEFT(Settings!$B$8,2),ROUND(H22*I22/200,2),0)) | L22: =IF(H22="","",IF(LEFT($D$11,2)=LEFT(Settings!$B$8,2),0,ROUND(H22*I22/100,2))) | M22: =IF(H22="","",H22+J22+K22+L22)
A23: 10 | H23: =IF(D23="","",ROUND(D23*F23*(1-G23/100),2)) | J23: =IF(H23="","",IF(LEFT($D$11,2)=LEFT(Settings!$B$8,2),ROUND(H23*I23/200,2),0)) | K23: =IF(H23="","",IF(LEFT($D$11,2)=LEFT(Settings!$B$8,2),ROUND(H23*I23/200,2),0)) | L23: =IF(H23="","",IF(LEFT($D$11,2)=LEFT(Settings!$B$8,2),0,ROUND(H23*I23/100,2))) | M23: =IF(H23="","",H23+J23+K23+L23)
A24: 11 | H24: =IF(D24="","",ROUND(D24*F24*(1-G24/100),2)) | J24: =IF(H24="","",IF(LEFT($D$11,2)=LEFT(Settings!$B$8,2),ROUND(H24*I24/200,2),0)) | K24: =IF(H24="","",IF(LEFT($D$11,2)=LEFT(Settings!$B$8,2),ROUND(H24*I24/200,2),0)) | L24: =IF(H24="","",IF(LEFT($D$11,2)=LEFT(Settings!$B$8,2),0,ROUND(H24*I24/100,2))) | M24: =IF(H24="","",H24+J24+K24+L24)
A25: 12 | H25: =IF(D25="","",ROUND(D25*F25*(1-G25/100),2)) | J25: =IF(H25="","",IF(LEFT($D$11,2)=LEFT(Settings!$B$8,2),ROUND(H25*I25/200,2),0)) | K25: =IF(H25="","",IF(LEFT($D$11,2)=LEFT(Settings!$B$8,2),ROUND(H25*I25/200,2),0)) | L25: =IF(H25="","",IF(LEFT($D$11,2)=LEFT(Settings!$B$8,2),0,ROUND(H25*I25/100,2))) | M25: =IF(H25="","",H25+J25+K25+L25)
... A28: 15 | H28: =IF(D28="","",ROUND(D28*F28*(1-G28/100),2)) | J28: =IF(H28="","",IF(LEFT($D$11,2)=LEFT(Settings!$B$8,2),ROUND(H28*I28/200,2),0)) | K28: =IF(H28="","",IF(LEFT($D$11,2)=LEFT(Settings!$B$8,2),ROUND(H28*I28/200,2),0)) | L28: =IF(H28="","",IF(LEFT($D$11,2)=LEFT(Settings!$B$8,2),0,ROUND(H28*I28/100,2))) | M28: =IF(H28="","",H28+J28+K28+L28)
B29: Total | D29: =SUM(D14:D28) | H29: =SUM(H14:H28) | J29: =SUM(J14:J28) | K29: =SUM(K14:K28) | L29: =SUM(L14:L28) | M29: =SUM(M14:M28)
A30: Amount in words: | C30: Rupees ______________ only | K30: Round off | M30: =ROUND(M29,0)-M29
K31: GRAND TOTAL | M31: =ROUND(M29,0)
A32: Bank details: | C32: =Settings!B11&" A/c "&Settings!B12&" IFSC "&Settings!B13&IF(Settings!B14<>""," UPI "&Settings!B14,"")
A33: =Settings!B15 | J33: ="For "&Settings!B4
J36: Authorised Signatory

Sheet States
A1: Code | B1: State / UT | C1: Code + Name
A2: 01 | B2: Jammu and Kashmir | C2: 01 - Jammu and Kashmir
A3: 02 | B3: Himachal Pradesh | C3: 02 - Himachal Pradesh
A4: 03 | B4: Punjab | C4: 03 - Punjab
A5: 04 | B5: Chandigarh | C5: 04 - Chandigarh
A6: 05 | B6: Uttarakhand | C6: 05 - Uttarakhand
A7: 06 | B7: Haryana | C7: 06 - Haryana
A8: 07 | B8: Delhi | C8: 07 - Delhi
A9: 08 | B9: Rajasthan | C9: 08 - Rajasthan
A10: 09 | B10: Uttar Pradesh | C10: 09 - Uttar Pradesh
A11: 10 | B11: Bihar | C11: 10 - Bihar
A12: 11 | B12: Sikkim | C12: 11 - Sikkim
... A38: 97 | B38: Other Territory | C38: 97 - Other Territory

Sheet Sales Register
A1: Sales Register
A2: One row per invoice. Taxable value and tax come from the invoice totals.
A4: Date | B4: Invoice No. | C4: Customer | D4: Customer GSTIN | E4: Place of supply | F4: Taxable value | G4: CGST | H4: SGST | I4: IGST | J4: Invoice total | K4: B2B / B2C | L4: Month
J5: =IF(F5="","",F5+G5+H5+I5) | K5: =IF(F5="","",IF(D5<>"","B2B","B2C")) | L5: =IF(A5="","",TEXT(A5,"mmm-yy"))
J6: =IF(F6="","",F6+G6+H6+I6) | K6: =IF(F6="","",IF(D6<>"","B2B","B2C")) | L6: =IF(A6="","",TEXT(A6,"mmm-yy"))
J7: =IF(F7="","",F7+G7+H7+I7) | K7: =IF(F7="","",IF(D7<>"","B2B","B2C")) | L7: =IF(A7="","",TEXT(A7,"mmm-yy"))
J8: =IF(F8="","",F8+G8+H8+I8) | K8: =IF(F8="","",IF(D8<>"","B2B","B2C")) | L8: =IF(A8="","",TEXT(A8,"mmm-yy"))
J9: =IF(F9="","",F9+G9+H9+I9) | K9: =IF(F9="","",IF(D9<>"","B2B","B2C")) | L9: =IF(A9="","",TEXT(A9,"mmm-yy"))
J10: =IF(F10="","",F10+G10+H10+I10) | K10: =IF(F10="","",IF(D10<>"","B2B","B2C")) | L10: =IF(A10="","",TEXT(A10,"mmm-yy"))
J11: =IF(F11="","",F11+G11+H11+I11) | K11: =IF(F11="","",IF(D11<>"","B2B","B2C")) | L11: =IF(A11="","",TEXT(A11,"mmm-yy"))
J12: =IF(F12="","",F12+G12+H12+I12) | K12: =IF(F12="","",IF(D12<>"","B2B","B2C")) | L12: =IF(A12="","",TEXT(A12,"mmm-yy"))
J13: =IF(F13="","",F13+G13+H13+I13) | K13: =IF(F13="","",IF(D13<>"","B2B","B2C")) | L13: =IF(A13="","",TEXT(A13,"mmm-yy"))
J14: =IF(F14="","",F14+G14+H14+I14) | K14: =IF(F14="","",IF(D14<>"","B2B","B2C")) | L14: =IF(A14="","",TEXT(A14,"mmm-yy"))
J15: =IF(F15="","",F15+G15+H15+I15) | K15: =IF(F15="","",IF(D15<>"","B2B","B2C")) | L15: =IF(A15="","",TEXT(A15,"mmm-yy"))
J16: =IF(F16="","",F16+G16+H16+I16) | K16: =IF(F16="","",IF(D16<>"","B2B","B2C")) | L16: =IF(A16="","",TEXT(A16,"mmm-yy"))
... J504: =IF(F504="","",F504+G504+H504+I504) | K504: =IF(F504="","",IF(D504<>"","B2B","B2C")) | L504: =IF(A504="","",TEXT(A504,"mmm-yy"))

Sheet Monthly Summary
A1: Monthly GST Summary — FY 2026-27
A2: Filled automatically from the Sales Register
A4: Month | B4: Invoices | C4: Taxable value | D4: CGST | E4: SGST | F4: IGST | G4: Total tax | H4: B2B taxable | I4: B2C taxable
A5: =DATE(2026,4,1) | B5: =COUNTIFS('Sales Register'!$A$5:$A$504,">="&A5,'Sales Register'!$A$5:$A$504,"<="&EOMONTH(A5,0)) | C5: =SUMIFS('Sales Register'!$F$5:$F$504,'Sales Register'!$A$5:$A$504,">="&A5,'Sales Register'!$A$5:$A$504,"<="&EOMONTH(A5,0)) | D5: =SUMIFS('Sales Register'!$G$5:$G$504,'Sales Register'!$A$5:$A$504,">="&A5,'Sales Register'!$A$5:$A$504,"<="&EOMONTH(A5,0)) | E5: =SUMIFS('Sales Register'!$H$5:$H$504,'Sales Register'!$A$5:$A$504,">="&A5,'Sales Register'!$A$5:$A$504,"<="&EOMONTH(A5,0)) | F5: =SUMIFS('Sales Register'!$I$5:$I$504,'Sales Register'!$A$5:$A$504,">="&A5,'Sales Register'!$A$5:$A$504,"<="&EOMONTH(A5,0)) | G5: =D5+E5+F5 | H5: =SUMIFS('Sales Register'!$F$5:$F$504,'Sales Register'!$A$5:$A$504,">="&A5,'Sales Register'!$A$5:$A$504,"<="&EOMONTH(A5,0),'Sales Register'!$K$5:$K$504,"B2B") | I5: =SUMIFS('Sales Register'!$F$5:$F$504,'Sales Register'!$A$5:$A$504,">="&A5,'Sales Register'!$A$5:$A$504,"<="&EOMONTH(A5,0),'Sales Register'!$K$5:$K$504,"B2C")
A6: =DATE(2026,5,1) | B6: =COUNTIFS('Sales Register'!$A$5:$A$504,">="&A6,'Sales Register'!$A$5:$A$504,"<="&EOMONTH(A6,0)) | C6: =SUMIFS('Sales Register'!$F$5:$F$504,'Sales Register'!$A$5:$A$504,">="&A6,'Sales Register'!$A$5:$A$504,"<="&EOMONTH(A6,0)) | D6: =SUMIFS('Sales Register'!$G$5:$G$504,'Sales Register'!$A$5:$A$504,">="&A6,'Sales Register'!$A$5:$A$504,"<="&EOMONTH(A6,0)) | E6: =SUMIFS('Sales Register'!$H$5:$H$504,'Sales Register'!$A$5:$A$504,">="&A6,'Sales Register'!$A$5:$A$504,"<="&EOMONTH(A6,0)) | F6: =SUMIFS('Sales Register'!$I$5:$I$504,'Sales Register'!$A$5:$A$504,">="&A6,'Sales Register'!$A$5:$A$504,"<="&EOMONTH(A6,0)) | G6: =D6+E6+F6 | H6: =SUMIFS('Sales Register'!$F$5:$F$504,'Sales Register'!$A$5:$A$504,">="&A6,'Sales Register'!$A$5:$A$504,"<="&EOMONTH(A6,0),'Sales Register'!$K$5:$K$504,"B2B") | I6: =SUMIFS('Sales Register'!$F$5:$F$504,'Sales Register'!$A$5:$A$504,">="&A6,'Sales Register'!$A$5:$A$504,"<="&EOMONTH(A6,0),'Sales Register'!$K$5:$K$504,"B2C")
A7: =DATE(2026,6,1) | B7: =COUNTIFS('Sales Register'!$A$5:$A$504,">="&A7,'Sales Register'!$A$5:$A$504,"<="&EOMONTH(A7,0)) | C7: =SUMIFS('Sales Register'!$F$5:$F$504,'Sales Register'!$A$5:$A$504,">="&A7,'Sales Register'!$A$5:$A$504,"<="&EOMONTH(A7,0)) | D7: =SUMIFS('Sales Register'!$G$5:$G$504,'Sales Register'!$A$5:$A$504,">="&A7,'Sales Register'!$A$5:$A$504,"<="&EOMONTH(A7,0)) | E7: =SUMIFS('Sales Register'!$H$5:$H$504,'Sales Register'!$A$5:$A$504,">="&A7,'Sales Register'!$A$5:$A$504,"<="&EOMONTH(A7,0)) | F7: =SUMIFS('Sales Register'!$I$5:$I$504,'Sales Register'!$A$5:$A$504,">="&A7,'Sales Register'!$A$5:$A$504,"<="&EOMONTH(A7,0)) | G7: =D7+E7+F7 | H7: =SUMIFS('Sales Register'!$F$5:$F$504,'Sales Register'!$A$5:$A$504,">="&A7,'Sales Register'!$A$5:$A$504,"<="&EOMONTH(A7,0),'Sales Register'!$K$5:$K$504,"B2B") | I7: =SUMIFS('Sales Register'!$F$5:$F$504,'Sales Register'!$A$5:$A$504,">="&A7,'Sales Register'!$A$5:$A$504,"<="&EOMONTH(A7,0),'Sales Register'!$K$5:$K$504,"B2C")
A8: =DATE(2026,7,1) | B8: =COUNTIFS('Sales Register'!$A$5:$A$504,">="&A8,'Sales Register'!$A$5:$A$504,"<="&EOMONTH(A8,0)) | C8: =SUMIFS('Sales Register'!$F$5:$F$504,'Sales Register'!$A$5:$A$504,">="&A8,'Sales Register'!$A$5:$A$504,"<="&EOMONTH(A8,0)) | D8: =SUMIFS('Sales Register'!$G$5:$G$504,'Sales Register'!$A$5:$A$504,">="&A8,'Sales Register'!$A$5:$A$504,"<="&EOMONTH(A8,0)) | E8: =SUMIFS('Sales Register'!$H$5:$H$504,'Sales Register'!$A$5:$A$504,">="&A8,'Sales Register'!$A$5:$A$504,"<="&EOMONTH(A8,0)) | F8: =SUMIFS('Sales Register'!$I$5:$I$504,'Sales Register'!$A$5:$A$504,">="&A8,'Sales Register'!$A$5:$A$504,"<="&EOMONTH(A8,0)) | G8: =D8+E8+F8 | H8: =SUMIFS('Sales Register'!$F$5:$F$504,'Sales Register'!$A$5:$A$504,">="&A8,'Sales Register'!$A$5:$A$504,"<="&EOMONTH(A8,0),'Sales Register'!$K$5:$K$504,"B2B") | I8: =SUMIFS('Sales Register'!$F$5:$F$504,'Sales Register'!$A$5:$A$504,">="&A8,'Sales Register'!$A$5:$A$504,"<="&EOMONTH(A8,0),'Sales Register'!$K$5:$K$504,"B2C")
A9: =DATE(2026,8,1) | B9: =COUNTIFS('Sales Register'!$A$5:$A$504,">="&A9,'Sales Register'!$A$5:$A$504,"<="&EOMONTH(A9,0)) | C9: =SUMIFS('Sales Register'!$F$5:$F$504,'Sales Register'!$A$5:$A$504,">="&A9,'Sales Register'!$A$5:$A$504,"<="&EOMONTH(A9,0)) | D9: =SUMIFS('Sales Register'!$G$5:$G$504,'Sales Register'!$A$5:$A$504,">="&A9,'Sales Register'!$A$5:$A$504,"<="&EOMONTH(A9,0)) | E9: =SUMIFS('Sales Register'!$H$5:$H$504,'Sales Register'!$A$5:$A$504,">="&A9,'Sales Register'!$A$5:$A$504,"<="&EOMONTH(A9,0)) | F9: =SUMIFS('Sales Register'!$I$5:$I$504,'Sales Register'!$A$5:$A$504,">="&A9,'Sales Register'!$A$5:$A$504,"<="&EOMONTH(A9,0)) | G9: =D9+E9+F9 | H9: =SUMIFS('Sales Register'!$F$5:$F$504,'Sales Register'!$A$5:$A$504,">="&A9,'Sales Register'!$A$5:$A$504,"<="&EOMONTH(A9,0),'Sales Register'!$K$5:$K$504,"B2B") | I9: =SUMIFS('Sales Register'!$F$5:$F$504,'Sales Register'!$A$5:$A$504,">="&A9,'Sales Register'!$A$5:$A$504,"<="&EOMONTH(A9,0),'Sales Register'!$K$5:$K$504,"B2C")
A10: =DATE(2026,9,1) | B10: =COUNTIFS('Sales Register'!$A$5:$A$504,">="&A10,'Sales Register'!$A$5:$A$504,"<="&EOMONTH(A10,0)) | C10: =SUMIFS('Sales Register'!$F$5:$F$504,'Sales Register'!$A$5:$A$504,">="&A10,'Sales Register'!$A$5:$A$504,"<="&EOMONTH(A10,0)) | D10: =SUMIFS('Sales Register'!$G$5:$G$504,'Sales Register'!$A$5:$A$504,">="&A10,'Sales Register'!$A$5:$A$504,"<="&EOMONTH(A10,0)) | E10: =SUMIFS('Sales Register'!$H$5:$H$504,'Sales Register'!$A$5:$A$504,">="&A10,'Sales Register'!$A$5:$A$504,"<="&EOMONTH(A10,0)) | F10: =SUMIFS('Sales Register'!$I$5:$I$504,'Sales Register'!$A$5:$A$504,">="&A10,'Sales Register'!$A$5:$A$504,"<="&EOMONTH(A10,0)) | G10: =D10+E10+F10 | H10: =SUMIFS('Sales Register'!$F$5:$F$504,'Sales Register'!$A$5:$A$504,">="&A10,'Sales Register'!$A$5:$A$504,"<="&EOMONTH(A10,0),'Sales Register'!$K$5:$K$504,"B2B") | I10: =SUMIFS('Sales Register'!$F$5:$F$504,'Sales Register'!$A$5:$A$504,">="&A10,'Sales Register'!$A$5:$A$504,"<="&EOMONTH(A10,0),'Sales Register'!$K$5:$K$504,"B2C")
A11: =DATE(2026,10,1) | B11: =COUNTIFS('Sales Register'!$A$5:$A$504,">="&A11,'Sales Register'!$A$5:$A$504,"<="&EOMONTH(A11,0)) | C11: =SUMIFS('Sales Register'!$F$5:$F$504,'Sales Register'!$A$5:$A$504,">="&A11,'Sales Register'!$A$5:$A$504,"<="&EOMONTH(A11,0)) | D11: =SUMIFS('Sales Register'!$G$5:$G$504,'Sales Register'!$A$5:$A$504,">="&A11,'Sales Register'!$A$5:$A$504,"<="&EOMONTH(A11,0)) | E11: =SUMIFS('Sales Register'!$H$5:$H$504,'Sales Register'!$A$5:$A$504,">="&A11,'Sales Register'!$A$5:$A$504,"<="&EOMONTH(A11,0)) | F11: =SUMIFS('Sales Register'!$I$5:$I$504,'Sales Register'!$A$5:$A$504,">="&A11,'Sales Register'!$A$5:$A$504,"<="&EOMONTH(A11,0)) | G11: =D11+E11+F11 | H11: =SUMIFS('Sales Register'!$F$5:$F$504,'Sales Register'!$A$5:$A$504,">="&A11,'Sales Register'!$A$5:$A$504,"<="&EOMONTH(A11,0),'Sales Register'!$K$5:$K$504,"B2B") | I11: =SUMIFS('Sales Register'!$F$5:$F$504,'Sales Register'!$A$5:$A$504,">="&A11,'Sales Register'!$A$5:$A$504,"<="&EOMONTH(A11,0),'Sales Register'!$K$5:$K$504,"B2C")
A12: =DATE(2026,11,1) | B12: =COUNTIFS('Sales Register'!$A$5:$A$504,">="&A12,'Sales Register'!$A$5:$A$504,"<="&EOMONTH(A12,0)) | C12: =SUMIFS('Sales Register'!$F$5:$F$504,'Sales Register'!$A$5:$A$504,">="&A12,'Sales Register'!$A$5:$A$504,"<="&EOMONTH(A12,0)) | D12: =SUMIFS('Sales Register'!$G$5:$G$504,'Sales Register'!$A$5:$A$504,">="&A12,'Sales Register'!$A$5:$A$504,"<="&EOMONTH(A12,0)) | E12: =SUMIFS('Sales Register'!$H$5:$H$504,'Sales Register'!$A$5:$A$504,">="&A12,'Sales Register'!$A$5:$A$504,"<="&EOMONTH(A12,0)) | F12: =SUMIFS('Sales Register'!$I$5:$I$504,'Sales Register'!$A$5:$A$504,">="&A12,'Sales Register'!$A$5:$A$504,"<="&EOMONTH(A12,0)) | G12: =D12+E12+F12 | H12: =SUMIFS('Sales Register'!$F$5:$F$504,'Sales Register'!$A$5:$A$504,">="&A12,'Sales Register'!$A$5:$A$504,"<="&EOMONTH(A12,0),'Sales Register'!$K$5:$K$504,"B2B") | I12: =SUMIFS('Sales Register'!$F$5:$F$504,'Sales Register'!$A$5:$A$504,">="&A12,'Sales Register'!$A$5:$A$504,"<="&EOMONTH(A12,0),'Sales Register'!$K$5:$K$504,"B2C")
A13: =DATE(2026,12,1) | B13: =COUNTIFS('Sales Register'!$A$5:$A$504,">="&A13,'Sales Register'!$A$5:$A$504,"<="&EOMONTH(A13,0)) | C13: =SUMIFS('Sales Register'!$F$5:$F$504,'Sales Register'!$A$5:$A$504,">="&A13,'Sales Register'!$A$5:$A$504,"<="&EOMONTH(A13,0)) | D13: =SUMIFS('Sales Register'!$G$5:$G$504,'Sales Register'!$A$5:$A$504,">="&A13,'Sales Register'!$A$5:$A$504,"<="&EOMONTH(A13,0)) | E13: =SUMIFS('Sales Register'!$H$5:$H$504,'Sales Register'!$A$5:$A$504,">="&A13,'Sales Register'!$A$5:$A$504,"<="&EOMONTH(A13,0)) | F13: =SUMIFS('Sales Register'!$I$5:$I$504,'Sales Register'!$A$5:$A$504,">="&A13,'Sales Register'!$A$5:$A$504,"<="&EOMONTH(A13,0)) | G13: =D13+E13+F13 | H13: =SUMIFS('Sales Register'!$F$5:$F$504,'Sales Register'!$A$5:$A$504,">="&A13,'Sales Register'!$A$5:$A$504,"<="&EOMONTH(A13,0),'Sales Register'!$K$5:$K$504,"B2B") | I13: =SUMIFS('Sales Register'!$F$5:$F$504,'Sales Register'!$A$5:$A$504,">="&A13,'Sales Register'!$A$5:$A$504,"<="&EOMONTH(A13,0),'Sales Register'!$K$5:$K$504,"B2C")
A14: =DATE(2027,1,1) | B14: =COUNTIFS('Sales Register'!$A$5:$A$504,">="&A14,'Sales Register'!$A$5:$A$504,"<="&EOMONTH(A14,0)) | C14: =SUMIFS('Sales Register'!$F$5:$F$504,'Sales Register'!$A$5:$A$504,">="&A14,'Sales Register'!$A$5:$A$504,"<="&EOMONTH(A14,0)) | D14: =SUMIFS('Sales Register'!$G$5:$G$504,'Sales Register'!$A$5:$A$504,">="&A14,'Sales Register'!$A$5:$A$504,"<="&EOMONTH(A14,0)) | E14: =SUMIFS('Sales Register'!$H$5:$H$504,'Sales Register'!$A$5:$A$504,">="&A14,'Sales Register'!$A$5:$A$504,"<="&EOMONTH(A14,0)) | F14: =SUMIFS('Sales Register'!$I$5:$I$504,'Sales Register'!$A$5:$A$504,">="&A14,'Sales Register'!$A$5:$A$504,"<="&EOMONTH(A14,0)) | G14: =D14+E14+F14 | H14: =SUMIFS('Sales Register'!$F$5:$F$504,'Sales Register'!$A$5:$A$504,">="&A14,'Sales Register'!$A$5:$A$504,"<="&EOMONTH(A14,0),'Sales Register'!$K$5:$K$504,"B2B") | I14: =SUMIFS('Sales Register'!$F$5:$F$504,'Sales Register'!$A$5:$A$504,">="&A14,'Sales Register'!$A$5:$A$504,"<="&EOMONTH(A14,0),'Sales Register'!$K$5:$K$504,"B2C")
A15: =DATE(2027,2,1) | B15: =COUNTIFS('Sales Register'!$A$5:$A$504,">="&A15,'Sales Register'!$A$5:$A$504,"<="&EOMONTH(A15,0)) | C15: =SUMIFS('Sales Register'!$F$5:$F$504,'Sales Register'!$A$5:$A$504,">="&A15,'Sales Register'!$A$5:$A$504,"<="&EOMONTH(A15,0)) | D15: =SUMIFS('Sales Register'!$G$5:$G$504,'Sales Register'!$A$5:$A$504,">="&A15,'Sales Register'!$A$5:$A$504,"<="&EOMONTH(A15,0)) | E15: =SUMIFS('Sales Register'!$H$5:$H$504,'Sales Register'!$A$5:$A$504,">="&A15,'Sales Register'!$A$5:$A$504,"<="&EOMONTH(A15,0)) | F15: =SUMIFS('Sales Register'!$I$5:$I$504,'Sales Register'!$A$5:$A$504,">="&A15,'Sales Register'!$A$5:$A$504,"<="&EOMONTH(A15,0)) | G15: =D15+E15+F15 | H15: =SUMIFS('Sales Register'!$F$5:$F$504,'Sales Register'!$A$5:$A$504,">="&A15,'Sales Register'!$A$5:$A$504,"<="&EOMONTH(A15,0),'Sales Register'!$K$5:$K$504,"B2B") | I15: =SUMIFS('Sales Register'!$F$5:$F$504,'Sales Register'!$A$5:$A$504,">="&A15,'Sales Register'!$A$5:$A$504,"<="&EOMONTH(A15,0),'Sales Register'!$K$5:$K$504,"B2C")
A16: =DATE(2027,3,1) | B16: =COUNTIFS('Sales Register'!$A$5:$A$504,">="&A16,'Sales Register'!$A$5:$A$504,"<="&EOMONTH(A16,0)) | C16: =SUMIFS('Sales Register'!$F$5:$F$504,'Sales Register'!$A$5:$A$504,">="&A16,'Sales Register'!$A$5:$A$504,"<="&EOMONTH(A16,0)) | D16: =SUMIFS('Sales Register'!$G$5:$G$504,'Sales Register'!$A$5:$A$504,">="&A16,'Sales Register'!$A$5:$A$504,"<="&EOMONTH(A16,0)) | E16: =SUMIFS('Sales Register'!$H$5:$H$504,'Sales Register'!$A$5:$A$504,">="&A16,'Sales Register'!$A$5:$A$504,"<="&EOMONTH(A16,0)) | F16: =SUMIFS('Sales Register'!$I$5:$I$504,'Sales Register'!$A$5:$A$504,">="&A16,'Sales Register'!$A$5:$A$504,"<="&EOMONTH(A16,0)) | G16: =D16+E16+F16 | H16: =SUMIFS('Sales Register'!$F$5:$F$504,'Sales Register'!$A$5:$A$504,">="&A16,'Sales Register'!$A$5:$A$504,"<="&EOMONTH(A16,0),'Sales Register'!$K$5:$K$504,"B2B") | I16: =SUMIFS('Sales Register'!$F$5:$F$504,'Sales Register'!$A$5:$A$504,">="&A16,'Sales Register'!$A$5:$A$504,"<="&EOMONTH(A16,0),'Sales Register'!$K$5:$K$504,"B2C")
A17: Total | B17: =SUM(B5:B16) | C17: =SUM(C5:C16) | D17: =SUM(D5:D16) | E17: =SUM(E5:E16) | F17: =SUM(F5:F16) | G17: =SUM(G5:G16) | H17: =SUM(H5:H16) | I17: =SUM(I5:I16)

Sheet HSN Register
A1: HSN Register (item lines)
A2: Log each invoice line here for the GSTR-1 HSN table
A4: Date | B4: Invoice No. | C4: HSN/SAC | D4: Description | E4: UQC (unit) | F4: Qty | G4: Taxable value | H4: GST % | I4: Tax amount
I5: =IF(G5="","",ROUND(G5*H5/100,2))
I6: =IF(G6="","",ROUND(G6*H6/100,2))
I7: =IF(G7="","",ROUND(G7*H7/100,2))
I8: =IF(G8="","",ROUND(G8*H8/100,2))
I9: =IF(G9="","",ROUND(G9*H9/100,2))
I10: =IF(G10="","",ROUND(G10*H10/100,2))
I11: =IF(G11="","",ROUND(G11*H11/100,2))
I12: =IF(G12="","",ROUND(G12*H12/100,2))
I13: =IF(G13="","",ROUND(G13*H13/100,2))
I14: =IF(G14="","",ROUND(G14*H14/100,2))
I15: =IF(G15="","",ROUND(G15*H15/100,2))
I16: =IF(G16="","",ROUND(G16*H16/100,2))
... I1004: =IF(G1004="","",ROUND(G1004*H1004/100,2))

Sheet HSN Summary
A1: HSN-wise Summary
A2: Type each HSN code once in column A — totals fill in automatically
A4: HSN/SAC | B4: Description | C4: Total qty | D4: Taxable value | E4: Tax amount
C5: =IF(A5="","",SUMIF('HSN Register'!$C$5:$C$1004,A5,'HSN Register'!$F$5:$F$1004)) | D5: =IF(A5="","",SUMIF('HSN Register'!$C$5:$C$1004,A5,'HSN Register'!$G$5:$G$1004)) | E5: =IF(A5="","",SUMIF('HSN Register'!$C$5:$C$1004,A5,'HSN Register'!$I$5:$I$1004))
C6: =IF(A6="","",SUMIF('HSN Register'!$C$5:$C$1004,A6,'HSN Register'!$F$5:$F$1004)) | D6: =IF(A6="","",SUMIF('HSN Register'!$C$5:$C$1004,A6,'HSN Register'!$G$5:$G$1004)) | E6: =IF(A6="","",SUMIF('HSN Register'!$C$5:$C$1004,A6,'HSN Register'!$I$5:$I$1004))
C7: =IF(A7="","",SUMIF('HSN Register'!$C$5:$C$1004,A7,'HSN Register'!$F$5:$F$1004)) | D7: =IF(A7="","",SUMIF('HSN Register'!$C$5:$C$1004,A7,'HSN Register'!$G$5:$G$1004)) | E7: =IF(A7="","",SUMIF('HSN Register'!$C$5:$C$1004,A7,'HSN Register'!$I$5:$I$1004))
C8: =IF(A8="","",SUMIF('HSN Register'!$C$5:$C$1004,A8,'HSN Register'!$F$5:$F$1004)) | D8: =IF(A8="","",SUMIF('HSN Register'!$C$5:$C$1004,A8,'HSN Register'!$G$5:$G$1004)) | E8: =IF(A8="","",SUMIF('HSN Register'!$C$5:$C$1004,A8,'HSN Register'!$I$5:$I$1004))
C9: =IF(A9="","",SUMIF('HSN Register'!$C$5:$C$1004,A9,'HSN Register'!$F$5:$F$1004)) | D9: =IF(A9="","",SUMIF('HSN Register'!$C$5:$C$1004,A9,'HSN Register'!$G$5:$G$1004)) | E9: =IF(A9="","",SUMIF('HSN Register'!$C$5:$C$1004,A9,'HSN Register'!$I$5:$I$1004))
C10: =IF(A10="","",SUMIF('HSN Register'!$C$5:$C$1004,A10,'HSN Register'!$F$5:$F$1004)) | D10: =IF(A10="","",SUMIF('HSN Register'!$C$5:$C$1004,A10,'HSN Register'!$G$5:$G$1004)) | E10: =IF(A10="","",SUMIF('HSN Register'!$C$5:$C$1004,A10,'HSN Register'!$I$5:$I$1004))
C11: =IF(A11="","",SUMIF('HSN Register'!$C$5:$C$1004,A11,'HSN Register'!$F$5:$F$1004)) | D11: =IF(A11="","",SUMIF('HSN Register'!$C$5:$C$1004,A11,'HSN Register'!$G$5:$G$1004)) | E11: =IF(A11="","",SUMIF('HSN Register'!$C$5:$C$1004,A11,'HSN Register'!$I$5:$I$1004))
C12: =IF(A12="","",SUMIF('HSN Register'!$C$5:$C$1004,A12,'HSN Register'!$F$5:$F$1004)) | D12: =IF(A12="","",SUMIF('HSN Register'!$C$5:$C$1004,A12,'HSN Register'!$G$5:$G$1004)) | E12: =IF(A12="","",SUMIF('HSN Register'!$C$5:$C$1004,A12,'HSN Register'!$I$5:$I$1004))
C13: =IF(A13="","",SUMIF('HSN Register'!$C$5:$C$1004,A13,'HSN Register'!$F$5:$F$1004)) | D13: =IF(A13="","",SUMIF('HSN Register'!$C$5:$C$1004,A13,'HSN Register'!$G$5:$G$1004)) | E13: =IF(A13="","",SUMIF('HSN Register'!$C$5:$C$1004,A13,'HSN Register'!$I$5:$I$1004))
C14: =IF(A14="","",SUMIF('HSN Register'!$C$5:$C$1004,A14,'HSN Register'!$F$5:$F$1004)) | D14: =IF(A14="","",SUMIF('HSN Register'!$C$5:$C$1004,A14,'HSN Register'!$G$5:$G$1004)) | E14: =IF(A14="","",SUMIF('HSN Register'!$C$5:$C$1004,A14,'HSN Register'!$I$5:$I$1004))
C15: =IF(A15="","",SUMIF('HSN Register'!$C$5:$C$1004,A15,'HSN Register'!$F$5:$F$1004)) | D15: =IF(A15="","",SUMIF('HSN Register'!$C$5:$C$1004,A15,'HSN Register'!$G$5:$G$1004)) | E15: =IF(A15="","",SUMIF('HSN Register'!$C$5:$C$1004,A15,'HSN Register'!$I$5:$I$1004))
C16: =IF(A16="","",SUMIF('HSN Register'!$C$5:$C$1004,A16,'HSN Register'!$F$5:$F$1004)) | D16: =IF(A16="","",SUMIF('HSN Register'!$C$5:$C$1004,A16,'HSN Register'!$G$5:$G$1004)) | E16: =IF(A16="","",SUMIF('HSN Register'!$C$5:$C$1004,A16,'HSN Register'!$I$5:$I$1004))
... C44: =IF(A44="","",SUMIF('HSN Register'!$C$5:$C$1004,A44,'HSN Register'!$F$5:$F$1004)) | D44: =IF(A44="","",SUMIF('HSN Register'!$C$5:$C$1004,A44,'HSN Register'!$G$5:$G$1004)) | E44: =IF(A44="","",SUMIF('HSN Register'!$C$5:$C$1004,A44,'HSN Register'!$I$5:$I$1004))

Sheet Purchase Register
A1: Purchase Register (inward supplies)
A2: One row per purchase bill. The last column checks the bill against your GSTR-2B data.
A4: Date | B4: Supplier | C4: Supplier GSTIN | D4: Bill / Invoice No. | E4: Taxable value | F4: CGST | G4: SGST | H4: IGST | I4: Total | J4: ITC eligible? (Y/N) | K4: Match key | L4: Status vs GSTR-2B
I5: =IF(E5="","",E5+F5+G5+H5) | K5: =IF(D5="","",UPPER(TRIM(C5))&"|"&UPPER(TRIM(D5))) | L5: =IF(K5="","",IF(COUNTIF('GSTR-2B Data'!$J$5:$J$504,K5)=0,"Not in 2B — follow up",IF(ABS(SUMIF('GSTR-2B Data'!$J$5:$J$504,K5,'GSTR-2B Data'!$I$5:$I$504)-(F5+G5+H5))>1,"Tax amount differs","Matched")))
I6: =IF(E6="","",E6+F6+G6+H6) | K6: =IF(D6="","",UPPER(TRIM(C6))&"|"&UPPER(TRIM(D6))) | L6: =IF(K6="","",IF(COUNTIF('GSTR-2B Data'!$J$5:$J$504,K6)=0,"Not in 2B — follow up",IF(ABS(SUMIF('GSTR-2B Data'!$J$5:$J$504,K6,'GSTR-2B Data'!$I$5:$I$504)-(F6+G6+H6))>1,"Tax amount differs","Matched")))
I7: =IF(E7="","",E7+F7+G7+H7) | K7: =IF(D7="","",UPPER(TRIM(C7))&"|"&UPPER(TRIM(D7))) | L7: =IF(K7="","",IF(COUNTIF('GSTR-2B Data'!$J$5:$J$504,K7)=0,"Not in 2B — follow up",IF(ABS(SUMIF('GSTR-2B Data'!$J$5:$J$504,K7,'GSTR-2B Data'!$I$5:$I$504)-(F7+G7+H7))>1,"Tax amount differs","Matched")))
I8: =IF(E8="","",E8+F8+G8+H8) | K8: =IF(D8="","",UPPER(TRIM(C8))&"|"&UPPER(TRIM(D8))) | L8: =IF(K8="","",IF(COUNTIF('GSTR-2B Data'!$J$5:$J$504,K8)=0,"Not in 2B — follow up",IF(ABS(SUMIF('GSTR-2B Data'!$J$5:$J$504,K8,'GSTR-2B Data'!$I$5:$I$504)-(F8+G8+H8))>1,"Tax amount differs","Matched")))
I9: =IF(E9="","",E9+F9+G9+H9) | K9: =IF(D9="","",UPPER(TRIM(C9))&"|"&UPPER(TRIM(D9))) | L9: =IF(K9="","",IF(COUNTIF('GSTR-2B Data'!$J$5:$J$504,K9)=0,"Not in 2B — follow up",IF(ABS(SUMIF('GSTR-2B Data'!$J$5:$J$504,K9,'GSTR-2B Data'!$I$5:$I$504)-(F9+G9+H9))>1,"Tax amount differs","Matched")))
I10: =IF(E10="","",E10+F10+G10+H10) | K10: =IF(D10="","",UPPER(TRIM(C10))&"|"&UPPER(TRIM(D10))) | L10: =IF(K10="","",IF(COUNTIF('GSTR-2B Data'!$J$5:$J$504,K10)=0,"Not in 2B — follow up",IF(ABS(SUMIF('GSTR-2B Data'!$J$5:$J$504,K10,'GSTR-2B Data'!$I$5:$I$504)-(F10+G10+H10))>1,"Tax amount differs","Matched")))
I11: =IF(E11="","",E11+F11+G11+H11) | K11: =IF(D11="","",UPPER(TRIM(C11))&"|"&UPPER(TRIM(D11))) | L11: =IF(K11="","",IF(COUNTIF('GSTR-2B Data'!$J$5:$J$504,K11)=0,"Not in 2B — follow up",IF(ABS(SUMIF('GSTR-2B Data'!$J$5:$J$504,K11,'GSTR-2B Data'!$I$5:$I$504)-(F11+G11+H11))>1,"Tax amount differs","Matched")))
I12: =IF(E12="","",E12+F12+G12+H12) | K12: =IF(D12="","",UPPER(TRIM(C12))&"|"&UPPER(TRIM(D12))) | L12: =IF(K12="","",IF(COUNTIF('GSTR-2B Data'!$J$5:$J$504,K12)=0,"Not in 2B — follow up",IF(ABS(SUMIF('GSTR-2B Data'!$J$5:$J$504,K12,'GSTR-2B Data'!$I$5:$I$504)-(F12+G12+H12))>1,"Tax amount differs","Matched")))
I13: =IF(E13="","",E13+F13+G13+H13) | K13: =IF(D13="","",UPPER(TRIM(C13))&"|"&UPPER(TRIM(D13))) | L13: =IF(K13="","",IF(COUNTIF('GSTR-2B Data'!$J$5:$J$504,K13)=0,"Not in 2B — follow up",IF(ABS(SUMIF('GSTR-2B Data'!$J$5:$J$504,K13,'GSTR-2B Data'!$I$5:$I$504)-(F13+G13+H13))>1,"Tax amount differs","Matched")))
I14: =IF(E14="","",E14+F14+G14+H14) | K14: =IF(D14="","",UPPER(TRIM(C14))&"|"&UPPER(TRIM(D14))) | L14: =IF(K14="","",IF(COUNTIF('GSTR-2B Data'!$J$5:$J$504,K14)=0,"Not in 2B — follow up",IF(ABS(SUMIF('GSTR-2B Data'!$J$5:$J$504,K14,'GSTR-2B Data'!$I$5:$I$504)-(F14+G14+H14))>1,"Tax amount differs","Matched")))
I15: =IF(E15="","",E15+F15+G15+H15) | K15: =IF(D15="","",UPPER(TRIM(C15))&"|"&UPPER(TRIM(D15))) | L15: =IF(K15="","",IF(COUNTIF('GSTR-2B Data'!$J$5:$J$504,K15)=0,"Not in 2B — follow up",IF(ABS(SUMIF('GSTR-2B Data'!$J$5:$J$504,K15,'GSTR-2B Data'!$I$5:$I$504)-(F15+G15+H15))>1,"Tax amount differs","Matched")))
I16: =IF(E16="","",E16+F16+G16+H16) | K16: =IF(D16="","",UPPER(TRIM(C16))&"|"&UPPER(TRIM(D16))) | L16: =IF(K16="","",IF(COUNTIF('GSTR-2B Data'!$J$5:$J$504,K16)=0,"Not in 2B — follow up",IF(ABS(SUMIF('GSTR-2B Data'!$J$5:$J$504,K16,'GSTR-2B Data'!$I$5:$I$504)-(F16+G16+H16))>1,"Tax amount differs","Matched")))
... I504: =IF(E504="","",E504+F504+G504+H504) | K504: =IF(D504="","",UPPER(TRIM(C504))&"|"&UPPER(TRIM(D504))) | L504: =IF(K504="","",IF(COUNTIF('GSTR-2B Data'!$J$5:$J$504,K504)=0,"Not in 2B — follow up",IF(ABS(SUMIF('GSTR-2B Data'!$J$5:$J$504,K504,'GSTR-2B Data'!$I$5:$I$504)-(F504+G504+H504))>1,"Tax amount differs","Matched")))

Sheet GSTR-2B Data
A1: GSTR-2B Data (paste from the portal)
A2: GST portal → Returns → GSTR-2B → Download (Excel) → 'B2B' tab. Paste supplier GSTIN, name, invoice no., date, taxable value and tax into the yellow columns.
A4: Supplier GSTIN | B4: Supplier name | C4: Invoice No. | D4: Invoice date | E4: Taxable value | F4: CGST | G4: SGST | H4: IGST | I4: Total tax | J4: Match key | K4: In your books?
I5: =IF(C5="","",F5+G5+H5) | J5: =IF(C5="","",UPPER(TRIM(A5))&"|"&UPPER(TRIM(C5))) | K5: =IF(J5="","",IF(COUNTIF('Purchase Register'!$K$5:$K$504,J5)=0,"In 2B, not in your books","In books"))
I6: =IF(C6="","",F6+G6+H6) | J6: =IF(C6="","",UPPER(TRIM(A6))&"|"&UPPER(TRIM(C6))) | K6: =IF(J6="","",IF(COUNTIF('Purchase Register'!$K$5:$K$504,J6)=0,"In 2B, not in your books","In books"))
I7: =IF(C7="","",F7+G7+H7) | J7: =IF(C7="","",UPPER(TRIM(A7))&"|"&UPPER(TRIM(C7))) | K7: =IF(J7="","",IF(COUNTIF('Purchase Register'!$K$5:$K$504,J7)=0,"In 2B, not in your books","In books"))
I8: =IF(C8="","",F8+G8+H8) | J8: =IF(C8="","",UPPER(TRIM(A8))&"|"&UPPER(TRIM(C8))) | K8: =IF(J8="","",IF(COUNTIF('Purchase Register'!$K$5:$K$504,J8)=0,"In 2B, not in your books","In books"))
I9: =IF(C9="","",F9+G9+H9) | J9: =IF(C9="","",UPPER(TRIM(A9))&"|"&UPPER(TRIM(C9))) | K9: =IF(J9="","",IF(COUNTIF('Purchase Register'!$K$5:$K$504,J9)=0,"In 2B, not in your books","In books"))
I10: =IF(C10="","",F10+G10+H10) | J10: =IF(C10="","",UPPER(TRIM(A10))&"|"&UPPER(TRIM(C10))) | K10: =IF(J10="","",IF(COUNTIF('Purchase Register'!$K$5:$K$504,J10)=0,"In 2B, not in your books","In books"))
I11: =IF(C11="","",F11+G11+H11) | J11: =IF(C11="","",UPPER(TRIM(A11))&"|"&UPPER(TRIM(C11))) | K11: =IF(J11="","",IF(COUNTIF('Purchase Register'!$K$5:$K$504,J11)=0,"In 2B, not in your books","In books"))
I12: =IF(C12="","",F12+G12+H12) | J12: =IF(C12="","",UPPER(TRIM(A12))&"|"&UPPER(TRIM(C12))) | K12: =IF(J12="","",IF(COUNTIF('Purchase Register'!$K$5:$K$504,J12)=0,"In 2B, not in your books","In books"))
I13: =IF(C13="","",F13+G13+H13) | J13: =IF(C13="","",UPPER(TRIM(A13))&"|"&UPPER(TRIM(C13))) | K13: =IF(J13="","",IF(COUNTIF('Purchase Register'!$K$5:$K$504,J13)=0,"In 2B, not in your books","In books"))
I14: =IF(C14="","",F14+G14+H14) | J14: =IF(C14="","",UPPER(TRIM(A14))&"|"&UPPER(TRIM(C14))) | K14: =IF(J14="","",IF(COUNTIF('Purchase Register'!$K$5:$K$504,J14)=0,"In 2B, not in your books","In books"))
I15: =IF(C15="","",F15+G15+H15) | J15: =IF(C15="","",UPPER(TRIM(A15))&"|"&UPPER(TRIM(C15))) | K15: =IF(J15="","",IF(COUNTIF('Purchase Register'!$K$5:$K$504,J15)=0,"In 2B, not in your books","In books"))
I16: =IF(C16="","",F16+G16+H16) | J16: =IF(C16="","",UPPER(TRIM(A16))&"|"&UPPER(TRIM(C16))) | K16: =IF(J16="","",IF(COUNTIF('Purchase Register'!$K$5:$K$504,J16)=0,"In 2B, not in your books","In books"))
... I504: =IF(C504="","",F504+G504+H504) | J504: =IF(C504="","",UPPER(TRIM(A504))&"|"&UPPER(TRIM(C504))) | K504: =IF(J504="","",IF(COUNTIF('Purchase Register'!$K$5:$K$504,J504)=0,"In 2B, not in your books","In books"))

Sheet ITC Reconciliation
A1: ITC Reconciliation — Books vs GSTR-2B
A2: Fills automatically from the two sheets
A4: Result | B4: No. of invoices | C4: Tax amount | D4: What to do
A5: Matched | B5: =COUNTIF('Purchase Register'!$L$5:$L$504,"Matched") | C5: =SUMPRODUCT(('Purchase Register'!$L$5:$L$504="Matched")*('Purchase Register'!$F$5:$F$504+'Purchase Register'!$G$5:$G$504+'Purchase Register'!$H$5:$H$504)) | D5: Safe to claim (if otherwise eligible).
A6: Not in 2B — follow up | B6: =COUNTIF('Purchase Register'!$L$5:$L$504,"Not in 2B — follow up") | C6: =SUMPRODUCT(('Purchase Register'!$L$5:$L$504="Not in 2B — follow up")*('Purchase Register'!$F$5:$F$504+'Purchase Register'!$G$5:$G$504+'Purchase Register'!$H$5:$H$504)) | D6: Ask the supplier to upload the invoice in their GSTR-1/IFF. Claim the credit only when it appears in your 2B.
A7: Tax amount differs | B7: =COUNTIF('Purchase Register'!$L$5:$L$504,"Tax amount differs") | C7: =SUMPRODUCT(('Purchase Register'!$L$5:$L$504="Tax amount differs")*('Purchase Register'!$F$5:$F$504+'Purchase Register'!$G$5:$G$504+'Purchase Register'!$H$5:$H$504)) | D7: Check the invoice — wrong rate, typing error, or the supplier needs to amend.
A8: In 2B, not in your books | B8: =COUNTIF('GSTR-2B Data'!$K$5:$K$504,"In 2B, not in your books") | C8: =SUMIF('GSTR-2B Data'!$K$5:$K$504,"In 2B, not in your books",'GSTR-2B Data'!$I$5:$I$504) | D8: Either a bill you forgot to record, or a supplier reported a sale to you by mistake — check before claiming.
A11: Matching is on supplier GSTIN + invoice number (spaces and capital letters ignored). If a supplier writes the invoice number differently, correct it in one of the sheets so the two match.

Sheet GSTR-3B Working
A1: GSTR-3B Working — FY 2026-27
A2: Output tax from 'Monthly Summary'; ITC = eligible purchase bills that are matched with GSTR-2B (by bill date). Use the adjustment column for anything else.
A4: Month | B4: Output CGST | C4: Output SGST | D4: Output IGST | E4: Total output tax | F4: Matched ITC (books) | G4: ITC adjustment (+/−) | H4: ITC available incl. brought forward | I4: Cash to pay (approx.) | J4: ITC carried forward | K4: Note
A5: =DATE(2026,4,1) | B5: ='Monthly Summary'!D5 | C5: ='Monthly Summary'!E5 | D5: ='Monthly Summary'!F5 | E5: =B5+C5+D5 | F5: =SUMPRODUCT(('Purchase Register'!$A$5:$A$504>=A5)*('Purchase Register'!$A$5:$A$504<=EOMONTH(A5,0))*('Purchase Register'!$J$5:$J$504="Y")*('Purchase Register'!$L$5:$L$504="Matched")*('Purchase Register'!$F$5:$F$504+'Purchase Register'!$G$5:$G$504+'Purchase Register'!$H$5:$H$504)) | H5: =F5+G5 | I5: =MAX(0,E5-H5) | J5: =MAX(0,H5-E5)
A6: =DATE(2026,5,1) | B6: ='Monthly Summary'!D6 | C6: ='Monthly Summary'!E6 | D6: ='Monthly Summary'!F6 | E6: =B6+C6+D6 | F6: =SUMPRODUCT(('Purchase Register'!$A$5:$A$504>=A6)*('Purchase Register'!$A$5:$A$504<=EOMONTH(A6,0))*('Purchase Register'!$J$5:$J$504="Y")*('Purchase Register'!$L$5:$L$504="Matched")*('Purchase Register'!$F$5:$F$504+'Purchase Register'!$G$5:$G$504+'Purchase Register'!$H$5:$H$504)) | H6: =F6+G6+J5 | I6: =MAX(0,E6-H6) | J6: =MAX(0,H6-E6)
A7: =DATE(2026,6,1) | B7: ='Monthly Summary'!D7 | C7: ='Monthly Summary'!E7 | D7: ='Monthly Summary'!F7 | E7: =B7+C7+D7 | F7: =SUMPRODUCT(('Purchase Register'!$A$5:$A$504>=A7)*('Purchase Register'!$A$5:$A$504<=EOMONTH(A7,0))*('Purchase Register'!$J$5:$J$504="Y")*('Purchase Register'!$L$5:$L$504="Matched")*('Purchase Register'!$F$5:$F$504+'Purchase Register'!$G$5:$G$504+'Purchase Register'!$H$5:$H$504)) | H7: =F7+G7+J6 | I7: =MAX(0,E7-H7) | J7: =MAX(0,H7-E7)
A8: =DATE(2026,7,1) | B8: ='Monthly Summary'!D8 | C8: ='Monthly Summary'!E8 | D8: ='Monthly Summary'!F8 | E8: =B8+C8+D8 | F8: =SUMPRODUCT(('Purchase Register'!$A$5:$A$504>=A8)*('Purchase Register'!$A$5:$A$504<=EOMONTH(A8,0))*('Purchase Register'!$J$5:$J$504="Y")*('Purchase Register'!$L$5:$L$504="Matched")*('Purchase Register'!$F$5:$F$504+'Purchase Register'!$G$5:$G$504+'Purchase Register'!$H$5:$H$504)) | H8: =F8+G8+J7 | I8: =MAX(0,E8-H8) | J8: =MAX(0,H8-E8)
A9: =DATE(2026,8,1) | B9: ='Monthly Summary'!D9 | C9: ='Monthly Summary'!E9 | D9: ='Monthly Summary'!F9 | E9: =B9+C9+D9 | F9: =SUMPRODUCT(('Purchase Register'!$A$5:$A$504>=A9)*('Purchase Register'!$A$5:$A$504<=EOMONTH(A9,0))*('Purchase Register'!$J$5:$J$504="Y")*('Purchase Register'!$L$5:$L$504="Matched")*('Purchase Register'!$F$5:$F$504+'Purchase Register'!$G$5:$G$504+'Purchase Register'!$H$5:$H$504)) | H9: =F9+G9+J8 | I9: =MAX(0,E9-H9) | J9: =MAX(0,H9-E9)
A10: =DATE(2026,9,1) | B10: ='Monthly Summary'!D10 | C10: ='Monthly Summary'!E10 | D10: ='Monthly Summary'!F10 | E10: =B10+C10+D10 | F10: =SUMPRODUCT(('Purchase Register'!$A$5:$A$504>=A10)*('Purchase Register'!$A$5:$A$504<=EOMONTH(A10,0))*('Purchase Register'!$J$5:$J$504="Y")*('Purchase Register'!$L$5:$L$504="Matched")*('Purchase Register'!$F$5:$F$504+'Purchase Register'!$G$5:$G$504+'Purchase Register'!$H$5:$H$504)) | H10: =F10+G10+J9 | I10: =MAX(0,E10-H10) | J10: =MAX(0,H10-E10)
A11: =DATE(2026,10,1) | B11: ='Monthly Summary'!D11 | C11: ='Monthly Summary'!E11 | D11: ='Monthly Summary'!F11 | E11: =B11+C11+D11 | F11: =SUMPRODUCT(('Purchase Register'!$A$5:$A$504>=A11)*('Purchase Register'!$A$5:$A$504<=EOMONTH(A11,0))*('Purchase Register'!$J$5:$J$504="Y")*('Purchase Register'!$L$5:$L$504="Matched")*('Purchase Register'!$F$5:$F$504+'Purchase Register'!$G$5:$G$504+'Purchase Register'!$H$5:$H$504)) | H11: =F11+G11+J10 | I11: =MAX(0,E11-H11) | J11: =MAX(0,H11-E11)
A12: =DATE(2026,11,1) | B12: ='Monthly Summary'!D12 | C12: ='Monthly Summary'!E12 | D12: ='Monthly Summary'!F12 | E12: =B12+C12+D12 | F12: =SUMPRODUCT(('Purchase Register'!$A$5:$A$504>=A12)*('Purchase Register'!$A$5:$A$504<=EOMONTH(A12,0))*('Purchase Register'!$J$5:$J$504="Y")*('Purchase Register'!$L$5:$L$504="Matched")*('Purchase Register'!$F$5:$F$504+'Purchase Register'!$G$5:$G$504+'Purchase Register'!$H$5:$H$504)) | H12: =F12+G12+J11 | I12: =MAX(0,E12-H12) | J12: =MAX(0,H12-E12)
A13: =DATE(2026,12,1) | B13: ='Monthly Summary'!D13 | C13: ='Monthly Summary'!E13 | D13: ='Monthly Summary'!F13 | E13: =B13+C13+D13 | F13: =SUMPRODUCT(('Purchase Register'!$A$5:$A$504>=A13)*('Purchase Register'!$A$5:$A$504<=EOMONTH(A13,0))*('Purchase Register'!$J$5:$J$504="Y")*('Purchase Register'!$L$5:$L$504="Matched")*('Purchase Register'!$F$5:$F$504+'Purchase Register'!$G$5:$G$504+'Purchase Register'!$H$5:$H$504)) | H13: =F13+G13+J12 | I13: =MAX(0,E13-H13) | J13: =MAX(0,H13-E13)
A14: =DATE(2027,1,1) | B14: ='Monthly Summary'!D14 | C14: ='Monthly Summary'!E14 | D14: ='Monthly Summary'!F14 | E14: =B14+C14+D14 | F14: =SUMPRODUCT(('Purchase Register'!$A$5:$A$504>=A14)*('Purchase Register'!$A$5:$A$504<=EOMONTH(A14,0))*('Purchase Register'!$J$5:$J$504="Y")*('Purchase Register'!$L$5:$L$504="Matched")*('Purchase Register'!$F$5:$F$504+'Purchase Register'!$G$5:$G$504+'Purchase Register'!$H$5:$H$504)) | H14: =F14+G14+J13 | I14: =MAX(0,E14-H14) | J14: =MAX(0,H14-E14)
A15: =DATE(2027,2,1) | B15: ='Monthly Summary'!D15 | C15: ='Monthly Summary'!E15 | D15: ='Monthly Summary'!F15 | E15: =B15+C15+D15 | F15: =SUMPRODUCT(('Purchase Register'!$A$5:$A$504>=A15)*('Purchase Register'!$A$5:$A$504<=EOMONTH(A15,0))*('Purchase Register'!$J$5:$J$504="Y")*('Purchase Register'!$L$5:$L$504="Matched")*('Purchase Register'!$F$5:$F$504+'Purchase Register'!$G$5:$G$504+'Purchase Register'!$H$5:$H$504)) | H15: =F15+G15+J14 | I15: =MAX(0,E15-H15) | J15: =MAX(0,H15-E15)
A16: =DATE(2027,3,1) | B16: ='Monthly Summary'!D16 | C16: ='Monthly Summary'!E16 | D16: ='Monthly Summary'!F16 | E16: =B16+C16+D16 | F16: =SUMPRODUCT(('Purchase Register'!$A$5:$A$504>=A16)*('Purchase Register'!$A$5:$A$504<=EOMONTH(A16,0))*('Purchase Register'!$J$5:$J$504="Y")*('Purchase Register'!$L$5:$L$504="Matched")*('Purchase Register'!$F$5:$F$504+'Purchase Register'!$G$5:$G$504+'Purchase Register'!$H$5:$H$504)) | H16: =F16+G16+J15 | I16: =MAX(0,E16-H16) | J16: =MAX(0,H16-E16)
A17: Total | B17: =SUM(B5:B16) | C17: =SUM(C5:C16) | D17: =SUM(D5:D16) | E17: =SUM(E5:E16) | F17: =SUM(F5:F16) | G17: =SUM(G5:G16) | I17: =SUM(I5:I16)
A19: This is a planning figure. The portal sets off credit head-wise in a fixed order (IGST first, then CGST/SGST) — the exact cash per head is shown in GSTR-3B Table 6.1. Blocked credits (Section 17(5)) must be marked 'N' in the Purchase Register.

Sheet Due Date Calendar
A1: GST Due Date Calendar — FY 2026-27
A2: Statutory dates. The government sometimes extends a date — if so, just change it in column C. Enter the date you filed in column E.
A4: Return / payment | B4: Period | C4: Due date | D4: Who files it | E4: Filed on | F4: Status
A5: GSTR-1 | B5: Apr-26 | C5: =DATE(2026,5,11) | D5: Monthly filers | F5: =IF(E5<>"",IF(E5<=C5,"Filed on time","Filed late — see Late Fee sheet"),IF(TODAY()>C5,"OVERDUE",IF(C5-TODAY()<=5,"Due in "&(C5-TODAY())&" day(s)","Upcoming")))
A6: GSTR-3B + tax payment | B6: Apr-26 | C6: =DATE(2026,5,20) | D6: Monthly filers | F6: =IF(E6<>"",IF(E6<=C6,"Filed on time","Filed late — see Late Fee sheet"),IF(TODAY()>C6,"OVERDUE",IF(C6-TODAY()<=5,"Due in "&(C6-TODAY())&" day(s)","Upcoming")))
A7: IFF (optional B2B invoices) | B7: Apr-26 | C7: =DATE(2026,5,13) | D7: QRMP (quarterly) filers | F7: =IF(E7<>"",IF(E7<=C7,"Filed on time","Filed late — see Late Fee sheet"),IF(TODAY()>C7,"OVERDUE",IF(C7-TODAY()<=5,"Due in "&(C7-TODAY())&" day(s)","Upcoming")))
A8: PMT-06 tax payment | B8: Apr-26 | C8: =DATE(2026,5,25) | D8: QRMP (quarterly) filers | F8: =IF(E8<>"",IF(E8<=C8,"Filed on time","Filed late — see Late Fee sheet"),IF(TODAY()>C8,"OVERDUE",IF(C8-TODAY()<=5,"Due in "&(C8-TODAY())&" day(s)","Upcoming")))
A9: GSTR-1 | B9: May-26 | C9: =DATE(2026,6,11) | D9: Monthly filers | F9: =IF(E9<>"",IF(E9<=C9,"Filed on time","Filed late — see Late Fee sheet"),IF(TODAY()>C9,"OVERDUE",IF(C9-TODAY()<=5,"Due in "&(C9-TODAY())&" day(s)","Upcoming")))
A10: GSTR-3B + tax payment | B10: May-26 | C10: =DATE(2026,6,20) | D10: Monthly filers | F10: =IF(E10<>"",IF(E10<=C10,"Filed on time","Filed late — see Late Fee sheet"),IF(TODAY()>C10,"OVERDUE",IF(C10-TODAY()<=5,"Due in "&(C10-TODAY())&" day(s)","Upcoming")))
A11: IFF (optional B2B invoices) | B11: May-26 | C11: =DATE(2026,6,13) | D11: QRMP (quarterly) filers | F11: =IF(E11<>"",IF(E11<=C11,"Filed on time","Filed late — see Late Fee sheet"),IF(TODAY()>C11,"OVERDUE",IF(C11-TODAY()<=5,"Due in "&(C11-TODAY())&" day(s)","Upcoming")))
A12: PMT-06 tax payment | B12: May-26 | C12: =DATE(2026,6,25) | D12: QRMP (quarterly) filers | F12: =IF(E12<>"",IF(E12<=C12,"Filed on time","Filed late — see Late Fee sheet"),IF(TODAY()>C12,"OVERDUE",IF(C12-TODAY()<=5,"Due in "&(C12-TODAY())&" day(s)","Upcoming")))
A13: GSTR-1 | B13: Jun-26 | C13: =DATE(2026,7,11) | D13: Monthly filers | F13: =IF(E13<>"",IF(E13<=C13,"Filed on time","Filed late — see Late Fee sheet"),IF(TODAY()>C13,"OVERDUE",IF(C13-TODAY()<=5,"Due in "&(C13-TODAY())&" day(s)","Upcoming")))
A14: GSTR-3B + tax payment | B14: Jun-26 | C14: =DATE(2026,7,20) | D14: Monthly filers | F14: =IF(E14<>"",IF(E14<=C14,"Filed on time","Filed late — see Late Fee sheet"),IF(TODAY()>C14,"OVERDUE",IF(C14-TODAY()<=5,"Due in "&(C14-TODAY())&" day(s)","Upcoming")))
A15: GSTR-1 (quarterly) | B15: Apr–Jun-26 | C15: =DATE(2026,7,13) | D15: QRMP (quarterly) filers | F15: =IF(E15<>"",IF(E15<=C15,"Filed on time","Filed late — see Late Fee sheet"),IF(TODAY()>C15,"OVERDUE",IF(C15-TODAY()<=5,"Due in "&(C15-TODAY())&" day(s)","Upcoming")))
A16: GSTR-3B (quarterly) + tax | B16: Apr–Jun-26 | C16: =DATE(2026,7,IF(ISNUMBER(MATCH(LEFT(Settings!$B$8,2),{"22","23","24","25","26","27","29","30","31","32","33","34","35","36","37"},0)),22,24)) | D16: QRMP filers (22nd or 24th by your state — from Settings) | F16: =IF(E16<>"",IF(E16<=C16,"Filed on time","Filed late — see Late Fee sheet"),IF(TODAY()>C16,"OVERDUE",IF(C16-TODAY()<=5,"Due in "&(C16-TODAY())&" day(s)","Upcoming")))
A17: CMP-08 (composition tax) | B17: Apr–Jun-26 | C17: =DATE(2026,7,18) | D17: Composition dealers | F17: =IF(E17<>"",IF(E17<=C17,"Filed on time","Filed late — see Late Fee sheet"),IF(TODAY()>C17,"OVERDUE",IF(C17-TODAY()<=5,"Due in "&(C17-TODAY())&" day(s)","Upcoming")))
A18: GSTR-1 | B18: Jul-26 | C18: =DATE(2026,8,11) | D18: Monthly filers | F18: =IF(E18<>"",IF(E18<=C18,"Filed on time","Filed late — see Late Fee sheet"),IF(TODAY()>C18,"OVERDUE",IF(C18-TODAY()<=5,"Due in "&(C18-TODAY())&" day(s)","Upcoming")))
A19: GSTR-3B + tax payment | B19: Jul-26 | C19: =DATE(2026,8,20) | D19: Monthly filers | F19: =IF(E19<>"",IF(E19<=C19,"Filed on time","Filed late — see Late Fee sheet"),IF(TODAY()>C19,"OVERDUE",IF(C19-TODAY()<=5,"Due in "&(C19-TODAY())&" day(s)","Upcoming")))
A20: IFF (optional B2B invoices) | B20: Jul-26 | C20: =DATE(2026,8,13) | D20: QRMP (quarterly) filers | F20: =IF(E20<>"",IF(E20<=C20,"Filed on time","Filed late — see Late Fee sheet"),IF(TODAY()>C20,"OVERDUE",IF(C20-TODAY()<=5,"Due in "&(C20-TODAY())&" day(s)","Upcoming")))
A21: PMT-06 tax payment | B21: Jul-26 | C21: =DATE(2026,8,25) | D21: QRMP (quarterly) filers | F21: =IF(E21<>"",IF(E21<=C21,"Filed on time","Filed late — see Late Fee sheet"),IF(TODAY()>C21,"OVERDUE",IF(C21-TODAY()<=5,"Due in "&(C21-TODAY())&" day(s)","Upcoming")))
A22: GSTR-1 | B22: Aug-26 | C22: =DATE(2026,9,11) | D22: Monthly filers | F22: =IF(E22<>"",IF(E22<=C22,"Filed on time","Filed late — see Late Fee sheet"),IF(TODAY()>C22,"OVERDUE",IF(C22-TODAY()<=5,"Due in "&(C22-TODAY())&" day(s)","Upcoming")))
A23: GSTR-3B + tax payment | B23: Aug-26 | C23: =DATE(2026,9,20) | D23: Monthly filers | F23: =IF(E23<>"",IF(E23<=C23,"Filed on time","Filed late — see Late Fee sheet"),IF(TODAY()>C23,"OVERDUE",IF(C23-TODAY()<=5,"Due in "&(C23-TODAY())&" day(s)","Upcoming")))
A24: IFF (optional B2B invoices) | B24: Aug-26 | C24: =DATE(2026,9,13) | D24: QRMP (quarterly) filers | F24: =IF(E24<>"",IF(E24<=C24,"Filed on time","Filed late — see Late Fee sheet"),IF(TODAY()>C24,"OVERDUE",IF(C24-TODAY()<=5,"Due in "&(C24-TODAY())&" day(s)","Upcoming")))
A25: PMT-06 tax payment | B25: Aug-26 | C25: =DATE(2026,9,25) | D25: QRMP (quarterly) filers | F25: =IF(E25<>"",IF(E25<=C25,"Filed on time","Filed late — see Late Fee sheet"),IF(TODAY()>C25,"OVERDUE",IF(C25-TODAY()<=5,"Due in "&(C25-TODAY())&" day(s)","Upcoming")))
A26: GSTR-1 | B26: Sep-26 | C26: =DATE(2026,10,11) | D26: Monthly filers | F26: =IF(E26<>"",IF(E26<=C26,"Filed on time","Filed late — see Late Fee sheet"),IF(TODAY()>C26,"OVERDUE",IF(C26-TODAY()<=5,"Due in "&(C26-TODAY())&" day(s)","Upcoming")))
A27: GSTR-3B + tax payment | B27: Sep-26 | C27: =DATE(2026,10,20) | D27: Monthly filers | F27: =IF(E27<>"",IF(E27<=C27,"Filed on time","Filed late — see Late Fee sheet"),IF(TODAY()>C27,"OVERDUE",IF(C27-TODAY()<=5,"Due in "&(C27-TODAY())&" day(s)","Upcoming")))
A28: GSTR-1 (quarterly) | B28: Jul–Sep-26 | C28: =DATE(2026,10,13) | D28: QRMP (quarterly) filers | F28: =IF(E28<>"",IF(E28<=C28,"Filed on time","Filed late — see Late Fee sheet"),IF(TODAY()>C28,"OVERDUE",IF(C28-TODAY()<=5,"Due in "&(C28-TODAY())&" day(s)","Upcoming")))
A29: GSTR-3B (quarterly) + tax | B29: Jul–Sep-26 | C29: =DATE(2026,10,IF(ISNUMBER(MATCH(LEFT(Settings!$B$8,2),{"22","23","24","25","26","27","29","30","31","32","33","34","35","36","37"},0)),22,24)) | D29: QRMP filers (22nd or 24th by your state — from Settings) | F29: =IF(E29<>"",IF(E29<=C29,"Filed on time","Filed late — see Late Fee sheet"),IF(TODAY()>C29,"OVERDUE",IF(C29-TODAY()<=5,"Due in "&(C29-TODAY())&" day(s)","Upcoming")))
A30: CMP-08 (composition tax) | B30: Jul–Sep-26 | C30: =DATE(2026,10,18) | D30: Composition dealers | F30: =IF(E30<>"",IF(E30<=C30,"Filed on time","Filed late — see Late Fee sheet"),IF(TODAY()>C30,"OVERDUE",IF(C30-TODAY()<=5,"Due in "&(C30-TODAY())&" day(s)","Upcoming")))
A31: GSTR-1 | B31: Oct-26 | C31: =DATE(2026,11,11) | D31: Monthly filers | F31: =IF(E31<>"",IF(E31<=C31,"Filed on time","Filed late — see Late Fee sheet"),IF(TODAY()>C31,"OVERDUE",IF(C31-TODAY()<=5,"Due in "&(C31-TODAY())&" day(s)","Upcoming")))
A32: GSTR-3B + tax payment | B32: Oct-26 | C32: =DATE(2026,11,20) | D32: Monthly filers | F32: =IF(E32<>"",IF(E32<=C32,"Filed on time","Filed late — see Late Fee sheet"),IF(TODAY()>C32,"OVERDUE",IF(C32-TODAY()<=5,"Due in "&(C32-TODAY())&" day(s)","Upcoming")))
A33: IFF (optional B2B invoices) | B33: Oct-26 | C33: =DATE(2026,11,13) | D33: QRMP (quarterly) filers | F33: =IF(E33<>"",IF(E33<=C33,"Filed on time","Filed late — see Late Fee sheet"),IF(TODAY()>C33,"OVERDUE",IF(C33-TODAY()<=5,"Due in "&(C33-TODAY())&" day(s)","Upcoming")))
A34: PMT-06 tax payment | B34: Oct-26 | C34: =DATE(2026,11,25) | D34: QRMP (quarterly) filers | F34: =IF(E34<>"",IF(E34<=C34,"Filed on time","Filed late — see Late Fee sheet"),IF(TODAY()>C34,"OVERDUE",IF(C34-TODAY()<=5,"Due in "&(C34-TODAY())&" day(s)","Upcoming")))
A35: GSTR-1 | B35: Nov-26 | C35: =DATE(2026,12,11) | D35: Monthly filers | F35: =IF(E35<>"",IF(E35<=C35,"Filed on time","Filed late — see Late Fee sheet"),IF(TODAY()>C35,"OVERDUE",IF(C35-TODAY()<=5,"Due in "&(C35-TODAY())&" day(s)","Upcoming")))
A36: GSTR-3B + tax payment | B36: Nov-26 | C36: =DATE(2026,12,20) | D36: Monthly filers | F36: =IF(E36<>"",IF(E36<=C36,"Filed on time","Filed late — see Late Fee sheet"),IF(TODAY()>C36,"OVERDUE",IF(C36-TODAY()<=5,"Due in "&(C36-TODAY())&" day(s)","Upcoming")))
A37: IFF (optional B2B invoices) | B37: Nov-26 | C37: =DATE(2026,12,13) | D37: QRMP (quarterly) filers | F37: =IF(E37<>"",IF(E37<=C37,"Filed on time","Filed late — see Late Fee sheet"),IF(TODAY()>C37,"OVERDUE",IF(C37-TODAY()<=5,"Due in "&(C37-TODAY())&" day(s)","Upcoming")))
A38: PMT-06 tax payment | B38: Nov-26 | C38: =DATE(2026,12,25) | D38: QRMP (quarterly) filers | F38: =IF(E38<>"",IF(E38<=C38,"Filed on time","Filed late — see Late Fee sheet"),IF(TODAY()>C38,"OVERDUE",IF(C38-TODAY()<=5,"Due in "&(C38-TODAY())&" day(s)","Upcoming")))
A39: GSTR-1 | B39: Dec-26 | C39: =DATE(2027,1,11) | D39: Monthly filers | F39: =IF(E39<>"",IF(E39<=C39,"Filed on time","Filed late — see Late Fee sheet"),IF(TODAY()>C39,"OVERDUE",IF(C39-TODAY()<=5,"Due in "&(C39-TODAY())&" day(s)","Upcoming")))
A40: GSTR-3B + tax payment | B40: Dec-26 | C40: =DATE(2027,1,20) | D40: Monthly filers | F40: =IF(E40<>"",IF(E40<=C40,"Filed on time","Filed late — see Late Fee sheet"),IF(TODAY()>C40,"OVERDUE",IF(C40-TODAY()<=5,"Due in "&(C40-TODAY())&" day(s)","Upcoming")))
A41: GSTR-1 (quarterly) | B41: Oct–Dec-26 | C41: =DATE(2027,1,13) | D41: QRMP (quarterly) filers | F41: =IF(E41<>"",IF(E41<=C41,"Filed on time","Filed late — see Late Fee sheet"),IF(TODAY()>C41,"OVERDUE",IF(C41-TODAY()<=5,"Due in "&(C41-TODAY())&" day(s)","Upcoming")))
...

Sheet Late Fee & Interest
A1: Late Fee & Interest Calculator — GSTR-1 / GSTR-3B
A2: Fill the yellow cells
A4: Return | B4: GSTR-3B
A5: Nil return? (Y/N) | B5: N
A6: Aggregate turnover in the previous FY | B6: Up to ₹1.5 crore
A7: Due date
A8: Date actually filed (or expected)
A9: Tax paid late in cash (net of ITC), ₹ | B9: 0
A11: Days late | B11: =IF(OR(B7="",B8=""),0,MAX(0,B8-B7)) | C11: • Late fee: ₹50 per day (₹25 CGST + ₹25 SGST); ₹20 per day (₹10 + ₹10) for nil returns.
A12: Late fee per day (CGST + SGST) | B12: =IF(B5="Y",20,50) | C12: • Maximum late fee per return (Notifications 19/2021 & 20/2021 — CT): nil return ₹500; turnover up to ₹1.5 crore ₹2,000; ₹1.5–5 crore ₹5,000; above ₹5 crore ₹10,000.
A13: Maximum late fee for this return | B13: =IF(B5="Y",500,IF(B6="Up to ₹1.5 crore",2000,IF(B6="Above ₹5 crore",10000,5000))) | C13: • Interest (Section 50): 18% per year on the tax paid in cash after the due date, counted from the day after the due date. GSTR-1 itself carries no interest.
A14: Late fee payable | B14: =MIN(B11*B12,B13) | C14: • Late fee is paid in cash only — it cannot be paid from ITC.
A15: of which CGST | B15: =B14/2 | C15: • Rates as of FY 2026-27. Waivers/amnesty notified by the government can change the amount — check before paying.
A16: of which SGST | B16: =B14/2
A17: Interest @ 18% p.a. on tax paid late | B17: =IF(B4="GSTR-3B",ROUND(B9*18%*B11/365,0),0)
A18: TOTAL (late fee + interest) | B18: =B14+B17
