Workbook

Sheet How to use
B1: Rent Receipt & HRA Kit
B2: Rajput Lalit & Associates · www.rajputlalitassociates.in · WhatsApp +91 93549 53603
B4: Steps
A5: 1 | B5: Fill the yellow cells in 'Details' — your name, landlord's name and PAN, address, monthly rent and payment mode.
A6: 2 | B6: Open 'Receipts' — 12 monthly receipts (April 2026 to March 2027) are ready. Print on A4.
A7: 3 | B7: Get each receipt signed by the landlord. If rent is paid in cash and is more than ₹5,000, a ₹1 revenue stamp is needed.
A8: 4 | B8: Submit the receipts to your employer with the investment declaration (Form 12BB), or keep them for your ITR.
A9: 5 | B9: Open 'HRA Check' to see how much HRA is exempt and whether the landlord's PAN is required.
B11: Good to know
B12: • Landlord's PAN is required if the rent you pay is more than ₹1,00,000 in the year.
B13: • HRA exemption is available only in the OLD tax regime.
B14: • Metro cities for the 50% limit: Delhi, Mumbai, Kolkata and Chennai.
B15: • Paying rent to parents is allowed if they own the house and show the rent in their own ITR. Rent to a spouse is generally not accepted.
B17: Cells shaded light yellow are for your entries. White cells contain formulas — please don't type over them.
B19: Licensed for use in your own business. Please do not resell or share publicly. This template is a working aid, not professional advice.

Sheet Details
A1: Details for your rent receipts
A3: Tenant name (you) | B3: Your Name
A4: Landlord name | B4: Landlord Name
A5: Landlord PAN | B5: ABCDE1234F
A6: Rented house address | B6: House No., Street, City, PIN
A7: Monthly rent (₹) | B7: 15000
A8: Payment mode | B8: Bank transfer
A9: First month of rent | B9: =DATE(2026,4,1)
A10: Metro city? (Y/N) | B10: N
A11: Annual Basic + DA (₹) | B11: 600000
A12: Annual HRA received (₹) | B12: 240000

Sheet Receipts
B1: RENT RECEIPT
B2: ="Receipt No. 01 Date: "&TEXT(EOMONTH(Details!$B$9,0),"dd-mm-yyyy")
B3: ="Received with thanks from "&Details!$B$3&" a sum of Rs. "&TEXT(Details!$B$7,"#,##0")&"/- "&"by "&LOWER(Details!$B$8)&" towards rent for the month of "&TEXT(EDATE(Details!$B$9,0),"mmmm yyyy")&" for the residential premises at "&Details!$B$6&"."
B4: ="Landlord: "&Details!$B$4&" PAN: "&IF(Details!$B$7*12>100000,Details!$B$5,"(not required)")
B5: =IF(AND(Details!$B$8="Cash",Details!$B$7>5000),"[ Affix ₹1 revenue stamp ] Signature of landlord"," Signature of landlord")
B8: RENT RECEIPT
B9: ="Receipt No. 02 Date: "&TEXT(EOMONTH(Details!$B$9,1),"dd-mm-yyyy")
B10: ="Received with thanks from "&Details!$B$3&" a sum of Rs. "&TEXT(Details!$B$7,"#,##0")&"/- "&"by "&LOWER(Details!$B$8)&" towards rent for the month of "&TEXT(EDATE(Details!$B$9,1),"mmmm yyyy")&" for the residential premises at "&Details!$B$6&"."
B11: ="Landlord: "&Details!$B$4&" PAN: "&IF(Details!$B$7*12>100000,Details!$B$5,"(not required)")
B12: =IF(AND(Details!$B$8="Cash",Details!$B$7>5000),"[ Affix ₹1 revenue stamp ] Signature of landlord"," Signature of landlord")
B15: RENT RECEIPT
B16: ="Receipt No. 03 Date: "&TEXT(EOMONTH(Details!$B$9,2),"dd-mm-yyyy")
B17: ="Received with thanks from "&Details!$B$3&" a sum of Rs. "&TEXT(Details!$B$7,"#,##0")&"/- "&"by "&LOWER(Details!$B$8)&" towards rent for the month of "&TEXT(EDATE(Details!$B$9,2),"mmmm yyyy")&" for the residential premises at "&Details!$B$6&"."
B18: ="Landlord: "&Details!$B$4&" PAN: "&IF(Details!$B$7*12>100000,Details!$B$5,"(not required)")
B19: =IF(AND(Details!$B$8="Cash",Details!$B$7>5000),"[ Affix ₹1 revenue stamp ] Signature of landlord"," Signature of landlord")
B22: RENT RECEIPT
B23: ="Receipt No. 04 Date: "&TEXT(EOMONTH(Details!$B$9,3),"dd-mm-yyyy")
B24: ="Received with thanks from "&Details!$B$3&" a sum of Rs. "&TEXT(Details!$B$7,"#,##0")&"/- "&"by "&LOWER(Details!$B$8)&" towards rent for the month of "&TEXT(EDATE(Details!$B$9,3),"mmmm yyyy")&" for the residential premises at "&Details!$B$6&"."
B25: ="Landlord: "&Details!$B$4&" PAN: "&IF(Details!$B$7*12>100000,Details!$B$5,"(not required)")
B26: =IF(AND(Details!$B$8="Cash",Details!$B$7>5000),"[ Affix ₹1 revenue stamp ] Signature of landlord"," Signature of landlord")
B29: RENT RECEIPT
B30: ="Receipt No. 05 Date: "&TEXT(EOMONTH(Details!$B$9,4),"dd-mm-yyyy")
B31: ="Received with thanks from "&Details!$B$3&" a sum of Rs. "&TEXT(Details!$B$7,"#,##0")&"/- "&"by "&LOWER(Details!$B$8)&" towards rent for the month of "&TEXT(EDATE(Details!$B$9,4),"mmmm yyyy")&" for the residential premises at "&Details!$B$6&"."
B32: ="Landlord: "&Details!$B$4&" PAN: "&IF(Details!$B$7*12>100000,Details!$B$5,"(not required)")
B33: =IF(AND(Details!$B$8="Cash",Details!$B$7>5000),"[ Affix ₹1 revenue stamp ] Signature of landlord"," Signature of landlord")
B36: RENT RECEIPT
B37: ="Receipt No. 06 Date: "&TEXT(EOMONTH(Details!$B$9,5),"dd-mm-yyyy")
B38: ="Received with thanks from "&Details!$B$3&" a sum of Rs. "&TEXT(Details!$B$7,"#,##0")&"/- "&"by "&LOWER(Details!$B$8)&" towards rent for the month of "&TEXT(EDATE(Details!$B$9,5),"mmmm yyyy")&" for the residential premises at "&Details!$B$6&"."
B39: ="Landlord: "&Details!$B$4&" PAN: "&IF(Details!$B$7*12>100000,Details!$B$5,"(not required)")
B40: =IF(AND(Details!$B$8="Cash",Details!$B$7>5000),"[ Affix ₹1 revenue stamp ] Signature of landlord"," Signature of landlord")
B43: RENT RECEIPT
B44: ="Receipt No. 07 Date: "&TEXT(EOMONTH(Details!$B$9,6),"dd-mm-yyyy")
B45: ="Received with thanks from "&Details!$B$3&" a sum of Rs. "&TEXT(Details!$B$7,"#,##0")&"/- "&"by "&LOWER(Details!$B$8)&" towards rent for the month of "&TEXT(EDATE(Details!$B$9,6),"mmmm yyyy")&" for the residential premises at "&Details!$B$6&"."
B46: ="Landlord: "&Details!$B$4&" PAN: "&IF(Details!$B$7*12>100000,Details!$B$5,"(not required)")
B47: =IF(AND(Details!$B$8="Cash",Details!$B$7>5000),"[ Affix ₹1 revenue stamp ] Signature of landlord"," Signature of landlord")
B50: RENT RECEIPT
B51: ="Receipt No. 08 Date: "&TEXT(EOMONTH(Details!$B$9,7),"dd-mm-yyyy")
B52: ="Received with thanks from "&Details!$B$3&" a sum of Rs. "&TEXT(Details!$B$7,"#,##0")&"/- "&"by "&LOWER(Details!$B$8)&" towards rent for the month of "&TEXT(EDATE(Details!$B$9,7),"mmmm yyyy")&" for the residential premises at "&Details!$B$6&"."
B53: ="Landlord: "&Details!$B$4&" PAN: "&IF(Details!$B$7*12>100000,Details!$B$5,"(not required)")
B54: =IF(AND(Details!$B$8="Cash",Details!$B$7>5000),"[ Affix ₹1 revenue stamp ] Signature of landlord"," Signature of landlord")
...

Sheet HRA Check
A1: HRA exemption check (old regime)
A2: Exemption = least of the three amounts below
A4: Annual rent paid | B4: =Details!B7*12
A5: 1. Actual HRA received | B5: =Details!B12
A6: 2. Rent paid minus 10% of Basic+DA | B6: =MAX(0,B4-10%*Details!B11)
A7: 3. 50% (metro) / 40% (non-metro) of Basic+DA | B7: =IF(Details!B10="Y",50%,40%)*Details!B11
A8: HRA EXEMPT (least of 1, 2, 3) | B8: =MIN(B5,B6,B7)
A9: HRA taxable | B9: =B5-B8
A10: Landlord PAN needed? | B10: =IF(B4>100000,"Yes — rent is above ₹1,00,000 a year","No")
