Workbook

Sheet How to use
B1: Small Business Bookkeeping Kit
B2: Rajput Lalit & Associates · www.rajputlalitassociates.in · WhatsApp +91 93549 53603
B4: Steps
A5: 1 | B5: In 'Settings' enter your business name and the opening cash and bank balance on 1 April 2026.
A6: 2 | B6: Record every cash receipt/payment in 'Cash Book' and every bank entry in 'Bank Book' — the balance runs automatically.
A7: 3 | B7: Record each sale bill in 'Sales Register' and each purchase bill in 'Purchase Register'.
A8: 4 | B8: Record expenses (rent, salary, electricity...) in 'Expenses' and choose the head from the drop-down.
A9: 5 | B9: In the Purchase Register mark whether the bill appears in your GSTR-2B — 'ITC Tracker' then shows the month-wise gap.
A10: 6 | B10: Open 'P&L Summary' any time to see month-wise sales, purchases, expenses and profit.
A11: 7 | B11: Share this file with your CA at year end — everything is already classified.
B13: Good to know
B14: • If a sale/purchase is paid in cash or bank, also enter it in the Cash/Bank Book so balances stay correct.
B15: • Profit shown is an estimate (no stock valuation or depreciation) — your CA will finalise it.
B16: • Cash expenses above ₹10,000 paid to one person in a day are not allowed as a deduction (Income Tax rule) — pay by bank.
B18: Cells shaded light yellow are for your entries. White cells contain formulas — please don't type over them.
B20: Licensed for use in your own business. Please do not resell or share publicly. This template is a working aid, not professional advice.

Sheet Settings
A1: Settings
A3: Business name | B3: Your Business Name
A4: Financial year | B4: FY 2026-27
A5: Opening cash balance (1 Apr 2026) | B5: 0
A6: Opening bank balance (1 Apr 2026) | B6: 0

Sheet Heads
A1: Expense heads (edit if you like)
A2: Rent
A3: Salary & Wages
A4: Electricity
A5: Telephone & Internet
A6: Travel & Conveyance
A7: Office Expenses
A8: Printing & Stationery
A9: Repairs & Maintenance
A10: Professional Fees
A11: Bank Charges
A12: Advertising
... A16: Miscellaneous

Sheet Cash Book
A1: Cash Book
A2: Balance is calculated automatically
A4: Date | B4: Particulars | C4: Voucher / Ref | D4: Receipt (In) | E4: Payment (Out) | F4: Balance
B5: Opening balance | F5: =Settings!B5
F6: =IF(AND(D6="",E6=""),"",Settings!B5+SUM(D$6:D6)-SUM(E$6:E6))
F7: =IF(AND(D7="",E7=""),"",Settings!B5+SUM(D$6:D7)-SUM(E$6:E7))
F8: =IF(AND(D8="",E8=""),"",Settings!B5+SUM(D$6:D8)-SUM(E$6:E8))
F9: =IF(AND(D9="",E9=""),"",Settings!B5+SUM(D$6:D9)-SUM(E$6:E9))
F10: =IF(AND(D10="",E10=""),"",Settings!B5+SUM(D$6:D10)-SUM(E$6:E10))
F11: =IF(AND(D11="",E11=""),"",Settings!B5+SUM(D$6:D11)-SUM(E$6:E11))
F12: =IF(AND(D12="",E12=""),"",Settings!B5+SUM(D$6:D12)-SUM(E$6:E12))
F13: =IF(AND(D13="",E13=""),"",Settings!B5+SUM(D$6:D13)-SUM(E$6:E13))
F14: =IF(AND(D14="",E14=""),"",Settings!B5+SUM(D$6:D14)-SUM(E$6:E14))
F15: =IF(AND(D15="",E15=""),"",Settings!B5+SUM(D$6:D15)-SUM(E$6:E15))
F16: =IF(AND(D16="",E16=""),"",Settings!B5+SUM(D$6:D16)-SUM(E$6:E16))
F17: =IF(AND(D17="",E17=""),"",Settings!B5+SUM(D$6:D17)-SUM(E$6:E17))
F18: =IF(AND(D18="",E18=""),"",Settings!B5+SUM(D$6:D18)-SUM(E$6:E18))
F19: =IF(AND(D19="",E19=""),"",Settings!B5+SUM(D$6:D19)-SUM(E$6:E19))
F20: =IF(AND(D20="",E20=""),"",Settings!B5+SUM(D$6:D20)-SUM(E$6:E20))
F21: =IF(AND(D21="",E21=""),"",Settings!B5+SUM(D$6:D21)-SUM(E$6:E21))
F22: =IF(AND(D22="",E22=""),"",Settings!B5+SUM(D$6:D22)-SUM(E$6:E22))
F23: =IF(AND(D23="",E23=""),"",Settings!B5+SUM(D$6:D23)-SUM(E$6:E23))
F24: =IF(AND(D24="",E24=""),"",Settings!B5+SUM(D$6:D24)-SUM(E$6:E24))
F25: =IF(AND(D25="",E25=""),"",Settings!B5+SUM(D$6:D25)-SUM(E$6:E25))
F26: =IF(AND(D26="",E26=""),"",Settings!B5+SUM(D$6:D26)-SUM(E$6:E26))
F27: =IF(AND(D27="",E27=""),"",Settings!B5+SUM(D$6:D27)-SUM(E$6:E27))
F28: =IF(AND(D28="",E28=""),"",Settings!B5+SUM(D$6:D28)-SUM(E$6:E28))
F29: =IF(AND(D29="",E29=""),"",Settings!B5+SUM(D$6:D29)-SUM(E$6:E29))
F30: =IF(AND(D30="",E30=""),"",Settings!B5+SUM(D$6:D30)-SUM(E$6:E30))
F31: =IF(AND(D31="",E31=""),"",Settings!B5+SUM(D$6:D31)-SUM(E$6:E31))
F32: =IF(AND(D32="",E32=""),"",Settings!B5+SUM(D$6:D32)-SUM(E$6:E32))
F33: =IF(AND(D33="",E33=""),"",Settings!B5+SUM(D$6:D33)-SUM(E$6:E33))
F34: =IF(AND(D34="",E34=""),"",Settings!B5+SUM(D$6:D34)-SUM(E$6:E34))
F35: =IF(AND(D35="",E35=""),"",Settings!B5+SUM(D$6:D35)-SUM(E$6:E35))
F36: =IF(AND(D36="",E36=""),"",Settings!B5+SUM(D$6:D36)-SUM(E$6:E36))
F37: =IF(AND(D37="",E37=""),"",Settings!B5+SUM(D$6:D37)-SUM(E$6:E37))
F38: =IF(AND(D38="",E38=""),"",Settings!B5+SUM(D$6:D38)-SUM(E$6:E38))
F39: =IF(AND(D39="",E39=""),"",Settings!B5+SUM(D$6:D39)-SUM(E$6:E39))
F40: =IF(AND(D40="",E40=""),"",Settings!B5+SUM(D$6:D40)-SUM(E$6:E40))
F41: =IF(AND(D41="",E41=""),"",Settings!B5+SUM(D$6:D41)-SUM(E$6:E41))
...

Sheet Bank Book
A1: Bank Book
A2: Balance is calculated automatically
A4: Date | B4: Particulars | C4: Voucher / Ref | D4: Cheque / UTR | E4: Receipt (In) | F4: Payment (Out) | G4: Balance
B5: Opening balance | G5: =Settings!B6
G6: =IF(AND(E6="",F6=""),"",Settings!B6+SUM(E$6:E6)-SUM(F$6:F6))
G7: =IF(AND(E7="",F7=""),"",Settings!B6+SUM(E$6:E7)-SUM(F$6:F7))
G8: =IF(AND(E8="",F8=""),"",Settings!B6+SUM(E$6:E8)-SUM(F$6:F8))
G9: =IF(AND(E9="",F9=""),"",Settings!B6+SUM(E$6:E9)-SUM(F$6:F9))
G10: =IF(AND(E10="",F10=""),"",Settings!B6+SUM(E$6:E10)-SUM(F$6:F10))
G11: =IF(AND(E11="",F11=""),"",Settings!B6+SUM(E$6:E11)-SUM(F$6:F11))
G12: =IF(AND(E12="",F12=""),"",Settings!B6+SUM(E$6:E12)-SUM(F$6:F12))
G13: =IF(AND(E13="",F13=""),"",Settings!B6+SUM(E$6:E13)-SUM(F$6:F13))
G14: =IF(AND(E14="",F14=""),"",Settings!B6+SUM(E$6:E14)-SUM(F$6:F14))
G15: =IF(AND(E15="",F15=""),"",Settings!B6+SUM(E$6:E15)-SUM(F$6:F15))
G16: =IF(AND(E16="",F16=""),"",Settings!B6+SUM(E$6:E16)-SUM(F$6:F16))
G17: =IF(AND(E17="",F17=""),"",Settings!B6+SUM(E$6:E17)-SUM(F$6:F17))
G18: =IF(AND(E18="",F18=""),"",Settings!B6+SUM(E$6:E18)-SUM(F$6:F18))
G19: =IF(AND(E19="",F19=""),"",Settings!B6+SUM(E$6:E19)-SUM(F$6:F19))
G20: =IF(AND(E20="",F20=""),"",Settings!B6+SUM(E$6:E20)-SUM(F$6:F20))
G21: =IF(AND(E21="",F21=""),"",Settings!B6+SUM(E$6:E21)-SUM(F$6:F21))
G22: =IF(AND(E22="",F22=""),"",Settings!B6+SUM(E$6:E22)-SUM(F$6:F22))
G23: =IF(AND(E23="",F23=""),"",Settings!B6+SUM(E$6:E23)-SUM(F$6:F23))
G24: =IF(AND(E24="",F24=""),"",Settings!B6+SUM(E$6:E24)-SUM(F$6:F24))
G25: =IF(AND(E25="",F25=""),"",Settings!B6+SUM(E$6:E25)-SUM(F$6:F25))
G26: =IF(AND(E26="",F26=""),"",Settings!B6+SUM(E$6:E26)-SUM(F$6:F26))
G27: =IF(AND(E27="",F27=""),"",Settings!B6+SUM(E$6:E27)-SUM(F$6:F27))
G28: =IF(AND(E28="",F28=""),"",Settings!B6+SUM(E$6:E28)-SUM(F$6:F28))
G29: =IF(AND(E29="",F29=""),"",Settings!B6+SUM(E$6:E29)-SUM(F$6:F29))
G30: =IF(AND(E30="",F30=""),"",Settings!B6+SUM(E$6:E30)-SUM(F$6:F30))
G31: =IF(AND(E31="",F31=""),"",Settings!B6+SUM(E$6:E31)-SUM(F$6:F31))
G32: =IF(AND(E32="",F32=""),"",Settings!B6+SUM(E$6:E32)-SUM(F$6:F32))
G33: =IF(AND(E33="",F33=""),"",Settings!B6+SUM(E$6:E33)-SUM(F$6:F33))
G34: =IF(AND(E34="",F34=""),"",Settings!B6+SUM(E$6:E34)-SUM(F$6:F34))
G35: =IF(AND(E35="",F35=""),"",Settings!B6+SUM(E$6:E35)-SUM(F$6:F35))
G36: =IF(AND(E36="",F36=""),"",Settings!B6+SUM(E$6:E36)-SUM(F$6:F36))
G37: =IF(AND(E37="",F37=""),"",Settings!B6+SUM(E$6:E37)-SUM(F$6:F37))
G38: =IF(AND(E38="",F38=""),"",Settings!B6+SUM(E$6:E38)-SUM(F$6:F38))
G39: =IF(AND(E39="",F39=""),"",Settings!B6+SUM(E$6:E39)-SUM(F$6:F39))
G40: =IF(AND(E40="",F40=""),"",Settings!B6+SUM(E$6:E40)-SUM(F$6:F40))
G41: =IF(AND(E41="",F41=""),"",Settings!B6+SUM(E$6:E41)-SUM(F$6:F41))
...

Sheet Sales Register
A1: Sales Register
A4: Date | B4: Invoice No. | C4: Customer | D4: GSTIN | E4: Taxable value | F4: CGST | G4: SGST | H4: IGST | I4: Total
I5: =IF(E5="","",E5+F5+G5+H5)
I6: =IF(E6="","",E6+F6+G6+H6)
I7: =IF(E7="","",E7+F7+G7+H7)
I8: =IF(E8="","",E8+F8+G8+H8)
I9: =IF(E9="","",E9+F9+G9+H9)
I10: =IF(E10="","",E10+F10+G10+H10)
I11: =IF(E11="","",E11+F11+G11+H11)
I12: =IF(E12="","",E12+F12+G12+H12)
I13: =IF(E13="","",E13+F13+G13+H13)
I14: =IF(E14="","",E14+F14+G14+H14)
I15: =IF(E15="","",E15+F15+G15+H15)
I16: =IF(E16="","",E16+F16+G16+H16)
... I1004: =IF(E1004="","",E1004+F1004+G1004+H1004)

Sheet Purchase Register
A1: Purchase Register
A2: Mark ITC eligibility and whether the bill shows in your GSTR-2B
A4: Date | B4: Bill No. | C4: Supplier | D4: Supplier GSTIN | E4: Taxable value | F4: CGST | G4: SGST | H4: IGST | I4: Total | J4: ITC eligible? (Y/N) | K4: In GSTR-2B? (Y/N)
I5: =IF(E5="","",E5+F5+G5+H5)
I6: =IF(E6="","",E6+F6+G6+H6)
I7: =IF(E7="","",E7+F7+G7+H7)
I8: =IF(E8="","",E8+F8+G8+H8)
I9: =IF(E9="","",E9+F9+G9+H9)
I10: =IF(E10="","",E10+F10+G10+H10)
I11: =IF(E11="","",E11+F11+G11+H11)
I12: =IF(E12="","",E12+F12+G12+H12)
I13: =IF(E13="","",E13+F13+G13+H13)
I14: =IF(E14="","",E14+F14+G14+H14)
I15: =IF(E15="","",E15+F15+G15+H15)
I16: =IF(E16="","",E16+F16+G16+H16)
... I1004: =IF(E1004="","",E1004+F1004+G1004+H1004)

Sheet Expenses
A1: Expenses
A2: Pick the head from the drop-down
A4: Date | B4: Expense head | C4: Paid to | D4: Amount | E4: Mode (Cash/Bank/UPI) | F4: Remarks

Sheet ITC Tracker
A1: ITC Tracker — books vs GSTR-2B
A2: Difference = ITC you booked that is not yet in GSTR-2B (follow up with the supplier)
A4: Month | B4: Eligible ITC in books | C4: ITC reflected in GSTR-2B | D4: Difference | E4: Status
A5: =DATE(2026,4,1) | B5: =SUMPRODUCT(('Purchase Register'!$A$5:$A$1004>=A5)*('Purchase Register'!$A$5:$A$1004<=EOMONTH(A5,0))*('Purchase Register'!$J$5:$J$1004="Y")*('Purchase Register'!$F$5:$F$1004+'Purchase Register'!$G$5:$G$1004+'Purchase Register'!$H$5:$H$1004)) | C5: =SUMPRODUCT(('Purchase Register'!$A$5:$A$1004>=A5)*('Purchase Register'!$A$5:$A$1004<=EOMONTH(A5,0))*('Purchase Register'!$J$5:$J$1004="Y")*('Purchase Register'!$K$5:$K$1004="Y")*('Purchase Register'!$F$5:$F$1004+'Purchase Register'!$G$5:$G$1004+'Purchase Register'!$H$5:$H$1004)) | D5: =B5-C5 | E5: =IF(B5=0,"",IF(D5=0,"All matched","Follow up with suppliers"))
A6: =DATE(2026,5,1) | B6: =SUMPRODUCT(('Purchase Register'!$A$5:$A$1004>=A6)*('Purchase Register'!$A$5:$A$1004<=EOMONTH(A6,0))*('Purchase Register'!$J$5:$J$1004="Y")*('Purchase Register'!$F$5:$F$1004+'Purchase Register'!$G$5:$G$1004+'Purchase Register'!$H$5:$H$1004)) | C6: =SUMPRODUCT(('Purchase Register'!$A$5:$A$1004>=A6)*('Purchase Register'!$A$5:$A$1004<=EOMONTH(A6,0))*('Purchase Register'!$J$5:$J$1004="Y")*('Purchase Register'!$K$5:$K$1004="Y")*('Purchase Register'!$F$5:$F$1004+'Purchase Register'!$G$5:$G$1004+'Purchase Register'!$H$5:$H$1004)) | D6: =B6-C6 | E6: =IF(B6=0,"",IF(D6=0,"All matched","Follow up with suppliers"))
A7: =DATE(2026,6,1) | B7: =SUMPRODUCT(('Purchase Register'!$A$5:$A$1004>=A7)*('Purchase Register'!$A$5:$A$1004<=EOMONTH(A7,0))*('Purchase Register'!$J$5:$J$1004="Y")*('Purchase Register'!$F$5:$F$1004+'Purchase Register'!$G$5:$G$1004+'Purchase Register'!$H$5:$H$1004)) | C7: =SUMPRODUCT(('Purchase Register'!$A$5:$A$1004>=A7)*('Purchase Register'!$A$5:$A$1004<=EOMONTH(A7,0))*('Purchase Register'!$J$5:$J$1004="Y")*('Purchase Register'!$K$5:$K$1004="Y")*('Purchase Register'!$F$5:$F$1004+'Purchase Register'!$G$5:$G$1004+'Purchase Register'!$H$5:$H$1004)) | D7: =B7-C7 | E7: =IF(B7=0,"",IF(D7=0,"All matched","Follow up with suppliers"))
A8: =DATE(2026,7,1) | B8: =SUMPRODUCT(('Purchase Register'!$A$5:$A$1004>=A8)*('Purchase Register'!$A$5:$A$1004<=EOMONTH(A8,0))*('Purchase Register'!$J$5:$J$1004="Y")*('Purchase Register'!$F$5:$F$1004+'Purchase Register'!$G$5:$G$1004+'Purchase Register'!$H$5:$H$1004)) | C8: =SUMPRODUCT(('Purchase Register'!$A$5:$A$1004>=A8)*('Purchase Register'!$A$5:$A$1004<=EOMONTH(A8,0))*('Purchase Register'!$J$5:$J$1004="Y")*('Purchase Register'!$K$5:$K$1004="Y")*('Purchase Register'!$F$5:$F$1004+'Purchase Register'!$G$5:$G$1004+'Purchase Register'!$H$5:$H$1004)) | D8: =B8-C8 | E8: =IF(B8=0,"",IF(D8=0,"All matched","Follow up with suppliers"))
A9: =DATE(2026,8,1) | B9: =SUMPRODUCT(('Purchase Register'!$A$5:$A$1004>=A9)*('Purchase Register'!$A$5:$A$1004<=EOMONTH(A9,0))*('Purchase Register'!$J$5:$J$1004="Y")*('Purchase Register'!$F$5:$F$1004+'Purchase Register'!$G$5:$G$1004+'Purchase Register'!$H$5:$H$1004)) | C9: =SUMPRODUCT(('Purchase Register'!$A$5:$A$1004>=A9)*('Purchase Register'!$A$5:$A$1004<=EOMONTH(A9,0))*('Purchase Register'!$J$5:$J$1004="Y")*('Purchase Register'!$K$5:$K$1004="Y")*('Purchase Register'!$F$5:$F$1004+'Purchase Register'!$G$5:$G$1004+'Purchase Register'!$H$5:$H$1004)) | D9: =B9-C9 | E9: =IF(B9=0,"",IF(D9=0,"All matched","Follow up with suppliers"))
A10: =DATE(2026,9,1) | B10: =SUMPRODUCT(('Purchase Register'!$A$5:$A$1004>=A10)*('Purchase Register'!$A$5:$A$1004<=EOMONTH(A10,0))*('Purchase Register'!$J$5:$J$1004="Y")*('Purchase Register'!$F$5:$F$1004+'Purchase Register'!$G$5:$G$1004+'Purchase Register'!$H$5:$H$1004)) | C10: =SUMPRODUCT(('Purchase Register'!$A$5:$A$1004>=A10)*('Purchase Register'!$A$5:$A$1004<=EOMONTH(A10,0))*('Purchase Register'!$J$5:$J$1004="Y")*('Purchase Register'!$K$5:$K$1004="Y")*('Purchase Register'!$F$5:$F$1004+'Purchase Register'!$G$5:$G$1004+'Purchase Register'!$H$5:$H$1004)) | D10: =B10-C10 | E10: =IF(B10=0,"",IF(D10=0,"All matched","Follow up with suppliers"))
A11: =DATE(2026,10,1) | B11: =SUMPRODUCT(('Purchase Register'!$A$5:$A$1004>=A11)*('Purchase Register'!$A$5:$A$1004<=EOMONTH(A11,0))*('Purchase Register'!$J$5:$J$1004="Y")*('Purchase Register'!$F$5:$F$1004+'Purchase Register'!$G$5:$G$1004+'Purchase Register'!$H$5:$H$1004)) | C11: =SUMPRODUCT(('Purchase Register'!$A$5:$A$1004>=A11)*('Purchase Register'!$A$5:$A$1004<=EOMONTH(A11,0))*('Purchase Register'!$J$5:$J$1004="Y")*('Purchase Register'!$K$5:$K$1004="Y")*('Purchase Register'!$F$5:$F$1004+'Purchase Register'!$G$5:$G$1004+'Purchase Register'!$H$5:$H$1004)) | D11: =B11-C11 | E11: =IF(B11=0,"",IF(D11=0,"All matched","Follow up with suppliers"))
A12: =DATE(2026,11,1) | B12: =SUMPRODUCT(('Purchase Register'!$A$5:$A$1004>=A12)*('Purchase Register'!$A$5:$A$1004<=EOMONTH(A12,0))*('Purchase Register'!$J$5:$J$1004="Y")*('Purchase Register'!$F$5:$F$1004+'Purchase Register'!$G$5:$G$1004+'Purchase Register'!$H$5:$H$1004)) | C12: =SUMPRODUCT(('Purchase Register'!$A$5:$A$1004>=A12)*('Purchase Register'!$A$5:$A$1004<=EOMONTH(A12,0))*('Purchase Register'!$J$5:$J$1004="Y")*('Purchase Register'!$K$5:$K$1004="Y")*('Purchase Register'!$F$5:$F$1004+'Purchase Register'!$G$5:$G$1004+'Purchase Register'!$H$5:$H$1004)) | D12: =B12-C12 | E12: =IF(B12=0,"",IF(D12=0,"All matched","Follow up with suppliers"))
A13: =DATE(2026,12,1) | B13: =SUMPRODUCT(('Purchase Register'!$A$5:$A$1004>=A13)*('Purchase Register'!$A$5:$A$1004<=EOMONTH(A13,0))*('Purchase Register'!$J$5:$J$1004="Y")*('Purchase Register'!$F$5:$F$1004+'Purchase Register'!$G$5:$G$1004+'Purchase Register'!$H$5:$H$1004)) | C13: =SUMPRODUCT(('Purchase Register'!$A$5:$A$1004>=A13)*('Purchase Register'!$A$5:$A$1004<=EOMONTH(A13,0))*('Purchase Register'!$J$5:$J$1004="Y")*('Purchase Register'!$K$5:$K$1004="Y")*('Purchase Register'!$F$5:$F$1004+'Purchase Register'!$G$5:$G$1004+'Purchase Register'!$H$5:$H$1004)) | D13: =B13-C13 | E13: =IF(B13=0,"",IF(D13=0,"All matched","Follow up with suppliers"))
A14: =DATE(2027,1,1) | B14: =SUMPRODUCT(('Purchase Register'!$A$5:$A$1004>=A14)*('Purchase Register'!$A$5:$A$1004<=EOMONTH(A14,0))*('Purchase Register'!$J$5:$J$1004="Y")*('Purchase Register'!$F$5:$F$1004+'Purchase Register'!$G$5:$G$1004+'Purchase Register'!$H$5:$H$1004)) | C14: =SUMPRODUCT(('Purchase Register'!$A$5:$A$1004>=A14)*('Purchase Register'!$A$5:$A$1004<=EOMONTH(A14,0))*('Purchase Register'!$J$5:$J$1004="Y")*('Purchase Register'!$K$5:$K$1004="Y")*('Purchase Register'!$F$5:$F$1004+'Purchase Register'!$G$5:$G$1004+'Purchase Register'!$H$5:$H$1004)) | D14: =B14-C14 | E14: =IF(B14=0,"",IF(D14=0,"All matched","Follow up with suppliers"))
A15: =DATE(2027,2,1) | B15: =SUMPRODUCT(('Purchase Register'!$A$5:$A$1004>=A15)*('Purchase Register'!$A$5:$A$1004<=EOMONTH(A15,0))*('Purchase Register'!$J$5:$J$1004="Y")*('Purchase Register'!$F$5:$F$1004+'Purchase Register'!$G$5:$G$1004+'Purchase Register'!$H$5:$H$1004)) | C15: =SUMPRODUCT(('Purchase Register'!$A$5:$A$1004>=A15)*('Purchase Register'!$A$5:$A$1004<=EOMONTH(A15,0))*('Purchase Register'!$J$5:$J$1004="Y")*('Purchase Register'!$K$5:$K$1004="Y")*('Purchase Register'!$F$5:$F$1004+'Purchase Register'!$G$5:$G$1004+'Purchase Register'!$H$5:$H$1004)) | D15: =B15-C15 | E15: =IF(B15=0,"",IF(D15=0,"All matched","Follow up with suppliers"))
A16: =DATE(2027,3,1) | B16: =SUMPRODUCT(('Purchase Register'!$A$5:$A$1004>=A16)*('Purchase Register'!$A$5:$A$1004<=EOMONTH(A16,0))*('Purchase Register'!$J$5:$J$1004="Y")*('Purchase Register'!$F$5:$F$1004+'Purchase Register'!$G$5:$G$1004+'Purchase Register'!$H$5:$H$1004)) | C16: =SUMPRODUCT(('Purchase Register'!$A$5:$A$1004>=A16)*('Purchase Register'!$A$5:$A$1004<=EOMONTH(A16,0))*('Purchase Register'!$J$5:$J$1004="Y")*('Purchase Register'!$K$5:$K$1004="Y")*('Purchase Register'!$F$5:$F$1004+'Purchase Register'!$G$5:$G$1004+'Purchase Register'!$H$5:$H$1004)) | D16: =B16-C16 | E16: =IF(B16=0,"",IF(D16=0,"All matched","Follow up with suppliers"))

Sheet P&L Summary
A1: Profit & Loss Summary — FY 2026-27
A2: Estimated, from your registers (taxable values, excluding GST)
A4: Particulars | B4: =DATE(2026,4,1) | C4: =DATE(2026,5,1) | D4: =DATE(2026,6,1) | E4: =DATE(2026,7,1) | F4: =DATE(2026,8,1) | G4: =DATE(2026,9,1) | H4: =DATE(2026,10,1) | I4: =DATE(2026,11,1) | J4: =DATE(2026,12,1) | K4: =DATE(2027,1,1) | L4: =DATE(2027,2,1) | M4: =DATE(2027,3,1) | N4: Total
A5: Sales | B5: =SUMIFS('Sales Register'!$E$5:$E$1004,'Sales Register'!$A$5:$A$1004,">="&B$4,'Sales Register'!$A$5:$A$1004,"<="&EOMONTH(B$4,0)) | C5: =SUMIFS('Sales Register'!$E$5:$E$1004,'Sales Register'!$A$5:$A$1004,">="&C$4,'Sales Register'!$A$5:$A$1004,"<="&EOMONTH(C$4,0)) | D5: =SUMIFS('Sales Register'!$E$5:$E$1004,'Sales Register'!$A$5:$A$1004,">="&D$4,'Sales Register'!$A$5:$A$1004,"<="&EOMONTH(D$4,0)) | E5: =SUMIFS('Sales Register'!$E$5:$E$1004,'Sales Register'!$A$5:$A$1004,">="&E$4,'Sales Register'!$A$5:$A$1004,"<="&EOMONTH(E$4,0)) | F5: =SUMIFS('Sales Register'!$E$5:$E$1004,'Sales Register'!$A$5:$A$1004,">="&F$4,'Sales Register'!$A$5:$A$1004,"<="&EOMONTH(F$4,0)) | G5: =SUMIFS('Sales Register'!$E$5:$E$1004,'Sales Register'!$A$5:$A$1004,">="&G$4,'Sales Register'!$A$5:$A$1004,"<="&EOMONTH(G$4,0)) | H5: =SUMIFS('Sales Register'!$E$5:$E$1004,'Sales Register'!$A$5:$A$1004,">="&H$4,'Sales Register'!$A$5:$A$1004,"<="&EOMONTH(H$4,0)) | I5: =SUMIFS('Sales Register'!$E$5:$E$1004,'Sales Register'!$A$5:$A$1004,">="&I$4,'Sales Register'!$A$5:$A$1004,"<="&EOMONTH(I$4,0)) | ... M5: =SUMIFS('Sales Register'!$E$5:$E$1004,'Sales Register'!$A$5:$A$1004,">="&M$4,'Sales Register'!$A$5:$A$1004,"<="&EOMONTH(M$4,0)) | N5: =SUM(B5:M5)
A6: Purchases | B6: =SUMIFS('Purchase Register'!$E$5:$E$1004,'Purchase Register'!$A$5:$A$1004,">="&B$4,'Purchase Register'!$A$5:$A$1004,"<="&EOMONTH(B$4,0)) | C6: =SUMIFS('Purchase Register'!$E$5:$E$1004,'Purchase Register'!$A$5:$A$1004,">="&C$4,'Purchase Register'!$A$5:$A$1004,"<="&EOMONTH(C$4,0)) | D6: =SUMIFS('Purchase Register'!$E$5:$E$1004,'Purchase Register'!$A$5:$A$1004,">="&D$4,'Purchase Register'!$A$5:$A$1004,"<="&EOMONTH(D$4,0)) | E6: =SUMIFS('Purchase Register'!$E$5:$E$1004,'Purchase Register'!$A$5:$A$1004,">="&E$4,'Purchase Register'!$A$5:$A$1004,"<="&EOMONTH(E$4,0)) | F6: =SUMIFS('Purchase Register'!$E$5:$E$1004,'Purchase Register'!$A$5:$A$1004,">="&F$4,'Purchase Register'!$A$5:$A$1004,"<="&EOMONTH(F$4,0)) | G6: =SUMIFS('Purchase Register'!$E$5:$E$1004,'Purchase Register'!$A$5:$A$1004,">="&G$4,'Purchase Register'!$A$5:$A$1004,"<="&EOMONTH(G$4,0)) | H6: =SUMIFS('Purchase Register'!$E$5:$E$1004,'Purchase Register'!$A$5:$A$1004,">="&H$4,'Purchase Register'!$A$5:$A$1004,"<="&EOMONTH(H$4,0)) | I6: =SUMIFS('Purchase Register'!$E$5:$E$1004,'Purchase Register'!$A$5:$A$1004,">="&I$4,'Purchase Register'!$A$5:$A$1004,"<="&EOMONTH(I$4,0)) | ... M6: =SUMIFS('Purchase Register'!$E$5:$E$1004,'Purchase Register'!$A$5:$A$1004,">="&M$4,'Purchase Register'!$A$5:$A$1004,"<="&EOMONTH(M$4,0)) | N6: =SUM(B6:M6)
A7: Gross profit | B7: =B5-B6 | C7: =C5-C6 | D7: =D5-D6 | E7: =E5-E6 | F7: =F5-F6 | G7: =G5-G6 | H7: =H5-H6 | I7: =I5-I6 | ... M7: =M5-M6 | N7: =SUM(B7:M7)
A9: =Heads!A2 | B9: =SUMIFS('Expenses'!$D$5:$D$1004,'Expenses'!$A$5:$A$1004,">="&B$4,'Expenses'!$A$5:$A$1004,"<="&EOMONTH(B$4,0),'Expenses'!$B$5:$B$1004,$A9) | C9: =SUMIFS('Expenses'!$D$5:$D$1004,'Expenses'!$A$5:$A$1004,">="&C$4,'Expenses'!$A$5:$A$1004,"<="&EOMONTH(C$4,0),'Expenses'!$B$5:$B$1004,$A9) | D9: =SUMIFS('Expenses'!$D$5:$D$1004,'Expenses'!$A$5:$A$1004,">="&D$4,'Expenses'!$A$5:$A$1004,"<="&EOMONTH(D$4,0),'Expenses'!$B$5:$B$1004,$A9) | E9: =SUMIFS('Expenses'!$D$5:$D$1004,'Expenses'!$A$5:$A$1004,">="&E$4,'Expenses'!$A$5:$A$1004,"<="&EOMONTH(E$4,0),'Expenses'!$B$5:$B$1004,$A9) | F9: =SUMIFS('Expenses'!$D$5:$D$1004,'Expenses'!$A$5:$A$1004,">="&F$4,'Expenses'!$A$5:$A$1004,"<="&EOMONTH(F$4,0),'Expenses'!$B$5:$B$1004,$A9) | G9: =SUMIFS('Expenses'!$D$5:$D$1004,'Expenses'!$A$5:$A$1004,">="&G$4,'Expenses'!$A$5:$A$1004,"<="&EOMONTH(G$4,0),'Expenses'!$B$5:$B$1004,$A9) | H9: =SUMIFS('Expenses'!$D$5:$D$1004,'Expenses'!$A$5:$A$1004,">="&H$4,'Expenses'!$A$5:$A$1004,"<="&EOMONTH(H$4,0),'Expenses'!$B$5:$B$1004,$A9) | I9: =SUMIFS('Expenses'!$D$5:$D$1004,'Expenses'!$A$5:$A$1004,">="&I$4,'Expenses'!$A$5:$A$1004,"<="&EOMONTH(I$4,0),'Expenses'!$B$5:$B$1004,$A9) | ... M9: =SUMIFS('Expenses'!$D$5:$D$1004,'Expenses'!$A$5:$A$1004,">="&M$4,'Expenses'!$A$5:$A$1004,"<="&EOMONTH(M$4,0),'Expenses'!$B$5:$B$1004,$A9) | N9: =SUM(B9:M9)
A10: =Heads!A3 | B10: =SUMIFS('Expenses'!$D$5:$D$1004,'Expenses'!$A$5:$A$1004,">="&B$4,'Expenses'!$A$5:$A$1004,"<="&EOMONTH(B$4,0),'Expenses'!$B$5:$B$1004,$A10) | C10: =SUMIFS('Expenses'!$D$5:$D$1004,'Expenses'!$A$5:$A$1004,">="&C$4,'Expenses'!$A$5:$A$1004,"<="&EOMONTH(C$4,0),'Expenses'!$B$5:$B$1004,$A10) | D10: =SUMIFS('Expenses'!$D$5:$D$1004,'Expenses'!$A$5:$A$1004,">="&D$4,'Expenses'!$A$5:$A$1004,"<="&EOMONTH(D$4,0),'Expenses'!$B$5:$B$1004,$A10) | E10: =SUMIFS('Expenses'!$D$5:$D$1004,'Expenses'!$A$5:$A$1004,">="&E$4,'Expenses'!$A$5:$A$1004,"<="&EOMONTH(E$4,0),'Expenses'!$B$5:$B$1004,$A10) | F10: =SUMIFS('Expenses'!$D$5:$D$1004,'Expenses'!$A$5:$A$1004,">="&F$4,'Expenses'!$A$5:$A$1004,"<="&EOMONTH(F$4,0),'Expenses'!$B$5:$B$1004,$A10) | G10: =SUMIFS('Expenses'!$D$5:$D$1004,'Expenses'!$A$5:$A$1004,">="&G$4,'Expenses'!$A$5:$A$1004,"<="&EOMONTH(G$4,0),'Expenses'!$B$5:$B$1004,$A10) | H10: =SUMIFS('Expenses'!$D$5:$D$1004,'Expenses'!$A$5:$A$1004,">="&H$4,'Expenses'!$A$5:$A$1004,"<="&EOMONTH(H$4,0),'Expenses'!$B$5:$B$1004,$A10) | I10: =SUMIFS('Expenses'!$D$5:$D$1004,'Expenses'!$A$5:$A$1004,">="&I$4,'Expenses'!$A$5:$A$1004,"<="&EOMONTH(I$4,0),'Expenses'!$B$5:$B$1004,$A10) | ... M10: =SUMIFS('Expenses'!$D$5:$D$1004,'Expenses'!$A$5:$A$1004,">="&M$4,'Expenses'!$A$5:$A$1004,"<="&EOMONTH(M$4,0),'Expenses'!$B$5:$B$1004,$A10) | N10: =SUM(B10:M10)
A11: =Heads!A4 | B11: =SUMIFS('Expenses'!$D$5:$D$1004,'Expenses'!$A$5:$A$1004,">="&B$4,'Expenses'!$A$5:$A$1004,"<="&EOMONTH(B$4,0),'Expenses'!$B$5:$B$1004,$A11) | C11: =SUMIFS('Expenses'!$D$5:$D$1004,'Expenses'!$A$5:$A$1004,">="&C$4,'Expenses'!$A$5:$A$1004,"<="&EOMONTH(C$4,0),'Expenses'!$B$5:$B$1004,$A11) | D11: =SUMIFS('Expenses'!$D$5:$D$1004,'Expenses'!$A$5:$A$1004,">="&D$4,'Expenses'!$A$5:$A$1004,"<="&EOMONTH(D$4,0),'Expenses'!$B$5:$B$1004,$A11) | E11: =SUMIFS('Expenses'!$D$5:$D$1004,'Expenses'!$A$5:$A$1004,">="&E$4,'Expenses'!$A$5:$A$1004,"<="&EOMONTH(E$4,0),'Expenses'!$B$5:$B$1004,$A11) | F11: =SUMIFS('Expenses'!$D$5:$D$1004,'Expenses'!$A$5:$A$1004,">="&F$4,'Expenses'!$A$5:$A$1004,"<="&EOMONTH(F$4,0),'Expenses'!$B$5:$B$1004,$A11) | G11: =SUMIFS('Expenses'!$D$5:$D$1004,'Expenses'!$A$5:$A$1004,">="&G$4,'Expenses'!$A$5:$A$1004,"<="&EOMONTH(G$4,0),'Expenses'!$B$5:$B$1004,$A11) | H11: =SUMIFS('Expenses'!$D$5:$D$1004,'Expenses'!$A$5:$A$1004,">="&H$4,'Expenses'!$A$5:$A$1004,"<="&EOMONTH(H$4,0),'Expenses'!$B$5:$B$1004,$A11) | I11: =SUMIFS('Expenses'!$D$5:$D$1004,'Expenses'!$A$5:$A$1004,">="&I$4,'Expenses'!$A$5:$A$1004,"<="&EOMONTH(I$4,0),'Expenses'!$B$5:$B$1004,$A11) | ... M11: =SUMIFS('Expenses'!$D$5:$D$1004,'Expenses'!$A$5:$A$1004,">="&M$4,'Expenses'!$A$5:$A$1004,"<="&EOMONTH(M$4,0),'Expenses'!$B$5:$B$1004,$A11) | N11: =SUM(B11:M11)
A12: =Heads!A5 | B12: =SUMIFS('Expenses'!$D$5:$D$1004,'Expenses'!$A$5:$A$1004,">="&B$4,'Expenses'!$A$5:$A$1004,"<="&EOMONTH(B$4,0),'Expenses'!$B$5:$B$1004,$A12) | C12: =SUMIFS('Expenses'!$D$5:$D$1004,'Expenses'!$A$5:$A$1004,">="&C$4,'Expenses'!$A$5:$A$1004,"<="&EOMONTH(C$4,0),'Expenses'!$B$5:$B$1004,$A12) | D12: =SUMIFS('Expenses'!$D$5:$D$1004,'Expenses'!$A$5:$A$1004,">="&D$4,'Expenses'!$A$5:$A$1004,"<="&EOMONTH(D$4,0),'Expenses'!$B$5:$B$1004,$A12) | E12: =SUMIFS('Expenses'!$D$5:$D$1004,'Expenses'!$A$5:$A$1004,">="&E$4,'Expenses'!$A$5:$A$1004,"<="&EOMONTH(E$4,0),'Expenses'!$B$5:$B$1004,$A12) | F12: =SUMIFS('Expenses'!$D$5:$D$1004,'Expenses'!$A$5:$A$1004,">="&F$4,'Expenses'!$A$5:$A$1004,"<="&EOMONTH(F$4,0),'Expenses'!$B$5:$B$1004,$A12) | G12: =SUMIFS('Expenses'!$D$5:$D$1004,'Expenses'!$A$5:$A$1004,">="&G$4,'Expenses'!$A$5:$A$1004,"<="&EOMONTH(G$4,0),'Expenses'!$B$5:$B$1004,$A12) | H12: =SUMIFS('Expenses'!$D$5:$D$1004,'Expenses'!$A$5:$A$1004,">="&H$4,'Expenses'!$A$5:$A$1004,"<="&EOMONTH(H$4,0),'Expenses'!$B$5:$B$1004,$A12) | I12: =SUMIFS('Expenses'!$D$5:$D$1004,'Expenses'!$A$5:$A$1004,">="&I$4,'Expenses'!$A$5:$A$1004,"<="&EOMONTH(I$4,0),'Expenses'!$B$5:$B$1004,$A12) | ... M12: =SUMIFS('Expenses'!$D$5:$D$1004,'Expenses'!$A$5:$A$1004,">="&M$4,'Expenses'!$A$5:$A$1004,"<="&EOMONTH(M$4,0),'Expenses'!$B$5:$B$1004,$A12) | N12: =SUM(B12:M12)
A13: =Heads!A6 | B13: =SUMIFS('Expenses'!$D$5:$D$1004,'Expenses'!$A$5:$A$1004,">="&B$4,'Expenses'!$A$5:$A$1004,"<="&EOMONTH(B$4,0),'Expenses'!$B$5:$B$1004,$A13) | C13: =SUMIFS('Expenses'!$D$5:$D$1004,'Expenses'!$A$5:$A$1004,">="&C$4,'Expenses'!$A$5:$A$1004,"<="&EOMONTH(C$4,0),'Expenses'!$B$5:$B$1004,$A13) | D13: =SUMIFS('Expenses'!$D$5:$D$1004,'Expenses'!$A$5:$A$1004,">="&D$4,'Expenses'!$A$5:$A$1004,"<="&EOMONTH(D$4,0),'Expenses'!$B$5:$B$1004,$A13) | E13: =SUMIFS('Expenses'!$D$5:$D$1004,'Expenses'!$A$5:$A$1004,">="&E$4,'Expenses'!$A$5:$A$1004,"<="&EOMONTH(E$4,0),'Expenses'!$B$5:$B$1004,$A13) | F13: =SUMIFS('Expenses'!$D$5:$D$1004,'Expenses'!$A$5:$A$1004,">="&F$4,'Expenses'!$A$5:$A$1004,"<="&EOMONTH(F$4,0),'Expenses'!$B$5:$B$1004,$A13) | G13: =SUMIFS('Expenses'!$D$5:$D$1004,'Expenses'!$A$5:$A$1004,">="&G$4,'Expenses'!$A$5:$A$1004,"<="&EOMONTH(G$4,0),'Expenses'!$B$5:$B$1004,$A13) | H13: =SUMIFS('Expenses'!$D$5:$D$1004,'Expenses'!$A$5:$A$1004,">="&H$4,'Expenses'!$A$5:$A$1004,"<="&EOMONTH(H$4,0),'Expenses'!$B$5:$B$1004,$A13) | I13: =SUMIFS('Expenses'!$D$5:$D$1004,'Expenses'!$A$5:$A$1004,">="&I$4,'Expenses'!$A$5:$A$1004,"<="&EOMONTH(I$4,0),'Expenses'!$B$5:$B$1004,$A13) | ... M13: =SUMIFS('Expenses'!$D$5:$D$1004,'Expenses'!$A$5:$A$1004,">="&M$4,'Expenses'!$A$5:$A$1004,"<="&EOMONTH(M$4,0),'Expenses'!$B$5:$B$1004,$A13) | N13: =SUM(B13:M13)
A14: =Heads!A7 | B14: =SUMIFS('Expenses'!$D$5:$D$1004,'Expenses'!$A$5:$A$1004,">="&B$4,'Expenses'!$A$5:$A$1004,"<="&EOMONTH(B$4,0),'Expenses'!$B$5:$B$1004,$A14) | C14: =SUMIFS('Expenses'!$D$5:$D$1004,'Expenses'!$A$5:$A$1004,">="&C$4,'Expenses'!$A$5:$A$1004,"<="&EOMONTH(C$4,0),'Expenses'!$B$5:$B$1004,$A14) | D14: =SUMIFS('Expenses'!$D$5:$D$1004,'Expenses'!$A$5:$A$1004,">="&D$4,'Expenses'!$A$5:$A$1004,"<="&EOMONTH(D$4,0),'Expenses'!$B$5:$B$1004,$A14) | E14: =SUMIFS('Expenses'!$D$5:$D$1004,'Expenses'!$A$5:$A$1004,">="&E$4,'Expenses'!$A$5:$A$1004,"<="&EOMONTH(E$4,0),'Expenses'!$B$5:$B$1004,$A14) | F14: =SUMIFS('Expenses'!$D$5:$D$1004,'Expenses'!$A$5:$A$1004,">="&F$4,'Expenses'!$A$5:$A$1004,"<="&EOMONTH(F$4,0),'Expenses'!$B$5:$B$1004,$A14) | G14: =SUMIFS('Expenses'!$D$5:$D$1004,'Expenses'!$A$5:$A$1004,">="&G$4,'Expenses'!$A$5:$A$1004,"<="&EOMONTH(G$4,0),'Expenses'!$B$5:$B$1004,$A14) | H14: =SUMIFS('Expenses'!$D$5:$D$1004,'Expenses'!$A$5:$A$1004,">="&H$4,'Expenses'!$A$5:$A$1004,"<="&EOMONTH(H$4,0),'Expenses'!$B$5:$B$1004,$A14) | I14: =SUMIFS('Expenses'!$D$5:$D$1004,'Expenses'!$A$5:$A$1004,">="&I$4,'Expenses'!$A$5:$A$1004,"<="&EOMONTH(I$4,0),'Expenses'!$B$5:$B$1004,$A14) | ... M14: =SUMIFS('Expenses'!$D$5:$D$1004,'Expenses'!$A$5:$A$1004,">="&M$4,'Expenses'!$A$5:$A$1004,"<="&EOMONTH(M$4,0),'Expenses'!$B$5:$B$1004,$A14) | N14: =SUM(B14:M14)
A15: =Heads!A8 | B15: =SUMIFS('Expenses'!$D$5:$D$1004,'Expenses'!$A$5:$A$1004,">="&B$4,'Expenses'!$A$5:$A$1004,"<="&EOMONTH(B$4,0),'Expenses'!$B$5:$B$1004,$A15) | C15: =SUMIFS('Expenses'!$D$5:$D$1004,'Expenses'!$A$5:$A$1004,">="&C$4,'Expenses'!$A$5:$A$1004,"<="&EOMONTH(C$4,0),'Expenses'!$B$5:$B$1004,$A15) | D15: =SUMIFS('Expenses'!$D$5:$D$1004,'Expenses'!$A$5:$A$1004,">="&D$4,'Expenses'!$A$5:$A$1004,"<="&EOMONTH(D$4,0),'Expenses'!$B$5:$B$1004,$A15) | E15: =SUMIFS('Expenses'!$D$5:$D$1004,'Expenses'!$A$5:$A$1004,">="&E$4,'Expenses'!$A$5:$A$1004,"<="&EOMONTH(E$4,0),'Expenses'!$B$5:$B$1004,$A15) | F15: =SUMIFS('Expenses'!$D$5:$D$1004,'Expenses'!$A$5:$A$1004,">="&F$4,'Expenses'!$A$5:$A$1004,"<="&EOMONTH(F$4,0),'Expenses'!$B$5:$B$1004,$A15) | G15: =SUMIFS('Expenses'!$D$5:$D$1004,'Expenses'!$A$5:$A$1004,">="&G$4,'Expenses'!$A$5:$A$1004,"<="&EOMONTH(G$4,0),'Expenses'!$B$5:$B$1004,$A15) | H15: =SUMIFS('Expenses'!$D$5:$D$1004,'Expenses'!$A$5:$A$1004,">="&H$4,'Expenses'!$A$5:$A$1004,"<="&EOMONTH(H$4,0),'Expenses'!$B$5:$B$1004,$A15) | I15: =SUMIFS('Expenses'!$D$5:$D$1004,'Expenses'!$A$5:$A$1004,">="&I$4,'Expenses'!$A$5:$A$1004,"<="&EOMONTH(I$4,0),'Expenses'!$B$5:$B$1004,$A15) | ... M15: =SUMIFS('Expenses'!$D$5:$D$1004,'Expenses'!$A$5:$A$1004,">="&M$4,'Expenses'!$A$5:$A$1004,"<="&EOMONTH(M$4,0),'Expenses'!$B$5:$B$1004,$A15) | N15: =SUM(B15:M15)
A16: =Heads!A9 | B16: =SUMIFS('Expenses'!$D$5:$D$1004,'Expenses'!$A$5:$A$1004,">="&B$4,'Expenses'!$A$5:$A$1004,"<="&EOMONTH(B$4,0),'Expenses'!$B$5:$B$1004,$A16) | C16: =SUMIFS('Expenses'!$D$5:$D$1004,'Expenses'!$A$5:$A$1004,">="&C$4,'Expenses'!$A$5:$A$1004,"<="&EOMONTH(C$4,0),'Expenses'!$B$5:$B$1004,$A16) | D16: =SUMIFS('Expenses'!$D$5:$D$1004,'Expenses'!$A$5:$A$1004,">="&D$4,'Expenses'!$A$5:$A$1004,"<="&EOMONTH(D$4,0),'Expenses'!$B$5:$B$1004,$A16) | E16: =SUMIFS('Expenses'!$D$5:$D$1004,'Expenses'!$A$5:$A$1004,">="&E$4,'Expenses'!$A$5:$A$1004,"<="&EOMONTH(E$4,0),'Expenses'!$B$5:$B$1004,$A16) | F16: =SUMIFS('Expenses'!$D$5:$D$1004,'Expenses'!$A$5:$A$1004,">="&F$4,'Expenses'!$A$5:$A$1004,"<="&EOMONTH(F$4,0),'Expenses'!$B$5:$B$1004,$A16) | G16: =SUMIFS('Expenses'!$D$5:$D$1004,'Expenses'!$A$5:$A$1004,">="&G$4,'Expenses'!$A$5:$A$1004,"<="&EOMONTH(G$4,0),'Expenses'!$B$5:$B$1004,$A16) | H16: =SUMIFS('Expenses'!$D$5:$D$1004,'Expenses'!$A$5:$A$1004,">="&H$4,'Expenses'!$A$5:$A$1004,"<="&EOMONTH(H$4,0),'Expenses'!$B$5:$B$1004,$A16) | I16: =SUMIFS('Expenses'!$D$5:$D$1004,'Expenses'!$A$5:$A$1004,">="&I$4,'Expenses'!$A$5:$A$1004,"<="&EOMONTH(I$4,0),'Expenses'!$B$5:$B$1004,$A16) | ... M16: =SUMIFS('Expenses'!$D$5:$D$1004,'Expenses'!$A$5:$A$1004,">="&M$4,'Expenses'!$A$5:$A$1004,"<="&EOMONTH(M$4,0),'Expenses'!$B$5:$B$1004,$A16) | N16: =SUM(B16:M16)
A17: =Heads!A10 | B17: =SUMIFS('Expenses'!$D$5:$D$1004,'Expenses'!$A$5:$A$1004,">="&B$4,'Expenses'!$A$5:$A$1004,"<="&EOMONTH(B$4,0),'Expenses'!$B$5:$B$1004,$A17) | C17: =SUMIFS('Expenses'!$D$5:$D$1004,'Expenses'!$A$5:$A$1004,">="&C$4,'Expenses'!$A$5:$A$1004,"<="&EOMONTH(C$4,0),'Expenses'!$B$5:$B$1004,$A17) | D17: =SUMIFS('Expenses'!$D$5:$D$1004,'Expenses'!$A$5:$A$1004,">="&D$4,'Expenses'!$A$5:$A$1004,"<="&EOMONTH(D$4,0),'Expenses'!$B$5:$B$1004,$A17) | E17: =SUMIFS('Expenses'!$D$5:$D$1004,'Expenses'!$A$5:$A$1004,">="&E$4,'Expenses'!$A$5:$A$1004,"<="&EOMONTH(E$4,0),'Expenses'!$B$5:$B$1004,$A17) | F17: =SUMIFS('Expenses'!$D$5:$D$1004,'Expenses'!$A$5:$A$1004,">="&F$4,'Expenses'!$A$5:$A$1004,"<="&EOMONTH(F$4,0),'Expenses'!$B$5:$B$1004,$A17) | G17: =SUMIFS('Expenses'!$D$5:$D$1004,'Expenses'!$A$5:$A$1004,">="&G$4,'Expenses'!$A$5:$A$1004,"<="&EOMONTH(G$4,0),'Expenses'!$B$5:$B$1004,$A17) | H17: =SUMIFS('Expenses'!$D$5:$D$1004,'Expenses'!$A$5:$A$1004,">="&H$4,'Expenses'!$A$5:$A$1004,"<="&EOMONTH(H$4,0),'Expenses'!$B$5:$B$1004,$A17) | I17: =SUMIFS('Expenses'!$D$5:$D$1004,'Expenses'!$A$5:$A$1004,">="&I$4,'Expenses'!$A$5:$A$1004,"<="&EOMONTH(I$4,0),'Expenses'!$B$5:$B$1004,$A17) | ... M17: =SUMIFS('Expenses'!$D$5:$D$1004,'Expenses'!$A$5:$A$1004,">="&M$4,'Expenses'!$A$5:$A$1004,"<="&EOMONTH(M$4,0),'Expenses'!$B$5:$B$1004,$A17) | N17: =SUM(B17:M17)
A18: =Heads!A11 | B18: =SUMIFS('Expenses'!$D$5:$D$1004,'Expenses'!$A$5:$A$1004,">="&B$4,'Expenses'!$A$5:$A$1004,"<="&EOMONTH(B$4,0),'Expenses'!$B$5:$B$1004,$A18) | C18: =SUMIFS('Expenses'!$D$5:$D$1004,'Expenses'!$A$5:$A$1004,">="&C$4,'Expenses'!$A$5:$A$1004,"<="&EOMONTH(C$4,0),'Expenses'!$B$5:$B$1004,$A18) | D18: =SUMIFS('Expenses'!$D$5:$D$1004,'Expenses'!$A$5:$A$1004,">="&D$4,'Expenses'!$A$5:$A$1004,"<="&EOMONTH(D$4,0),'Expenses'!$B$5:$B$1004,$A18) | E18: =SUMIFS('Expenses'!$D$5:$D$1004,'Expenses'!$A$5:$A$1004,">="&E$4,'Expenses'!$A$5:$A$1004,"<="&EOMONTH(E$4,0),'Expenses'!$B$5:$B$1004,$A18) | F18: =SUMIFS('Expenses'!$D$5:$D$1004,'Expenses'!$A$5:$A$1004,">="&F$4,'Expenses'!$A$5:$A$1004,"<="&EOMONTH(F$4,0),'Expenses'!$B$5:$B$1004,$A18) | G18: =SUMIFS('Expenses'!$D$5:$D$1004,'Expenses'!$A$5:$A$1004,">="&G$4,'Expenses'!$A$5:$A$1004,"<="&EOMONTH(G$4,0),'Expenses'!$B$5:$B$1004,$A18) | H18: =SUMIFS('Expenses'!$D$5:$D$1004,'Expenses'!$A$5:$A$1004,">="&H$4,'Expenses'!$A$5:$A$1004,"<="&EOMONTH(H$4,0),'Expenses'!$B$5:$B$1004,$A18) | I18: =SUMIFS('Expenses'!$D$5:$D$1004,'Expenses'!$A$5:$A$1004,">="&I$4,'Expenses'!$A$5:$A$1004,"<="&EOMONTH(I$4,0),'Expenses'!$B$5:$B$1004,$A18) | ... M18: =SUMIFS('Expenses'!$D$5:$D$1004,'Expenses'!$A$5:$A$1004,">="&M$4,'Expenses'!$A$5:$A$1004,"<="&EOMONTH(M$4,0),'Expenses'!$B$5:$B$1004,$A18) | N18: =SUM(B18:M18)
A19: =Heads!A12 | B19: =SUMIFS('Expenses'!$D$5:$D$1004,'Expenses'!$A$5:$A$1004,">="&B$4,'Expenses'!$A$5:$A$1004,"<="&EOMONTH(B$4,0),'Expenses'!$B$5:$B$1004,$A19) | C19: =SUMIFS('Expenses'!$D$5:$D$1004,'Expenses'!$A$5:$A$1004,">="&C$4,'Expenses'!$A$5:$A$1004,"<="&EOMONTH(C$4,0),'Expenses'!$B$5:$B$1004,$A19) | D19: =SUMIFS('Expenses'!$D$5:$D$1004,'Expenses'!$A$5:$A$1004,">="&D$4,'Expenses'!$A$5:$A$1004,"<="&EOMONTH(D$4,0),'Expenses'!$B$5:$B$1004,$A19) | E19: =SUMIFS('Expenses'!$D$5:$D$1004,'Expenses'!$A$5:$A$1004,">="&E$4,'Expenses'!$A$5:$A$1004,"<="&EOMONTH(E$4,0),'Expenses'!$B$5:$B$1004,$A19) | F19: =SUMIFS('Expenses'!$D$5:$D$1004,'Expenses'!$A$5:$A$1004,">="&F$4,'Expenses'!$A$5:$A$1004,"<="&EOMONTH(F$4,0),'Expenses'!$B$5:$B$1004,$A19) | G19: =SUMIFS('Expenses'!$D$5:$D$1004,'Expenses'!$A$5:$A$1004,">="&G$4,'Expenses'!$A$5:$A$1004,"<="&EOMONTH(G$4,0),'Expenses'!$B$5:$B$1004,$A19) | H19: =SUMIFS('Expenses'!$D$5:$D$1004,'Expenses'!$A$5:$A$1004,">="&H$4,'Expenses'!$A$5:$A$1004,"<="&EOMONTH(H$4,0),'Expenses'!$B$5:$B$1004,$A19) | I19: =SUMIFS('Expenses'!$D$5:$D$1004,'Expenses'!$A$5:$A$1004,">="&I$4,'Expenses'!$A$5:$A$1004,"<="&EOMONTH(I$4,0),'Expenses'!$B$5:$B$1004,$A19) | ... M19: =SUMIFS('Expenses'!$D$5:$D$1004,'Expenses'!$A$5:$A$1004,">="&M$4,'Expenses'!$A$5:$A$1004,"<="&EOMONTH(M$4,0),'Expenses'!$B$5:$B$1004,$A19) | N19: =SUM(B19:M19)
A20: =Heads!A13 | B20: =SUMIFS('Expenses'!$D$5:$D$1004,'Expenses'!$A$5:$A$1004,">="&B$4,'Expenses'!$A$5:$A$1004,"<="&EOMONTH(B$4,0),'Expenses'!$B$5:$B$1004,$A20) | C20: =SUMIFS('Expenses'!$D$5:$D$1004,'Expenses'!$A$5:$A$1004,">="&C$4,'Expenses'!$A$5:$A$1004,"<="&EOMONTH(C$4,0),'Expenses'!$B$5:$B$1004,$A20) | D20: =SUMIFS('Expenses'!$D$5:$D$1004,'Expenses'!$A$5:$A$1004,">="&D$4,'Expenses'!$A$5:$A$1004,"<="&EOMONTH(D$4,0),'Expenses'!$B$5:$B$1004,$A20) | E20: =SUMIFS('Expenses'!$D$5:$D$1004,'Expenses'!$A$5:$A$1004,">="&E$4,'Expenses'!$A$5:$A$1004,"<="&EOMONTH(E$4,0),'Expenses'!$B$5:$B$1004,$A20) | F20: =SUMIFS('Expenses'!$D$5:$D$1004,'Expenses'!$A$5:$A$1004,">="&F$4,'Expenses'!$A$5:$A$1004,"<="&EOMONTH(F$4,0),'Expenses'!$B$5:$B$1004,$A20) | G20: =SUMIFS('Expenses'!$D$5:$D$1004,'Expenses'!$A$5:$A$1004,">="&G$4,'Expenses'!$A$5:$A$1004,"<="&EOMONTH(G$4,0),'Expenses'!$B$5:$B$1004,$A20) | H20: =SUMIFS('Expenses'!$D$5:$D$1004,'Expenses'!$A$5:$A$1004,">="&H$4,'Expenses'!$A$5:$A$1004,"<="&EOMONTH(H$4,0),'Expenses'!$B$5:$B$1004,$A20) | I20: =SUMIFS('Expenses'!$D$5:$D$1004,'Expenses'!$A$5:$A$1004,">="&I$4,'Expenses'!$A$5:$A$1004,"<="&EOMONTH(I$4,0),'Expenses'!$B$5:$B$1004,$A20) | ... M20: =SUMIFS('Expenses'!$D$5:$D$1004,'Expenses'!$A$5:$A$1004,">="&M$4,'Expenses'!$A$5:$A$1004,"<="&EOMONTH(M$4,0),'Expenses'!$B$5:$B$1004,$A20) | N20: =SUM(B20:M20)
... A23: =Heads!A16 | B23: =SUMIFS('Expenses'!$D$5:$D$1004,'Expenses'!$A$5:$A$1004,">="&B$4,'Expenses'!$A$5:$A$1004,"<="&EOMONTH(B$4,0),'Expenses'!$B$5:$B$1004,$A23) | C23: =SUMIFS('Expenses'!$D$5:$D$1004,'Expenses'!$A$5:$A$1004,">="&C$4,'Expenses'!$A$5:$A$1004,"<="&EOMONTH(C$4,0),'Expenses'!$B$5:$B$1004,$A23) | D23: =SUMIFS('Expenses'!$D$5:$D$1004,'Expenses'!$A$5:$A$1004,">="&D$4,'Expenses'!$A$5:$A$1004,"<="&EOMONTH(D$4,0),'Expenses'!$B$5:$B$1004,$A23) | E23: =SUMIFS('Expenses'!$D$5:$D$1004,'Expenses'!$A$5:$A$1004,">="&E$4,'Expenses'!$A$5:$A$1004,"<="&EOMONTH(E$4,0),'Expenses'!$B$5:$B$1004,$A23) | F23: =SUMIFS('Expenses'!$D$5:$D$1004,'Expenses'!$A$5:$A$1004,">="&F$4,'Expenses'!$A$5:$A$1004,"<="&EOMONTH(F$4,0),'Expenses'!$B$5:$B$1004,$A23) | G23: =SUMIFS('Expenses'!$D$5:$D$1004,'Expenses'!$A$5:$A$1004,">="&G$4,'Expenses'!$A$5:$A$1004,"<="&EOMONTH(G$4,0),'Expenses'!$B$5:$B$1004,$A23) | H23: =SUMIFS('Expenses'!$D$5:$D$1004,'Expenses'!$A$5:$A$1004,">="&H$4,'Expenses'!$A$5:$A$1004,"<="&EOMONTH(H$4,0),'Expenses'!$B$5:$B$1004,$A23) | I23: =SUMIFS('Expenses'!$D$5:$D$1004,'Expenses'!$A$5:$A$1004,">="&I$4,'Expenses'!$A$5:$A$1004,"<="&EOMONTH(I$4,0),'Expenses'!$B$5:$B$1004,$A23) | ... M23: =SUMIFS('Expenses'!$D$5:$D$1004,'Expenses'!$A$5:$A$1004,">="&M$4,'Expenses'!$A$5:$A$1004,"<="&EOMONTH(M$4,0),'Expenses'!$B$5:$B$1004,$A23) | N23: =SUM(B23:M23)
A24: Total expenses | B24: =SUM(B9:B23) | C24: =SUM(C9:C23) | D24: =SUM(D9:D23) | E24: =SUM(E9:E23) | F24: =SUM(F9:F23) | G24: =SUM(G9:G23) | H24: =SUM(H9:H23) | I24: =SUM(I9:I23) | ... M24: =SUM(M9:M23) | N24: =SUM(B24:M24)
A26: NET PROFIT | B26: =B7-B24 | C26: =C7-C24 | D26: =D7-D24 | E26: =E7-E24 | F26: =F7-F24 | G26: =G7-G24 | H26: =H7-H24 | I26: =I7-I24 | ... M26: =M7-M24 | N26: =SUM(B26:M26)
